Workbook
Name Barge: 'Aux - Lists'!$D$5
Name Barge_tanker: 'Aux - Lists'!$E$5
Name Crusher_types_RAP: 'Aux - Lists'!$A$48:$A$49
Name Crusher_types_RCA: 'Aux - Lists'!$A$58:$A$59
Name Electric_component: 'Aux - Lists'!$A$169:$A$170
Name Excavator_Hitachi_ZX1357_160kW: 'Aux - Lists'!$C$146:$C$153
Name Excavator_types: 'Aux - Lists'!$A$145:$A$146
Name Milling_large_scale_project_Wirtgen_W250Fi_753kW: 'Aux - Lists'!$E$135:$E$142
Name Milling_medium_scale_project_Wirtgen_W210XPi_571kW: 'Aux - Lists'!$D$135:$D$142
Name Milling_small_scale_project_Wirtgen_W35Ri_45kW: 'Aux - Lists'!$C$135:$C$142
Name Milling_types: 'Aux - Lists'!$A$134:$A$137
Name Mobile_jaw_crusher_400tph_RAP: 'Aux - Lists'!$C$48:$C$55
Name Mobile_jaw_crusher_400tph_RCA: 'Aux - Lists'!$C$58:$C$65
Name Mobile_screener_500tph_RAP: 'Aux - Lists'!$C$91:$C$98
Name Mobile_screener_500tph_RCA: 'Aux - Lists'!$C$101:$C$108
Name No: 'Aux - Lists'!$B$5
Name No_crusher_RAP: 'Aux - Lists'!$B$48
Name No_crusher_RCA: 'Aux - Lists'!$B$58
Name No_excavator: 'Aux - Lists'!$B$145
Name No_milling_machine: 'Aux - Lists'!$B$134
Name No_paver: 'Aux - Lists'!$B$112
Name No_roller: 'Aux - Lists'!$B$123
Name No_screener_RAP: 'Aux - Lists'!$B$91
Name No_screener_RCA: 'Aux - Lists'!$B$101
Name No_stacker_RAP: 'Aux - Lists'!$B$68
Name No_stacker_RCA: 'Aux - Lists'!$B$80
Name No_sweeper_truck: 'Aux - Lists'!$B$156
Name No_wheel_loader: 'Aux - Lists'!$B$17
Name Paver_large_scale_project_354kW: 'Aux - Lists'!$E$112:$E$119
Name Paver_medium_scale_project_129kW: 'Aux - Lists'!$D$112:$D$119
Name Paver_small_scale_project_25kW: 'Aux - Lists'!$C$112:$C$119
Name Paver_types: 'Aux - Lists'!$A$112:$A$115
Name Roller_large_scale_project_100kW: 'Aux - Lists'!$E$124:$E$131
Name Roller_medium_scale_project_55kW: 'Aux - Lists'!$D$124:$D$131
Name Roller_small_scale_project_30kW: 'Aux - Lists'!$C$124:$C$131
Name Roller_types: 'Aux - Lists'!$A$123:$A$126
Name Screener_types_RAP: 'Aux - Lists'!$A$91:$A$92
Name Screener_types_RCA: 'Aux - Lists'!$A$101:$A$102
Name Ship: 'Aux - Lists'!$F$5
Name Stacker_types_RAP: 'Aux - Lists'!$A$68:$A$69
Name Stacker_types_RCA: 'Aux - Lists'!$A$80:$A$81
Name Sweeper_truck_volvo_186kW: 'Aux - Lists'!$C$157:$C$164
Name Tracked_stacker_500tph_RAP: 'Aux - Lists'!$C$68:$C$75
Name Tracked_stacker_500tph_RCA: 'Aux - Lists'!$C$80:$C$87
Name Train: 'Aux - Lists'!$G$5:$G$6
Name Transport_mode: 'Aux - Lists'!$A$5:$A$10
Name Truck: 'Aux - Lists'!$C$5:$C$13
Name Types_sweeper_truck: 'Aux - Lists'!$A$156:$A$157
Name Wheel_loader_338tph_Komatsu_WA500: 'Aux - Lists'!$C$17:$C$24
Name Wheel_loader_338tph_Komatsu_WA500_RAP: 'Aux - Lists'!$C$28:$C$35
Name Wheel_loader_338tph_Komatsu_WA500_RCA: 'Aux - Lists'!$C$38:$C$45
Name Wheel_loader_types: 'Aux - Lists'!$A$17:$A$18
Name Wheel_loader_types_RAP: 'Aux - Lists'!$A$28:$A$29
Name Wheel_loader_types_RCA: 'Aux - Lists'!$A$38:$A$39
Name Yes: 'Aux - Lists'!$B$169:$B$170

Sheet ReadMe
A2: This LCA-based tool has been developed by the University of Antwerp as part of the PIONEERS (Portable Innovation Open Network for Efficiency and Emissions Reduction Solutions) project using funding from the European Union’s Horizon 2020 research and innovation programme under Grant Agreement 101037564.
A4: https://pioneers-ports.eu/
A5: https://cordis.europa.eu/project/id/101037564
A12: Use of this spreadsheet is restricted to consortium partners during the duration of the project only (from Oct 1, 2021 to Sep 30, 2026). This spreadsheet contains confidential information that falls under the regulations of the collaboration agreement of the PIONEERS project.
A15: Version 2.1 (released date: March 31, 2025)
A17: For more information and access, contact the Sustainable Pavements and Asphalt Research (SuPAR) group at the University of Antwerp.

Sheet Input
A1: Data collection form for LCA-based tool
A4: 1. General Information | C4: Example
A5: Date | B5: 45747 | C5: 45747
A6: Mixture ID | B6: 2221 | C6: 2221
A7: Mixture type (SB250) | C7: APO-A
A8: Mixture type (EN 13108) | C8: AC 20 base 70/100
A9: Total binder cotent (by weight of mix) | B9: 0.043 | C9: 0.043
A10: Asphalt binder replacement | B10: =(B9-B39)/B9 -> 0.53488372
A13: 2. Mixture Production
A14: Asphalt plant location (city/town) | B14: Locatie A
A15: Plant type | B15: Batch with parallel drum
A16: Average hour plant production (t/h) | B16: 180
A17: Asphalt plant: primary energy source type for heating and drying | B17: Natural_gas | C17: 0.8 | D17: =IF(AND(C17 + C18 = 100%, OR(B18 <> "No", C18 = 0%)), "Correct", IF(B18 = "No", "Error", "Error: Check %")) -> Correct
A18: Asphalt plant: secondary energy source type for heating and drying | B18: Electricity | C18: 0.2
A19: Asphalt plant: electric components | B19: Yes | C19: Electricity | D19: =IF(OR(AND(B19="Yes", C19<>"No"), AND(B19="No",C19="No")), "Correct", "Error") -> Correct
A20: Secondary energy source for asphalt plant operation & percentage | B20: No
A21: Mixture production temperature range (°C) | B21: 155⁰C - 185⁰C
A22: Mixture bulk density (SVM) (kg/m3) | B22: 2400
A23: Annual average daily temperature of production location (°C) | B23: 11.2
B25: Type | C25: Energy source
A26: Asphalt mix loading operation | B26: Wheel_loader_338tph_Komatsu_WA500 | C26: Diesel | D26: =IF(OR(AND(B26="No_wheel_loader", C26<>"No"), AND(C26="No", B26<>"No_wheel_loader")), "Error", "") | U26: =IF(OR(AND(B26="No_wheel_loader", C26<>"No"), AND(C26="No", B26<>"No_wheel_loader")), 1, 0) -> 0
A29: 3. Layer Specifications
A30: Layer | B30: Thickness (mm) | C30: Mass per FU (ton/m2)
A31: Wearing Course 1 | B31: 80 | C31: =($B$22/1000)*($B$31/1000) -> 0.192
A34: 4. Mixture Components and Transporation Distances
A35: - For virgin binder, enter the location and transportation mode and distance from the refinery - For aggregate and filler, enter the location and transportation mode and distance from the quarry - For waste, enter the location and transportation mode and distance from the processing plant - For additives, enter the location and transportation mode and distance from the factory
A36: Mixture Components | B36: % (by weight of mixture) | C36: Type | D36: Biogenic origin - type | E36: % Biogenic content (by weight of product) | F36: Biogenic status | G36: Stockpile covered? | H36: Transportation distance (km) from point of extraction to asphalt plant and fuel type
H37: Location (city/town) | I37: Transport status | J37: Route 1 | M37: Route 2 | P37: Route 3
J38: Mode of transport | K38: Energy source | L38: Distance (km) | M38: Mode of transport | N38: Energy source | O38: Distance (km) | P38: Mode of transport | Q38: Energy source | R38: Distance (km) | T38: List | U38: Check
A39: Virgin binder | B39: 0.02 | C39: Conventional_Bitumen | D39: Binder_bio | E39: 0.1 | F39: =IF(AND(D39="No",E39>0), "Check biogenic content","Correct") -> Correct | H39: Antwerp | I39: =IF($B39=0%,"Do not fill Transport", "Fill Transport") -> Fill Transport | J39: Truck | K39: Diesel_Euro6 | L39: 20 | M39: No | N39: No | O39: 0 | P39: No | Q39: No | R39: 0 | U39: =+IF(B39>0,IF(K39="No",1,IF(SUM(L39,O39,R39)>0,0,2)),0) -> 0
A40: Virgin crushed coarse aggregate 1 (>2 mm) | B40: 0 | G40: No | H40: Bremanger | I40: =IF($B40=0%,"Do not fill Transport", "Fill Transport") -> Do not fill Transport | J40: No | K40: No | L40: 0 | M40: No | N40: No | O40: 0 | P40: No | Q40: No | R40: 0 | U40: =+IF(B40>0,IF(K40="No",1,IF(SUM(L40,O40,R40)>0,0,2)),0) -> 0
A41: Virgin crushed coarse aggregate 2 (>2 mm) | B41: 0.2 | G41: No | I41: =IF($B41=0%,"Do not fill Transport", "Fill Transport") -> Fill Transport | J41: Ship | K41: Heavy_fuel_oil | L41: 40 | M41: Ship | N41: Heavy_fuel_oil | O41: 40 | P41: No | Q41: No | R41: 0 | U41: =+IF(B41>0,IF(K41="No",1,IF(SUM(L41,O41,R41)>0,0,2)),0) -> 0
A42: Virgin crushed coarse aggregate 3 (>2 mm) | B42: 0.1 | G42: Yes | I42: =IF($B42=0%,"Do not fill Transport", "Fill Transport") -> Fill Transport | J42: Ship | K42: Heavy_fuel_oil | L42: 40 | M42: Ship | N42: Heavy_fuel_oil | O42: 40 | P42: Ship | Q42: Heavy_fuel_oil | R42: 40 | U42: =+IF(B42>0,IF(K42="No",1,IF(SUM(L42,O42,R42)>0,0,2)),0) -> 0
A43: Virgin crushed fine aggregate 1 (≤2 mm) | B43: 0.06 | G43: No | H43: Gaurain-Ramecroix | I43: =IF($B43=0%,"Do not fill Transport", "Fill Transport") -> Fill Transport | J43: Truck | K43: Diesel_Euro5 | L43: 22 | M43: No | N43: No | O43: 0 | P43: No | Q43: No | R43: 0 | U43: =+IF(B43>0,IF(K43="No",1,IF(SUM(L43,O43,R43)>0,0,2)),0) -> 0
A44: Virgin crushed fine aggregate 2 (≤2 mm) | B44: 0 | G44: No | I44: =IF($B44=0%,"Do not fill Transport", "Fill Transport") -> Do not fill Transport | J44: No | K44: No | L44: 0 | M44: No | N44: No | O44: 0 | P44: No | Q44: No | R44: 0 | U44: =+IF(B44>0,IF(K44="No",1,IF(SUM(L44,O44,R44)>0,0,2)),0) -> 0
A45: Virgin crushed fine aggregate 3 (≤2 mm) | B45: 0.03 | G45: Yes | I45: =IF($B45=0%,"Do not fill Transport", "Fill Transport") -> Fill Transport | J45: Truck | K45: Diesel_Euro5 | L45: 40 | M45: Truck | N45: Diesel_Euro5 | O45: 40 | P45: Truck | Q45: Diesel_Euro5 | R45: 40 | U45: =+IF(B45>0,IF(K45="No",1,IF(SUM(L45,O45,R45)>0,0,2)),0) -> 0
A46: Virgin natural fine aggregate 1 (≤2 mm) | B46: 0.02 | G46: No | H46: Schelde | I46: =IF($B46=0%,"Do not fill Transport", "Fill Transport") -> Fill Transport | J46: Train | K46: Electric | L46: 22 | M46: Train | N46: Diesel | O46: 30 | P46: Train | Q46: Diesel | R46: 30 | U46: =+IF(B46>0,IF(K46="No",1,IF(SUM(L46,O46,R46)>0,0,2)),0) -> 0
A47: Virgin natural fine aggregate 2 (≤2 mm) | B47: 0.02 | G47: No | I47: =IF($B47=0%,"Do not fill Transport", "Fill Transport") -> Fill Transport | J47: Train | K47: Diesel | L47: 30 | M47: Train | N47: Diesel | O47: 30 | P47: Train | Q47: Diesel | R47: 30 | U47: =+IF(B47>0,IF(K47="No",1,IF(SUM(L47,O47,R47)>0,0,2)),0) -> 0
A48: Virgin natural fine aggregate 3 (≤2 mm) | B48: 0.02 | G48: Yes | I48: =IF($B48=0%,"Do not fill Transport", "Fill Transport") -> Fill Transport | J48: Train | K48: Diesel | L48: 30 | M48: Train | N48: Diesel | O48: 30 | P48: Train | Q48: Diesel | R48: 30 | U48: =+IF(B48>0,IF(K48="No",1,IF(SUM(L48,O48,R48)>0,0,2)),0) -> 0
A49: Filler 1 | B49: 0.01 | C49: Cement | G49: Yes | H49: Wanssum | I49: =IF($B49=0%,"Do not fill Transport", "Fill Transport") -> Fill Transport | J49: Truck | K49: Biodiesel_4.5% | L49: 20 | M49: No | N49: No | O49: 0 | P49: No | Q49: No | R49: 0 | T49: =+IF(B49>0,IF(C49="No_filler",1,0),0) -> 0 | U49: =+IF(B49>0,IF(K49="No",1,IF(SUM(L49,O49,R49)>0,0,2)),0) -> 0
...

Sheet Result Dashboard
A1: LCA results for declared unit (cradle-to-gate analysis: A1-A3, D)
A3: General Information
A4: Date | B4: =Input!$B$5 -> 45747 | D4: Impact results (per declared unit)
A5: Mixture ID | B5: =Input!$B$6 -> 2221 | D5: Declared unit | E5: 1 ton of asphalt mixture
A6: Mixture type (SB250) | B6: =Input!$B$7 -> 0 | D6: Total PEF Score | E6: =IF(ABS('Aux - Check'!$B$11)>10^-10,"Error",Results!$M$47) -> 7.6924051 | F6: mpt/ton
A7: Mixture type (EN 13108) | B7: =+Input!B8 -> 0 | D7: Global Warming | E7: =IF(ABS('Aux - Check'!$B$11)>10^-10,"Error",Results!$L$53) -> 69.513812 | F7: kgCO2-eq/ton
A8: Asphalt plant location | B8: =Input!$B$14 -> Locatie A
A9: Mix temperature range | B9: =Input!$B$21 -> 155⁰C - 185⁰C
A10: Total binder (by weight of mix) | B10: =Input!$B$9 -> 0.043
A11: Asphalt binder replacement | B11: =+Input!B10 -> 0.53488372
A12: Bulk density [kg/m3] | B12: =Input!$B$22 -> 2400
A53: LCA results for functional unit (cradle-to-grave analysis: A1-C3, D)
A55: General Information
A56: Date | B56: =Input!$B$5 -> 45747 | D56: Impact results (per funtional unit)
A57: Mixture ID | B57: =Input!$B$6 -> 2221 | D57: Functional unit | E57: =+CONCATENATE("1 m2 (",Input!B31/10,"-cm thick)") -> 1 m2 (8-cm thick)
A58: Mixture type (SB250) | B58: =Input!$B$7 -> 0 | D58: Total PEF Score | E58: =IF(E6="Error","Error",Results!$N$111) -> 1.5740959 | F58: mpt/m2
A59: Mixture type (EN 13108) | B59: =Input!$B$8 -> 0 | D59: Global Warming | E59: =IF(E7="Error","Error",Results!$M$118) -> 14.877773 | F59: kgCO2-eq/m2
A60: Asphalt plant | B60: =Input!$B$14 -> Locatie A
A61: Mix temperature range | B61: =Input!$B$21 -> 155⁰C - 185⁰C
A62: Total binder | B62: =Input!$B$9 -> 0.043
A63: Asphalt binder replacement | B63: =+Input!B10 -> 0.53488372
A64: Bulk density [kg/m3] | B64: =Input!$B$22 -> 2400
A105: LCA results for a modified declared unit (cradle-to-grave analysis: A1-C3, D)
A107: General Information
A108: Date | B108: =Input!$B$5 -> 45747 | D108: Impact results (per ton excl. module D)
A109: Mixture ID | B109: =Input!$B$6 -> 2221 | D109: Declared unit | E109: =+CONCATENATE("1 ton (",Input!B31/10,"-cm thick)") -> 1 ton (8-cm thick)
A110: Mixture type (SB250) | B110: =Input!$B$7 -> 0 | D110: Total PEF Score | E110: =IF(E6="Error","Error",Results!$N$47) -> 8.1984162 | F110: mpt/ton
A111: Mixture type (EN 13108) | B111: =Input!$B$8 -> 0 | D111: Global Warming | E111: =IF(E7="Error","Error",Results!$M$53) -> 77.488402 | F111: kgCO2-eq/ ton
A112: Asphalt plant | B112: =Input!$B$14 -> Locatie A
A113: Mix temperature range | B113: =Input!$B$21 -> 155⁰C - 185⁰C
A114: Total binder | B114: =Input!$B$9 -> 0.043
A115: Asphalt binder replacement | B115: =+Input!$B$10 -> 0.53488372
A116: Bulk density [kg/m3] | B116: =Input!$B$22 -> 2400

Sheet Aux - Check
A2: Check machinery | B2: =+Input!U83 -> 0
A3: Check transportation | B3: =+Input!U58 -> 0
A4: Check sum of primary & secondary equals 100% | B4: =IF(Input!C17 + Input!C18 = 100%,0, 1) -> 0
A5: Check Asphalt plant: electric components | B5: =IF(OR(AND(Input!B19="Yes", Input!C19<>"No"), AND(Input!B19="No",Input!C19="No")), 0, 1) -> 0
A6: Check mix contents adds to 100% | B6: =IF(AND(Input!B58>=99.9%, Input!B58<=100.1%), 0, 1) -> 0
A7: Check asphalt mix components | B7: =IF( COUNTIFS( _xlfn.XLOOKUP(Input!$B$19,'Aux - Lists'!B168:C168,'Aux - Lists'!B169:C170,Input!$C$19), Input!$C$19)=0,1, 0) -> 0
A8: Checks asphalt mix loading operations | B8: =IF(COUNTIFS(_xlfn.XLOOKUP(Input!$B$26,'Aux - Lists'!B16:C16,'Aux - Lists'!B17:C24,Input!$C$26),Input!$C$26)=0,1,0) -> 0
A9: Check Results tab | B9: =+Results!B23+Results!B54+Results!B61+Results!B86+Results!B112+Results!B119+Results!B126+Results!B152+Results!B160 -> 0
A10: Check table results in all life cycle phases | B10: ='A1 - Raw Material Supply'!$B$139+'A1 - Raw Material Supply'!$C$139+'A1 - Raw Material Supply'!$D$139+'C3'' - Secondary Raw Material '!B345+'A2 - Transport'!$B$143+'C2''- Transport Secondary'!B82+'A3 - Production '!$B$230+'A3 - Production '!$C$230+'A4 - Transport'!$B$42+'A5 - Construction'!$B$163+'C1 - Deconstruction'!$B$111+'D- Benefits & Burdens'!$B$213+'D- Benefits & Burdens'!C213 -> -2.8421709e-14
B11: =+SUM(B2:B10) -> -2.8421709e-14

Sheet Results
A1: Environmental impacts per ton of asphalt mix per life cycle stage
A3: Impact Categories | B3: Unit | C3: A1 - Primary Raw Material | D3: C3' - Secondary Raw Material | E3: A2 - Transport Primary Raw Material | F3: C2' - Transport Secondary Raw Material | G3: A3- Production | H3: A4- Transport | I3: A5- Construction | J3: C1 - Deconstruction | K3: D- Burdens & Savings | L3: Total: A1-A3,C2',C3' (excl D) | M3: Total A1-A5,C1,C2',C3' (excl. D)
A4: Acidification | B4: accumulated exceedance (AE) mol H+ -eq | C4: ='A1 - Raw Material Supply'!Z114 -> 0.24301606 | D4: ='C3'' - Secondary Raw Material '!F320 -> 0.074906229 | E4: ='A2 - Transport'!Z118 -> 0.014214231 | F4: ='C2''- Transport Secondary'!H58 -> 0.0036805786 | G4: ='A3 - Production '!D205 -> 0.026233929 | H4: ='A4 - Transport'!B17 -> 0.019037691 | I4: ='A5 - Construction'!E137 -> 0.001298488 | J4: ='C1 - Deconstruction'!B86 -> 0 | K4: ='D- Benefits & Burdens'!N161 -> -0.12930824 | L4: =+SUM(C4:G4) -> 0.36205103 | M4: =SUM(C4:J4) -> 0.38238721
A5: Climate change | B5: global warming potential (GWP100) kgCO2-Eq | C5: ='A1 - Raw Material Supply'!Z115 -> 32.154504 | D5: ='C3'' - Secondary Raw Material '!F321 -> 16.171525 | E5: ='A2 - Transport'!Z119 -> 1.7271551 | F5: ='C2''- Transport Secondary'!H59 -> 0.70256399 | G5: ='A3 - Production '!D206 -> 18.758063 | H5: ='A4 - Transport'!B18 -> 6.9589458 | I5: ='A5 - Construction'!E138 -> 1.0156441 | J5: ='C1 - Deconstruction'!B87 -> 0 | K5: ='D- Benefits & Burdens'!N162 -> -37.502717 | L5: =+SUM(C5:G5) -> 69.513812 | M5: =SUM(C5:J5) -> 77.488402
A6: Climate change: biogenic | B6: global warming potential (GWP100) kgCO2-Eq | C6: ='A1 - Raw Material Supply'!Z116 -> -4.5388232 | D6: ='C3'' - Secondary Raw Material '!F322 -> 1.8526332 | E6: ='A2 - Transport'!Z120 -> 0.00070230325 | F6: ='C2''- Transport Secondary'!H60 -> 0.0062040874 | G6: ='A3 - Production '!D207 -> 0.061985478 | H6: ='A4 - Transport'!B19 -> 0.0032163484 | I6: ='A5 - Construction'!E139 -> 0.00020990788 | J6: ='C1 - Deconstruction'!B88 -> 0 | K6: ='D- Benefits & Burdens'!N163 -> -0.34335873 | L6: =+SUM(C6:G6) -> -2.617298 | M6: =SUM(C6:J6) -> -2.6138718
A7: Climate change: fossil | B7: global warming potential (GWP100) kgCO2-Eq | C7: ='A1 - Raw Material Supply'!Z117 -> 36.681411 | D7: ='C3'' - Secondary Raw Material '!F323 -> 14.294681 | E7: ='A2 - Transport'!Z121 -> 1.7259877 | F7: ='C2''- Transport Secondary'!H61 -> 0.69582446 | G7: ='A3 - Production '!D208 -> 18.686115 | H7: ='A4 - Transport'!B20 -> 6.9551823 | I7: ='A5 - Construction'!E140 -> 1.0153893 | J7: ='C1 - Deconstruction'!B89 -> 0 | K7: ='D- Benefits & Burdens'!N164 -> -37.151895 | L7: =+SUM(C7:G7) -> 72.084019 | M7: =SUM(C7:J7) -> 80.05459
A8: Land use and land use change | B8: global warming potential (GWP100) kgCO2-Eq | C8: ='A1 - Raw Material Supply'!Z118 -> 0.016966822 | D8: ='C3'' - Secondary Raw Material '!F324 -> 0.024211604 | E8: ='A2 - Transport'!Z122 -> 0.00046505352 | F8: ='C2''- Transport Secondary'!H62 -> 0.0005354434 | G8: ='A3 - Production '!D209 -> 0.0099621064 | H8: ='A4 - Transport'!B21 -> 0.0005471707 | I8: ='A5 - Construction'!E141 -> 4.4914436e-05 | J8: ='C1 - Deconstruction'!B90 -> 0 | K8: ='D- Benefits & Burdens'!N165 -> -0.014650666 | L8: =+SUM(C8:G8) -> 0.05214103 | M8: =SUM(C8:J8) -> 0.052733115
A9: Ecotoxicity: freshwater | B9: comparative toxic unit for ecosystems (CTUe) | C9: ='A1 - Raw Material Supply'!Z119 -> 608.36493 | D9: ='C3'' - Secondary Raw Material '!F325 -> 118.9236 | E9: ='A2 - Transport'!Z123 -> 2.0495657 | F9: ='C2''- Transport Secondary'!H63 -> 3.1475889 | G9: ='A3 - Production '!D210 -> 18.721989 | H9: ='A4 - Transport'!B22 -> 5.9140836 | I9: ='A5 - Construction'!E142 -> 0.44874267 | J9: ='C1 - Deconstruction'!B91 -> 0 | K9: ='D- Benefits & Burdens'!N166 -> -627.67294 | L9: =+SUM(C9:G9) -> 751.20767 | M9: =SUM(C9:J9) -> 757.5705
A10: Energy resources: non-renewable | B10: abiotic depletion potential (ADP): fossil fuels MJ, net calorific value | C10: ='A1 - Raw Material Supply'!Z120 -> 2002.7158 | D10: ='C3'' - Secondary Raw Material '!F326 -> 172.06189 | E10: ='A2 - Transport'!Z124 -> 22.63943 | F10: ='C2''- Transport Secondary'!H64 -> 15.869144 | G10: ='A3 - Production '!D211 -> 435.81457 | H10: ='A4 - Transport'!B23 -> 93.565403 | I10: ='A5 - Construction'!E143 -> 13.490469 | J10: ='C1 - Deconstruction'!B92 -> 0 | K10: ='D- Benefits & Burdens'!N167 -> -1105.8881 | L10: =+SUM(C10:G10) -> 2649.1009 | M10: =SUM(C10:J10) -> 2756.1567
A11: Eutrophication: freshwater | B11: fraction of nutrients reaching freshwater end compartment (P) | C11: ='A1 - Raw Material Supply'!Z121 -> 0.0057525189 | D11: ='C3'' - Secondary Raw Material '!F327 -> 0.0049076988 | E11: ='A2 - Transport'!Z125 -> 8.2885446e-05 | F11: ='C2''- Transport Secondary'!H65 -> 9.5715564e-05 | G11: ='A3 - Production '!D212 -> 0.0016191637 | H11: ='A4 - Transport'!B24 -> 0.000160089 | I11: ='A5 - Construction'!E144 -> 1.0736731e-05 | J11: ='C1 - Deconstruction'!B93 -> 0 | K11: ='D- Benefits & Burdens'!N168 -> -0.0030101971 | L11: =+SUM(C11:G11) -> 0.012457982 | M11: =SUM(C11:J11) -> 0.012628808
A12: Eutrophication: marine | B12: fraction of nutrients reaching marine end compartment (N) kg N-Eq | C12: ='A1 - Raw Material Supply'!Z122 -> 0.05275229 | D12: ='C3'' - Secondary Raw Material '!F328 -> 0.019414042 | E12: ='A2 - Transport'!Z126 -> 0.0043822842 | F12: ='C2''- Transport Secondary'!H66 -> 0.0021353852 | G12: ='A3 - Production '!D213 -> 0.0062702177 | H12: ='A4 - Transport'!B25 -> 0.006830722 | I12: ='A5 - Construction'!E145 -> 0.00029363044 | J12: ='C1 - Deconstruction'!B94 -> 0 | K12: ='D- Benefits & Burdens'!N169 -> -0.037081252 | L12: =+SUM(C12:G12) -> 0.084954219 | M12: =SUM(C12:J12) -> 0.092078571
A13: Eutrophication: terrestrial | B13: accumulated exceedance (AE) mol N-Eq | C13: ='A1 - Raw Material Supply'!Z123 -> 0.59039056 | D13: ='C3'' - Secondary Raw Material '!F329 -> 0.16159924 | E13: ='A2 - Transport'!Z127 -> 0.048090912 | F13: ='C2''- Transport Secondary'!H67 -> 0.01452035 | G13: ='A3 - Production '!D214 -> 0.064859522 | H13: ='A4 - Transport'!B26 -> 0.074512765 | I13: ='A5 - Construction'!E146 -> 0.0031921247 | J13: ='C1 - Deconstruction'!B95 -> 0 | K13: ='D- Benefits & Burdens'!N170 -> -0.42325647 | L13: =+SUM(C13:G13) -> 0.87946058 | M13: =SUM(C13:J13) -> 0.95716547
A14: Human toxicity: carcinogenic | B14: comparative toxic unit for human (CTUh) | C14: ='A1 - Raw Material Supply'!Z124 -> 1.6626148e-08 | D14: ='C3'' - Secondary Raw Material '!F330 -> 1.225906e-08 | E14: ='A2 - Transport'!Z128 -> 2.3315268e-10 | F14: ='C2''- Transport Secondary'!H68 -> 1.8232282e-10 | G14: ='A3 - Production '!D215 -> 2.7625344e-09 | H14: ='A4 - Transport'!B27 -> 6.504653e-10 | I14: ='A5 - Construction'!E147 -> 6.2066556e-11 | J14: ='C1 - Deconstruction'!B96 -> 0 | K14: ='D- Benefits & Burdens'!N171 -> -1.2947755e-08 | L14: =+SUM(C14:G14) -> 3.2063218e-08 | M14: =SUM(C14:J14) -> 3.2775749e-08
A15: Human toxicity: non-carcinogenic | B15: comparative toxic unit for human (CTUh) | C15: ='A1 - Raw Material Supply'!Z125 -> 6.1179362e-07 | D15: ='C3'' - Secondary Raw Material '!F331 -> 1.8468839e-07 | E15: ='A2 - Transport'!Z129 -> 1.0639367e-08 | F15: ='C2''- Transport Secondary'!H69 -> 1.4947885e-08 | G15: ='A3 - Production '!D216 -> 9.6382678e-08 | H15: ='A4 - Transport'!B28 -> 4.987355e-08 | I15: ='A5 - Construction'!E148 -> 1.654327e-09 | J15: ='C1 - Deconstruction'!B97 -> 0 | K15: ='D- Benefits & Burdens'!N172 -> -4.6033143e-07 | L15: =+SUM(C15:G15) -> 9.1845194e-07 | M15: =SUM(C15:J15) -> 9.6997982e-07
... A22: Water use | B22: user deprivation potential (deprivation-weighted water consumption) m3 world eq deprived | C22: ='A1 - Raw Material Supply'!Z132 -> 9.3844033 | D22: ='C3'' - Secondary Raw Material '!F338 -> 3.4045838 | E22: ='A2 - Transport'!Z136 -> 0.083027999 | F22: ='C2''- Transport Secondary'!H76 -> 0.21279676 | G22: ='A3 - Production '!D223 -> 2.3467328 | H22: ='A4 - Transport'!B35 -> 0.21118341 | I22: ='A5 - Construction'!E155 -> 0.018258328 | J22: ='C1 - Deconstruction'!B104 -> 0 | K22: ='D- Benefits & Burdens'!N179 -> -4.611785 | L22: =+SUM(C22:G22) -> 15.431545 | M22: =SUM(C22:J22) -> 15.660986
A23: Check | B23: =+SUM(C23:K23) -> 0 | C23: =+SUM(C4:C22)-'A1 - Raw Material Supply'!D137 -> 0 | D23: =+SUM(D4:D22)-'C3'' - Secondary Raw Material '!B344 -> 0 | E23: =+SUM(E4:E22)-'A2 - Transport'!B142 -> 0 | F23: =+SUM(F4:F22)-'C2''- Transport Secondary'!B81 -> 0 | G23: =+SUM(G4:G22)-'A3 - Production '!B229 -> 0 | H23: =+SUM(H4:H22)-'A4 - Transport'!B41 -> 0 | I23: =+SUM(I4:I22)-'A5 - Construction'!B162 -> 0 | J23: =+SUM(J4:J22)-'C1 - Deconstruction'!B110 -> 0 | K23: =+SUM(K4:K22)-'D- Benefits & Burdens'!B212 -> 0
A25: Single score per ton of asphalt mix per life cycle stage
A26: The total single score per impact categories are multiplied by 1000 to convert them from Points scale to Millipoint scale
A27: Impact Categories | B27: Normalization factor [unit/person.year] | C27: Weighting factor [%] | D27: A1 - Primary Material | E27: C3' - Secondary Material | F27: A2 - Transport Primary | G27: C2' - Transport Secondary | H27: A3- Production | I27: A4- Transport | J27: A5- Construction | K27: C1 - Deconstruction | L27: D- Burdens & Savings | M27: Total: A1-A3,C2',C3' (excl D) | N27: Total A1-A5,C1,C2',C3' (excl. D) | O27: Total (incl. D)
A28: Acidification | B28: 55.6 | C28: 0.062 | D28: =(C4/$B28)*$C28 -> 0.00027098913 | E28: =(D4/$B28)*$C28 -> 8.3528529e-05 | F28: =(E4/$B28)*$C28 -> 1.5850402e-05 | G28: =(F4/$B28)*$C28 -> 4.1042423e-06 | H28: =(G4/$B28)*$C28 -> 2.9253662e-05 | I28: =(H4/$B28)*$C28 -> 2.122908e-05 | J28: =(I4/$B28)*$C28 -> 1.4479542e-06 | K28: =(J4/$B28)*$C28 -> 0 | L28: =(K4/$B28)*$C28 -> -0.00014419265 | M28: =SUM(D28:H28)*1000 -> 0.40372597 | N28: =SUM(D28:K28)*1000 -> 0.426403 | O28: =SUM(D28:L28)*1000 -> 0.28221036
A29: Climate change | B29: 8100 | C29: 0.2106 | D29: =(C5/$B29)*$C29 -> 0.00083601712 | E29: =(D5/$B29)*$C29 -> 0.00042045966 | F29: =(E5/$B29)*$C29 -> 4.4906032e-05 | G29: =(F5/$B29)*$C29 -> 1.8266664e-05 | H29: =(G5/$B29)*$C29 -> 0.00048770964 | I29: =(H5/$B29)*$C29 -> 0.00018093259 | J29: =(I5/$B29)*$C29 -> 2.6406747e-05 | K29: =(J5/$B29)*$C29 -> 0 | L29: =(K5/$B29)*$C29 -> -0.00097507065 | M29: =SUM(D29:H29)*1000 -> 1.8073591 | N29: =SUM(D29:K29)*1000 -> 2.0146984 | O29: =SUM(D29:L29)*1000 -> 1.0396278
A30: Climate change: biogenic
A31: Climate change: fossil
A32: Land use and land use change
A33: Ecotoxicity: freshwater | B33: 42700 | C33: 0.0192 | D33: =(C9/$B33)*$C33 -> 0.00027355051 | E33: =(D9/$B33)*$C33 -> 5.3473846e-05 | F33: =(E9/$B33)*$C33 -> 9.2158459e-07 | G33: =(F9/$B33)*$C33 -> 1.4153093e-06 | H33: =(G9/$B33)*$C33 -> 8.4183182e-06 | I33: =(H9/$B33)*$C33 -> 2.6592601e-06 | J33: =(I9/$B33)*$C33 -> 2.0177656e-07 | K33: =(J9/$B33)*$C33 -> 0 | L33: =(K9/$B33)*$C33 -> -0.00028223233 | M33: =SUM(D33:H33)*1000 -> 0.33777956 | N33: =SUM(D33:K33)*1000 -> 0.3406406 | O33: =SUM(D33:L33)*1000 -> 0.058408272
A34: Energy resources: non-renewable | B34: 65000 | C34: 0.0755 | D34: =(C10/$B34)*$C34 -> 0.0023262315 | E34: =(D10/$B34)*$C34 -> 0.0001998565 | F34: =(E10/$B34)*$C34 -> 2.6296569e-05 | G34: =(F10/$B34)*$C34 -> 1.8432621e-05 | H34: =(G10/$B34)*$C34 -> 0.00050621538 | I34: =(H10/$B34)*$C34 -> 0.00010867981 | J34: =(I10/$B34)*$C34 -> 1.5669698e-05 | K34: =(J10/$B34)*$C34 -> 0 | L34: =(K10/$B34)*$C34 -> -0.0012845315 | M34: =SUM(D34:H34)*1000 -> 3.0770325 | N34: =SUM(D34:K34)*1000 -> 3.201382 | O34: =SUM(D34:L34)*1000 -> 1.9168505
A35: Eutrophication: freshwater | B35: 1.61 | C35: 0.028 | D35: =(C11/$B35)*$C35 -> 0.00010004381 | E35: =(D11/$B35)*$C35 -> 8.5351283e-05 | F35: =(E11/$B35)*$C35 -> 1.441486e-06 | G35: =(F11/$B35)*$C35 -> 1.6646185e-06 | H35: =(G11/$B35)*$C35 -> 2.8159369e-05 | I35: =(H11/$B35)*$C35 -> 2.7841565e-06 | J35: =(I11/$B35)*$C35 -> 1.8672576e-07 | K35: =(J11/$B35)*$C35 -> 0 | L35: =(K11/$B35)*$C35 -> -5.2351255e-05 | M35: =SUM(D35:H35)*1000 -> 0.21666056 | N35: =SUM(D35:K35)*1000 -> 0.21963145 | O35: =SUM(D35:L35)*1000 -> 0.16728019
A36: Eutrophication: marine | B36: 19.5 | C36: 0.0296 | D36: =(C12/$B36)*$C36 -> 8.0075271e-05 | E36: =(D12/$B36)*$C36 -> 2.946952e-05 | F36: =(E12/$B36)*$C36 -> 6.6520827e-06 | G36: =(F12/$B36)*$C36 -> 3.2414052e-06 | H36: =(G12/$B36)*$C36 -> 9.517869e-06 | I36: =(H12/$B36)*$C36 -> 1.0368686e-05 | J36: =(I12/$B36)*$C36 -> 4.4571595e-07 | K36: =(J12/$B36)*$C36 -> 0 | L36: =(K12/$B36)*$C36 -> -5.6287439e-05 | M36: =SUM(D36:H36)*1000 -> 0.12895615 | N36: =SUM(D36:K36)*1000 -> 0.13977055 | O36: =SUM(D36:L36)*1000 -> 0.08348311
A37: Eutrophication: terrestrial | B37: 177 | C37: 0.0371 | D37: =(C13/$B37)*$C37 -> 0.00012374853 | E37: =(D13/$B37)*$C37 -> 3.3871931e-05 | F37: =(E13/$B37)*$C37 -> 1.0080072e-05 | G37: =(F13/$B37)*$C37 -> 3.0435309e-06 | H37: =(G13/$B37)*$C37 -> 1.3594849e-05 | I37: =(H13/$B37)*$C37 -> 1.5618212e-05 | J37: =(I13/$B37)*$C37 -> 6.6908377e-07 | K37: =(J13/$B37)*$C37 -> 0 | L37: =(K13/$B37)*$C37 -> -8.8716468e-05 | M37: =SUM(D37:H37)*1000 -> 0.18433891 | N37: =SUM(D37:K37)*1000 -> 0.20062621 | O37: =SUM(D37:L37)*1000 -> 0.11190974
A38: Human toxicity: carcinogenic | B38: 1.69e-05 | C38: 0.0213 | D38: =(C14/$B38)*$C38 -> 2.0954849e-05 | E38: =(D14/$B38)*$C38 -> 1.5450768e-05 | F38: =(E14/$B38)*$C38 -> 2.9385515e-07 | G38: =(F14/$B38)*$C38 -> 2.2979148e-07 | H38: =(G14/$B38)*$C38 -> 3.4817741e-06 | I38: =(H14/$B38)*$C38 -> 8.1981721e-07 | J38: =(I14/$B38)*$C38 -> 7.8225896e-08 | K38: =(J14/$B38)*$C38 -> 0 | L38: =(K14/$B38)*$C38 -> -1.6318768e-05 | M38: =SUM(D38:H38)*1000 -> 0.040411037 | N38: =SUM(D38:K38)*1000 -> 0.041309081 | O38: =SUM(D38:L38)*1000 -> 0.024990313
A39: Human toxicity: non-carcinogenic | B39: 0.00023 | C39: 0.0184 | D39: =(C15/$B39)*$C39 -> 4.8943489e-05 | E39: =(D15/$B39)*$C39 -> 1.4775071e-05 | F39: =(E15/$B39)*$C39 -> 8.5114935e-07 | G39: =(F15/$B39)*$C39 -> 1.1958308e-06 | H39: =(G15/$B39)*$C39 -> 7.7106143e-06 | I39: =(H15/$B39)*$C39 -> 3.989884e-06 | J39: =(I15/$B39)*$C39 -> 1.3234616e-07 | K39: =(J15/$B39)*$C39 -> 0 | L39: =(K15/$B39)*$C39 -> -3.6826514e-05 | M39: =SUM(D39:H39)*1000 -> 0.073476155 | N39: =SUM(D39:K39)*1000 -> 0.077598385 | O39: =SUM(D39:L39)*1000 -> 0.040771871
A40: Ionising radiation: human health | B40: 4220 | C40: 0.0501 | D40: =(C16/$B40)*$C40 -> 2.510931e-05 | E40: =(D16/$B40)*$C40 -> 1.2427775e-05 | F40: =(E16/$B40)*$C40 -> 2.3822065e-07 | G40: =(F16/$B40)*$C40 -> 4.6632178e-06 | H40: =(G16/$B40)*$C40 -> 9.307452e-05 | I40: =(H16/$B40)*$C40 -> 5.0009777e-07 | J40: =(I16/$B40)*$C40 -> 4.8089174e-08 | K40: =(J16/$B40)*$C40 -> 0 | L40: =(K16/$B40)*$C40 -> -1.2649697e-05 | M40: =SUM(D40:H40)*1000 -> 0.13551304 | N40: =SUM(D40:K40)*1000 -> 0.13606123 | O40: =SUM(D40:L40)*1000 -> 0.12341153
A41: Land use | B41: 819000 | C41: 0.0794 | D41: =(C17/$B41)*$C41 -> 2.3959576e-05 | E41: =(D17/$B41)*$C41 -> 8.5752212e-06 | F41: =(E17/$B41)*$C41 -> 3.4766517e-07 | G41: =(F17/$B41)*$C41 -> 5.8860433e-07 | H41: =(G17/$B41)*$C41 -> 3.1308644e-06 | I41: =(H17/$B41)*$C41 -> 5.6920775e-07 | J41: =(I17/$B41)*$C41 -> 6.7243244e-08 | K41: =(J17/$B41)*$C41 -> 0 | L41: =(K17/$B41)*$C41 -> -4.8887765e-05 | M41: =SUM(D41:H41)*1000 -> 0.036601931 | N41: =SUM(D41:K41)*1000 -> 0.037238382 | O41: =SUM(D41:L41)*1000 -> -0.011649383
A42: Material resources: metals/minerals | B42: 65000 | C42: 0.0832 | D42: =(C18/$B42)*$C42 -> 3.3410777e-09 | E42: =(D18/$B42)*$C42 -> 1.091159e-10 | F42: =(E18/$B42)*$C42 -> 2.8822186e-12 | G42: =(F18/$B42)*$C42 -> 7.4871373e-12 | H42: =(G18/$B42)*$C42 -> 1.2779831e-10 | I42: =(H18/$B42)*$C42 -> 9.6551718e-12 | J42: =(I18/$B42)*$C42 -> 2.0271529e-13 | K42: =(J18/$B42)*$C42 -> 0 | L42: =(K18/$B42)*$C42 -> -9.910792e-11 | M42: =SUM(D42:H42)*1000 -> 3.5883612e-06 | N42: =SUM(D42:K42)*1000 -> 3.5982191e-06 | O42: =SUM(D42:L42)*1000 -> 3.4991112e-06
A43: Ozone depletion | B43: 0.0536 | C43: 0.0631 | D43: =(C19/$B43)*$C43 -> 3.686716e-07 | E43: =(D19/$B43)*$C43 -> 1.5547611e-07 | F43: =(E19/$B43)*$C43 -> 4.0763507e-08 | G43: =(F19/$B43)*$C43 -> 2.2845104e-08 | H43: =(G19/$B43)*$C43 -> 2.6116144e-06 | I43: =(H19/$B43)*$C43 -> 1.8222948e-07 | J43: =(I19/$B43)*$C43 -> 2.6943643e-08 | K43: =(J19/$B43)*$C43 -> 0 | L43: =(K19/$B43)*$C43 -> -2.9189223e-07 | M43: =SUM(D43:H43)*1000 -> 0.0031993707 | N43: =SUM(D43:K43)*1000 -> 0.0034085438 | O43: =SUM(D43:L43)*1000 -> 0.0031166516
A44: Particulate matter formation | B44: 0.000595 | C44: 0.0896 | D44: =(C20/$B44)*$C44 -> 0.0004374632 | E44: =(D20/$B44)*$C44 -> 0.00030845063 | F44: =(E20/$B44)*$C44 -> 1.7174642e-05 | G44: =(F20/$B44)*$C44 -> 9.3028005e-06 | H44: =(G20/$B44)*$C44 -> 2.2072931e-05 | I44: =(H20/$B44)*$C44 -> 7.0859144e-05 | J44: =(I20/$B44)*$C44 -> 1.5063858e-06 | K44: =(J20/$B44)*$C44 -> 0 | L44: =(K20/$B44)*$C44 -> -0.0002814245 | M44: =SUM(D44:H44)*1000 -> 0.7944642 | N44: =SUM(D44:K44)*1000 -> 0.86682973 | O44: =SUM(D44:L44)*1000 -> 0.58540522
... A46: Water use | B46: 11500 | C46: 0.0851 | D46: =(C22/$B46)*$C46 -> 6.9444585e-05 | E46: =(D22/$B46)*$C46 -> 2.519392e-05 | F46: =(E22/$B46)*$C46 -> 6.1440719e-07 | G46: =(F22/$B46)*$C46 -> 1.5746961e-06 | H46: =(G22/$B46)*$C46 -> 1.7365823e-05 | I46: =(H22/$B46)*$C46 -> 1.5627572e-06 | J46: =(I22/$B46)*$C46 -> 1.3511163e-07 | K46: =(J22/$B46)*$C46 -> 0 | L46: =(K22/$B46)*$C46 -> -3.4127209e-05 | M46: =SUM(D46:H46)*1000 -> 0.11419343 | N46: =SUM(D46:K46)*1000 -> 0.1158913 | O46: =SUM(D46:L46)*1000 -> 0.08176409
A47: Total | C47: =SUM(C28:C46) -> 1 | D47: =SUM(D28:D46)*1000 -> 4.8661056 | E47: =SUM(E28:E46)*1000 -> 1.3536664 | F47: =SUM(F28:F46)*1000 -> 0.14324638 | G47: =SUM(G28:G46)*1000 -> 0.071683222 | H47: =SUM(H28:H46)*1000 -> 1.2577035 | I47: =SUM(I28:I46)*1000 -> 0.45604379 | J47: =SUM(J28:J46)*1000 -> 0.049967363 | K47: =SUM(K28:K46)*1000 -> 0 | L47: =SUM(L28:L46)*1000 -> -3.4761029 | M47: =+SUM(M28:M46) -> 7.6924051 | N47: =+SUM(N28:N46) -> 8.1984162 | O47: =SUM(O28:O46) -> 4.7223133
A50: Global warming impact per ton of asphalt mix per life cycle stage
A51: Same as row 5
...

Sheet A1 - Raw Material Supply
A2: Impacts: Asphalt mix components
A3: Components | B3: Materials | C3: Mass (ton] | D3: List | E3: acidification | accumulated exceedance (AE) mol H+ -eq | F3: climate change | global warming potential (GWP100) kgCO2-Eq | G3: climate change: biogenic | global warming potential (GWP100) kgCO2-Eq | H3: climate change: fossil | global warming potential (GWP100) kgCO2-Eq | I3: land use and land use change | global warming potential (GWP100) kgCO2-Eq | J3: ecotoxicity: freshwater | comparative toxic unit for ecosystems (CTUe) | K3: energy resources: non-renewable | abiotic depletion potential (ADP): fossil fuels MJ, net calorific value | L3: eutrophication: freshwater | fraction of nutrients reaching freshwater end compartment (P) | M3: eutrophication: marine | fraction of nutrients reaching marine end compartment (N) kg N-Eq | N3: eutrophication: terrestrial | accumulated exceedance (AE) mol N-Eq | O3: human toxicity: carcinogenic | comparative toxic unit for human (CTUh) | P3: human toxicity: non-carcinogenic | comparative toxic unit for human (CTUh) | Q3: ionising radiation: human health | human exposure efficiency relative to u235 kBq U235-Eq | R3: land use | soil quality index dimensionless | S3: material resources: metals/minerals | abiotic depletion potential (ADP): elements (ultimate reserves) kg Sb-Eq | T3: ozone depletion|ozone depletion potential (ODP) kg CFC-11-Eq | U3: particulate matter formation | impact on human health | V3: photochemical oxidant formation: human health | tropospheric ozone concentration increase kg NMVOC-Eq | W3: water use | user deprivation potential (deprivation-weighted water consumption) m3 world eq deprived
A4: Binder | B4: =Input!A39 -> Virgin binder | C4: =+Input!B39*(1-Input!E39) -> 0.018 | D4: =Input!$C$39 -> Conventional_Bitumen | E4: {=INDEX(LCI!H$2:H$137,MATCH('A1 - Raw Material Supply'!$B4&'A1 - Raw Material Supply'!$D4,LCI!$B2:$B137&LCI!$D2:$D137,0))*$C4} -> 0.03096 | F4: {=INDEX(LCI!I$2:I$137,MATCH('A1 - Raw Material Supply'!$B4&'A1 - Raw Material Supply'!$D4,LCI!$B2:$B137&LCI!$D2:$D137,0))*$C4} -> 9.54 | G4: {=INDEX(LCI!J$2:J$137,MATCH('A1 - Raw Material Supply'!$B4&'A1 - Raw Material Supply'!$D4,LCI!$B2:$B137&LCI!$D2:$D137,0))*$C4} -> 0.0378 | H4: {=INDEX(LCI!K$2:K$137,MATCH('A1 - Raw Material Supply'!$B4&'A1 - Raw Material Supply'!$D4,LCI!$B2:$B137&LCI!$D2:$D137,0))*$C4} -> 9.504 | I4: {=INDEX(LCI!L$2:L$137,MATCH('A1 - Raw Material Supply'!$B4&'A1 - Raw Material Supply'!$D4,LCI!$B2:$B137&LCI!$D2:$D137,0))*$C4} -> 0.00477 | J4: {=INDEX(LCI!M$2:M$137,MATCH('A1 - Raw Material Supply'!$B4&'A1 - Raw Material Supply'!$D4,LCI!$B2:$B137&LCI!$D2:$D137,0))*$C4} -> 513 | K4: {=INDEX(LCI!N$2:N$137,MATCH('A1 - Raw Material Supply'!$B4&'A1 - Raw Material Supply'!$D4,LCI!$B2:$B137&LCI!$D2:$D137,0))*$C4} -> 824.4 | L4: {=INDEX(LCI!O$2:O$137,MATCH('A1 - Raw Material Supply'!$B4&'A1 - Raw Material Supply'!$D4,LCI!$B2:$B137&LCI!$D2:$D137,0))*$C4} -> 8.01e-06 | ... W4: {=INDEX(LCI!Z$2:Z$137,MATCH('A1 - Raw Material Supply'!$B4&'A1 - Raw Material Supply'!$D4,LCI!$B2:$B137&LCI!$D2:$D137,0))*$C4} -> 0.12978
A5: Aggregate | B5: =Input!A40 -> Virgin crushed coarse aggregate 1 (>2 mm) | C5: =+Input!B40*(1-Input!E40) -> 0 | E5: =INDEX(LCI!H$2:H$130,MATCH('A1 - Raw Material Supply'!$B5,LCI!$D$2:$D$130,0))*$C5 -> 0 | F5: =INDEX(LCI!I$2:I$130,MATCH('A1 - Raw Material Supply'!$B5,LCI!$D$2:$D$130,0))*$C5 -> 0 | G5: =INDEX(LCI!J$2:J$130,MATCH('A1 - Raw Material Supply'!$B5,LCI!$D$2:$D$130,0))*$C5 -> 0 | H5: =INDEX(LCI!K$2:K$130,MATCH('A1 - Raw Material Supply'!$B5,LCI!$D$2:$D$130,0))*$C5 -> 0 | I5: =INDEX(LCI!L$2:L$130,MATCH('A1 - Raw Material Supply'!$B5,LCI!$D$2:$D$130,0))*$C5 -> 0 | J5: =INDEX(LCI!M$2:M$130,MATCH('A1 - Raw Material Supply'!$B5,LCI!$D$2:$D$130,0))*$C5 -> 0 | K5: =INDEX(LCI!N$2:N$130,MATCH('A1 - Raw Material Supply'!$B5,LCI!$D$2:$D$130,0))*$C5 -> 0 | L5: =INDEX(LCI!O$2:O$130,MATCH('A1 - Raw Material Supply'!$B5,LCI!$D$2:$D$130,0))*$C5 -> 0 | ... W5: =INDEX(LCI!Z$2:Z$130,MATCH('A1 - Raw Material Supply'!$B5,LCI!$D$2:$D$130,0))*$C5 -> 0
B6: =Input!A41 -> Virgin crushed coarse aggregate 2 (>2 mm) | C6: =+Input!B41*(1-Input!E41) -> 0.2 | E6: =INDEX(LCI!H$2:H$130,MATCH('A1 - Raw Material Supply'!$B6,LCI!$D$2:$D$130,0))*$C6 -> 0.010887407 | F6: =INDEX(LCI!I$2:I$130,MATCH('A1 - Raw Material Supply'!$B6,LCI!$D$2:$D$130,0))*$C6 -> 0.56578264 | G6: =INDEX(LCI!J$2:J$130,MATCH('A1 - Raw Material Supply'!$B6,LCI!$D$2:$D$130,0))*$C6 -> 0.0017439429 | H6: =INDEX(LCI!K$2:K$130,MATCH('A1 - Raw Material Supply'!$B6,LCI!$D$2:$D$130,0))*$C6 -> 0.56385271 | I6: =INDEX(LCI!L$2:L$130,MATCH('A1 - Raw Material Supply'!$B6,LCI!$D$2:$D$130,0))*$C6 -> 0.0001859889 | J6: =INDEX(LCI!M$2:M$130,MATCH('A1 - Raw Material Supply'!$B6,LCI!$D$2:$D$130,0))*$C6 -> 5.5905857 | K6: =INDEX(LCI!N$2:N$130,MATCH('A1 - Raw Material Supply'!$B6,LCI!$D$2:$D$130,0))*$C6 -> 8.0169956 | L6: =INDEX(LCI!O$2:O$130,MATCH('A1 - Raw Material Supply'!$B6,LCI!$D$2:$D$130,0))*$C6 -> 4.1805746e-05 | ... W6: =INDEX(LCI!Z$2:Z$130,MATCH('A1 - Raw Material Supply'!$B6,LCI!$D$2:$D$130,0))*$C6 -> 0.80512543
B7: =Input!A42 -> Virgin crushed coarse aggregate 3 (>2 mm) | C7: =+Input!B42*(1-Input!E42) -> 0.1 | E7: =INDEX(LCI!H$2:H$130,MATCH('A1 - Raw Material Supply'!$B7,LCI!$D$2:$D$130,0))*$C7 -> 0.0054437035 | F7: =INDEX(LCI!I$2:I$130,MATCH('A1 - Raw Material Supply'!$B7,LCI!$D$2:$D$130,0))*$C7 -> 0.28289132 | G7: =INDEX(LCI!J$2:J$130,MATCH('A1 - Raw Material Supply'!$B7,LCI!$D$2:$D$130,0))*$C7 -> 0.00087197146 | H7: =INDEX(LCI!K$2:K$130,MATCH('A1 - Raw Material Supply'!$B7,LCI!$D$2:$D$130,0))*$C7 -> 0.28192635 | I7: =INDEX(LCI!L$2:L$130,MATCH('A1 - Raw Material Supply'!$B7,LCI!$D$2:$D$130,0))*$C7 -> 9.2994451e-05 | J7: =INDEX(LCI!M$2:M$130,MATCH('A1 - Raw Material Supply'!$B7,LCI!$D$2:$D$130,0))*$C7 -> 2.7952928 | K7: =INDEX(LCI!N$2:N$130,MATCH('A1 - Raw Material Supply'!$B7,LCI!$D$2:$D$130,0))*$C7 -> 4.0084978 | L7: =INDEX(LCI!O$2:O$130,MATCH('A1 - Raw Material Supply'!$B7,LCI!$D$2:$D$130,0))*$C7 -> 2.0902873e-05 | ... W7: =INDEX(LCI!Z$2:Z$130,MATCH('A1 - Raw Material Supply'!$B7,LCI!$D$2:$D$130,0))*$C7 -> 0.40256271
B8: =Input!A43 -> Virgin crushed fine aggregate 1 (≤2 mm) | C8: =+Input!B43*(1-Input!E43) -> 0.06 | E8: =INDEX(LCI!H$2:H$130,MATCH('A1 - Raw Material Supply'!$B8,LCI!$D$2:$D$130,0))*$C8 -> 0.0032662221 | F8: =INDEX(LCI!I$2:I$130,MATCH('A1 - Raw Material Supply'!$B8,LCI!$D$2:$D$130,0))*$C8 -> 0.16973479 | G8: =INDEX(LCI!J$2:J$130,MATCH('A1 - Raw Material Supply'!$B8,LCI!$D$2:$D$130,0))*$C8 -> 0.00052318288 | H8: =INDEX(LCI!K$2:K$130,MATCH('A1 - Raw Material Supply'!$B8,LCI!$D$2:$D$130,0))*$C8 -> 0.16915581 | I8: =INDEX(LCI!L$2:L$130,MATCH('A1 - Raw Material Supply'!$B8,LCI!$D$2:$D$130,0))*$C8 -> 5.5796671e-05 | J8: =INDEX(LCI!M$2:M$130,MATCH('A1 - Raw Material Supply'!$B8,LCI!$D$2:$D$130,0))*$C8 -> 1.6771757 | K8: =INDEX(LCI!N$2:N$130,MATCH('A1 - Raw Material Supply'!$B8,LCI!$D$2:$D$130,0))*$C8 -> 2.4050987 | L8: =INDEX(LCI!O$2:O$130,MATCH('A1 - Raw Material Supply'!$B8,LCI!$D$2:$D$130,0))*$C8 -> 1.2541724e-05 | ... W8: =INDEX(LCI!Z$2:Z$130,MATCH('A1 - Raw Material Supply'!$B8,LCI!$D$2:$D$130,0))*$C8 -> 0.24153763
B9: =Input!A44 -> Virgin crushed fine aggregate 2 (≤2 mm) | C9: =+Input!B44*(1-Input!E44) -> 0 | E9: =INDEX(LCI!H$2:H$130,MATCH('A1 - Raw Material Supply'!$B9,LCI!$D$2:$D$130,0))*$C9 -> 0 | F9: =INDEX(LCI!I$2:I$130,MATCH('A1 - Raw Material Supply'!$B9,LCI!$D$2:$D$130,0))*$C9 -> 0 | G9: =INDEX(LCI!J$2:J$130,MATCH('A1 - Raw Material Supply'!$B9,LCI!$D$2:$D$130,0))*$C9 -> 0 | H9: =INDEX(LCI!K$2:K$130,MATCH('A1 - Raw Material Supply'!$B9,LCI!$D$2:$D$130,0))*$C9 -> 0 | I9: =INDEX(LCI!L$2:L$130,MATCH('A1 - Raw Material Supply'!$B9,LCI!$D$2:$D$130,0))*$C9 -> 0 | J9: =INDEX(LCI!M$2:M$130,MATCH('A1 - Raw Material Supply'!$B9,LCI!$D$2:$D$130,0))*$C9 -> 0 | K9: =INDEX(LCI!N$2:N$130,MATCH('A1 - Raw Material Supply'!$B9,LCI!$D$2:$D$130,0))*$C9 -> 0 | L9: =INDEX(LCI!O$2:O$130,MATCH('A1 - Raw Material Supply'!$B9,LCI!$D$2:$D$130,0))*$C9 -> 0 | ... W9: =INDEX(LCI!Z$2:Z$130,MATCH('A1 - Raw Material Supply'!$B9,LCI!$D$2:$D$130,0))*$C9 -> 0
B10: =Input!A45 -> Virgin crushed fine aggregate 3 (≤2 mm) | C10: =+Input!B45*(1-Input!E45) -> 0.03 | E10: =INDEX(LCI!H$2:H$130,MATCH('A1 - Raw Material Supply'!$B10,LCI!$D$2:$D$130,0))*$C10 -> 0.0016331111 | F10: =INDEX(LCI!I$2:I$130,MATCH('A1 - Raw Material Supply'!$B10,LCI!$D$2:$D$130,0))*$C10 -> 0.084867396 | G10: =INDEX(LCI!J$2:J$130,MATCH('A1 - Raw Material Supply'!$B10,LCI!$D$2:$D$130,0))*$C10 -> 0.00026159144 | H10: =INDEX(LCI!K$2:K$130,MATCH('A1 - Raw Material Supply'!$B10,LCI!$D$2:$D$130,0))*$C10 -> 0.084577906 | I10: =INDEX(LCI!L$2:L$130,MATCH('A1 - Raw Material Supply'!$B10,LCI!$D$2:$D$130,0))*$C10 -> 2.7898335e-05 | J10: =INDEX(LCI!M$2:M$130,MATCH('A1 - Raw Material Supply'!$B10,LCI!$D$2:$D$130,0))*$C10 -> 0.83858785 | K10: =INDEX(LCI!N$2:N$130,MATCH('A1 - Raw Material Supply'!$B10,LCI!$D$2:$D$130,0))*$C10 -> 1.2025493 | L10: =INDEX(LCI!O$2:O$130,MATCH('A1 - Raw Material Supply'!$B10,LCI!$D$2:$D$130,0))*$C10 -> 6.2708619e-06 | ... W10: =INDEX(LCI!Z$2:Z$130,MATCH('A1 - Raw Material Supply'!$B10,LCI!$D$2:$D$130,0))*$C10 -> 0.12076881
B11: =Input!A46 -> Virgin natural fine aggregate 1 (≤2 mm) | C11: =+Input!B46*(1-Input!E46) -> 0.02 | E11: =INDEX(LCI!H$2:H$130,MATCH('A1 - Raw Material Supply'!$B11,LCI!$D$2:$D$130,0))*$C11 -> 0.00091951718 | F11: =INDEX(LCI!I$2:I$130,MATCH('A1 - Raw Material Supply'!$B11,LCI!$D$2:$D$130,0))*$C11 -> 0.10429696 | G11: =INDEX(LCI!J$2:J$130,MATCH('A1 - Raw Material Supply'!$B11,LCI!$D$2:$D$130,0))*$C11 -> -2.5091977e-05 | H11: =INDEX(LCI!K$2:K$130,MATCH('A1 - Raw Material Supply'!$B11,LCI!$D$2:$D$130,0))*$C11 -> 0.1043077 | I11: =INDEX(LCI!L$2:L$130,MATCH('A1 - Raw Material Supply'!$B11,LCI!$D$2:$D$130,0))*$C11 -> 1.435269e-05 | J11: =INDEX(LCI!M$2:M$130,MATCH('A1 - Raw Material Supply'!$B11,LCI!$D$2:$D$130,0))*$C11 -> 0.089073775 | K11: =INDEX(LCI!N$2:N$130,MATCH('A1 - Raw Material Supply'!$B11,LCI!$D$2:$D$130,0))*$C11 -> 1.3556791 | L11: =INDEX(LCI!O$2:O$130,MATCH('A1 - Raw Material Supply'!$B11,LCI!$D$2:$D$130,0))*$C11 -> 4.7041222e-06 | ... W11: =INDEX(LCI!Z$2:Z$130,MATCH('A1 - Raw Material Supply'!$B11,LCI!$D$2:$D$130,0))*$C11 -> 0.1334323
B12: =Input!A47 -> Virgin natural fine aggregate 2 (≤2 mm) | C12: =+Input!B47*(1-Input!E47) -> 0.02 | E12: =INDEX(LCI!H$2:H$130,MATCH('A1 - Raw Material Supply'!$B12,LCI!$D$2:$D$130,0))*$C12 -> 0.00091951718 | F12: =INDEX(LCI!I$2:I$130,MATCH('A1 - Raw Material Supply'!$B12,LCI!$D$2:$D$130,0))*$C12 -> 0.10429696 | G12: =INDEX(LCI!J$2:J$130,MATCH('A1 - Raw Material Supply'!$B12,LCI!$D$2:$D$130,0))*$C12 -> -2.5091977e-05 | H12: =INDEX(LCI!K$2:K$130,MATCH('A1 - Raw Material Supply'!$B12,LCI!$D$2:$D$130,0))*$C12 -> 0.1043077 | I12: =INDEX(LCI!L$2:L$130,MATCH('A1 - Raw Material Supply'!$B12,LCI!$D$2:$D$130,0))*$C12 -> 1.435269e-05 | J12: =INDEX(LCI!M$2:M$130,MATCH('A1 - Raw Material Supply'!$B12,LCI!$D$2:$D$130,0))*$C12 -> 0.089073775 | K12: =INDEX(LCI!N$2:N$130,MATCH('A1 - Raw Material Supply'!$B12,LCI!$D$2:$D$130,0))*$C12 -> 1.3556791 | L12: =INDEX(LCI!O$2:O$130,MATCH('A1 - Raw Material Supply'!$B12,LCI!$D$2:$D$130,0))*$C12 -> 4.7041222e-06 | ... W12: =INDEX(LCI!Z$2:Z$130,MATCH('A1 - Raw Material Supply'!$B12,LCI!$D$2:$D$130,0))*$C12 -> 0.1334323
B13: =Input!A48 -> Virgin natural fine aggregate 3 (≤2 mm) | C13: =+Input!B48*(1-Input!E48) -> 0.02 | E13: =INDEX(LCI!H$2:H$130,MATCH('A1 - Raw Material Supply'!$B13,LCI!$D$2:$D$130,0))*$C13 -> 0.00091951718 | F13: =INDEX(LCI!I$2:I$130,MATCH('A1 - Raw Material Supply'!$B13,LCI!$D$2:$D$130,0))*$C13 -> 0.10429696 | G13: =INDEX(LCI!J$2:J$130,MATCH('A1 - Raw Material Supply'!$B13,LCI!$D$2:$D$130,0))*$C13 -> -2.5091977e-05 | H13: =INDEX(LCI!K$2:K$130,MATCH('A1 - Raw Material Supply'!$B13,LCI!$D$2:$D$130,0))*$C13 -> 0.1043077 | I13: =INDEX(LCI!L$2:L$130,MATCH('A1 - Raw Material Supply'!$B13,LCI!$D$2:$D$130,0))*$C13 -> 1.435269e-05 | J13: =INDEX(LCI!M$2:M$130,MATCH('A1 - Raw Material Supply'!$B13,LCI!$D$2:$D$130,0))*$C13 -> 0.089073775 | K13: =INDEX(LCI!N$2:N$130,MATCH('A1 - Raw Material Supply'!$B13,LCI!$D$2:$D$130,0))*$C13 -> 1.3556791 | L13: =INDEX(LCI!O$2:O$130,MATCH('A1 - Raw Material Supply'!$B13,LCI!$D$2:$D$130,0))*$C13 -> 4.7041222e-06 | ... W13: =INDEX(LCI!Z$2:Z$130,MATCH('A1 - Raw Material Supply'!$B13,LCI!$D$2:$D$130,0))*$C13 -> 0.1334323
A14: Filler | B14: =Input!A49 -> Filler 1 | C14: =+Input!B49*(1-Input!E49) -> 0.01 | D14: =Input!$C$49 -> Cement | E14: {=INDEX(LCI!H$2:H$130,MATCH('A1 - Raw Material Supply'!$B$14&'A1 - Raw Material Supply'!$D$14,LCI!$B$2:$B$130&LCI!$D$2:$D$130,0))*$C14} -> 0.0155713 | F14: {=INDEX(LCI!I$2:I$130,MATCH('A1 - Raw Material Supply'!$B$14&'A1 - Raw Material Supply'!$D$14,LCI!$B$2:$B$130&LCI!$D$2:$D$130,0))*$C14} -> 5.4268669 | G14: {=INDEX(LCI!J$2:J$130,MATCH('A1 - Raw Material Supply'!$B$14&'A1 - Raw Material Supply'!$D$14,LCI!$B$2:$B$130&LCI!$D$2:$D$130,0))*$C14} -> 0.082324045 | H14: {=INDEX(LCI!K$2:K$130,MATCH('A1 - Raw Material Supply'!$B$14&'A1 - Raw Material Supply'!$D$14,LCI!$B$2:$B$130&LCI!$D$2:$D$130,0))*$C14} -> 5.3421646 | I14: {=INDEX(LCI!L$2:L$130,MATCH('A1 - Raw Material Supply'!$B$14&'A1 - Raw Material Supply'!$D$14,LCI!$B$2:$B$130&LCI!$D$2:$D$130,0))*$C14} -> 0.0023781735 | J14: {=INDEX(LCI!M$2:M$130,MATCH('A1 - Raw Material Supply'!$B$14&'A1 - Raw Material Supply'!$D$14,LCI!$B$2:$B$130&LCI!$D$2:$D$130,0))*$C14} -> 14.779543 | K14: {=INDEX(LCI!N$2:N$130,MATCH('A1 - Raw Material Supply'!$B$14&'A1 - Raw Material Supply'!$D$14,LCI!$B$2:$B$130&LCI!$D$2:$D$130,0))*$C14} -> 28.63669 | L14: {=INDEX(LCI!O$2:O$130,MATCH('A1 - Raw Material Supply'!$B$14&'A1 - Raw Material Supply'!$D$14,LCI!$B$2:$B$130&LCI!$D$2:$D$130,0))*$C14} -> 0.00076548598 | ... W14: {=INDEX(LCI!Z$2:Z$130,MATCH('A1 - Raw Material Supply'!$B$14&'A1 - Raw Material Supply'!$D$14,LCI!$B$2:$B$130&LCI!$D$2:$D$130,0))*$C14} -> 0.55942561
B15: =Input!A50 -> Filler 2 | C15: =+Input!B50*(1-Input!E50) -> 0.01 | D15: =Input!$C$50 -> Limestone_residue | E15: {=INDEX(LCI!H$2:H$130,MATCH('A1 - Raw Material Supply'!$B$15&'A1 - Raw Material Supply'!$D$15,LCI!$B$2:$B$130&LCI!$D$2:$D$130,0))*$C15} -> 0.0016923945 | F15: {=INDEX(LCI!I$2:I$130,MATCH('A1 - Raw Material Supply'!$B$15&'A1 - Raw Material Supply'!$D$15,LCI!$B$2:$B$130&LCI!$D$2:$D$130,0))*$C15} -> 0.22120797 | G15: {=INDEX(LCI!J$2:J$130,MATCH('A1 - Raw Material Supply'!$B$15&'A1 - Raw Material Supply'!$D$15,LCI!$B$2:$B$130&LCI!$D$2:$D$130,0))*$C15} -> 0.0034498134 | H15: {=INDEX(LCI!K$2:K$130,MATCH('A1 - Raw Material Supply'!$B$15&'A1 - Raw Material Supply'!$D$15,LCI!$B$2:$B$130&LCI!$D$2:$D$130,0))*$C15} -> 0.2173843 | I15: {=INDEX(LCI!L$2:L$130,MATCH('A1 - Raw Material Supply'!$B$15&'A1 - Raw Material Supply'!$D$15,LCI!$B$2:$B$130&LCI!$D$2:$D$130,0))*$C15} -> 0.00037385459 | J15: {=INDEX(LCI!M$2:M$130,MATCH('A1 - Raw Material Supply'!$B$15&'A1 - Raw Material Supply'!$D$15,LCI!$B$2:$B$130&LCI!$D$2:$D$130,0))*$C15} -> 0.69050089 | K15: {=INDEX(LCI!N$2:N$130,MATCH('A1 - Raw Material Supply'!$B$15&'A1 - Raw Material Supply'!$D$15,LCI!$B$2:$B$130&LCI!$D$2:$D$130,0))*$C15} -> 3.7042402 | L15: {=INDEX(LCI!O$2:O$130,MATCH('A1 - Raw Material Supply'!$B$15&'A1 - Raw Material Supply'!$D$15,LCI!$B$2:$B$130&LCI!$D$2:$D$130,0))*$C15} -> 0.00013291985 | ... W15: {=INDEX(LCI!Z$2:Z$130,MATCH('A1 - Raw Material Supply'!$B$15&'A1 - Raw Material Supply'!$D$15,LCI!$B$2:$B$130&LCI!$D$2:$D$130,0))*$C15} -> 0.46168314
A16: Reclaimed Asphalt Pavement | B16: =Input!A51 -> RAP 1
B17: =Input!A52 -> RAP 2
A18: Recycled Waste | B18: =Input!A53 -> Other_waste 1
B19: =Input!A54 -> Other_waste 2
A20: Additive | B20: =Input!A55 -> Additive 1 | C20: =+Input!B55*(1-Input!E55) -> 0.02 | D20: =Input!$C$55 -> Cellulose_fibres | E20: {=INDEX(LCI!H$2:H$130,MATCH('A1 - Raw Material Supply'!$B$20&'A1 - Raw Material Supply'!$D$20,LCI!$B$2:$B$130&LCI!$D$2:$D$130,0))*$C$20} -> 0.031617304 | F20: {=INDEX(LCI!I$2:I$130,MATCH('A1 - Raw Material Supply'!$B$20&'A1 - Raw Material Supply'!$D$20,LCI!$B$2:$B$130&LCI!$D$2:$D$130,0))*$C$20} -> 3.9650622 | G20: {=INDEX(LCI!J$2:J$130,MATCH('A1 - Raw Material Supply'!$B$20&'A1 - Raw Material Supply'!$D$20,LCI!$B$2:$B$130&LCI!$D$2:$D$130,0))*$C$20} -> 0.64768552 | H20: {=INDEX(LCI!K$2:K$130,MATCH('A1 - Raw Material Supply'!$B$20&'A1 - Raw Material Supply'!$D$20,LCI!$B$2:$B$130&LCI!$D$2:$D$130,0))*$C$20} -> 3.3146438 | I20: {=INDEX(LCI!L$2:L$130,MATCH('A1 - Raw Material Supply'!$B$20&'A1 - Raw Material Supply'!$D$20,LCI!$B$2:$B$130&LCI!$D$2:$D$130,0))*$C$20} -> 0.0027329105 | J20: {=INDEX(LCI!M$2:M$130,MATCH('A1 - Raw Material Supply'!$B$20&'A1 - Raw Material Supply'!$D$20,LCI!$B$2:$B$130&LCI!$D$2:$D$130,0))*$C$20} -> 16.559907 | K20: {=INDEX(LCI!N$2:N$130,MATCH('A1 - Raw Material Supply'!$B$20&'A1 - Raw Material Supply'!$D$20,LCI!$B$2:$B$130&LCI!$D$2:$D$130,0))*$C$20} -> 45.769593 | L20: {=INDEX(LCI!O$2:O$130,MATCH('A1 - Raw Material Supply'!$B$20&'A1 - Raw Material Supply'!$D$20,LCI!$B$2:$B$130&LCI!$D$2:$D$130,0))*$C$20} -> 0.0010455422 | ... W20: {=INDEX(LCI!Z$2:Z$130,MATCH('A1 - Raw Material Supply'!$B$20&'A1 - Raw Material Supply'!$D$20,LCI!$B$2:$B$130&LCI!$D$2:$D$130,0))*$C$20} -> 2.001299
B21: =Input!A56 -> Additive 2 | C21: =+Input!B56*(1-Input!E56) -> 0.02 | D21: =Input!$C$56 -> Rejuvenator_waxy | E21: {=INDEX(LCI!H$2:H$130,MATCH('A1 - Raw Material Supply'!$B$21&'A1 - Raw Material Supply'!$D$21,LCI!$B$2:$B$130&LCI!$D$2:$D$130,0))*$C$21} -> 0.10642676 | F21: {=INDEX(LCI!I$2:I$130,MATCH('A1 - Raw Material Supply'!$B$21&'A1 - Raw Material Supply'!$D$21,LCI!$B$2:$B$130&LCI!$D$2:$D$130,0))*$C$21} -> 13.480138 | G21: {=INDEX(LCI!J$2:J$130,MATCH('A1 - Raw Material Supply'!$B$21&'A1 - Raw Material Supply'!$D$21,LCI!$B$2:$B$130&LCI!$D$2:$D$130,0))*$C$21} -> 0.038906542 | H21: {=INDEX(LCI!K$2:K$130,MATCH('A1 - Raw Material Supply'!$B$21&'A1 - Raw Material Supply'!$D$21,LCI!$B$2:$B$130&LCI!$D$2:$D$130,0))*$C$21} -> 13.438138 | I21: {=INDEX(LCI!L$2:L$130,MATCH('A1 - Raw Material Supply'!$B$21&'A1 - Raw Material Supply'!$D$21,LCI!$B$2:$B$130&LCI!$D$2:$D$130,0))*$C$21} -> 0.003093237 | J21: {=INDEX(LCI!M$2:M$130,MATCH('A1 - Raw Material Supply'!$B$21&'A1 - Raw Material Supply'!$D$21,LCI!$B$2:$B$130&LCI!$D$2:$D$130,0))*$C$21} -> 24.366204 | K21: {=INDEX(LCI!N$2:N$130,MATCH('A1 - Raw Material Supply'!$B$21&'A1 - Raw Material Supply'!$D$21,LCI!$B$2:$B$130&LCI!$D$2:$D$130,0))*$C$21} -> 1033.5055 | L21: {=INDEX(LCI!O$2:O$130,MATCH('A1 - Raw Material Supply'!$B$21&'A1 - Raw Material Supply'!$D$21,LCI!$B$2:$B$130&LCI!$D$2:$D$130,0))*$C$21} -> 0.0026501851 | ... W21: {=INDEX(LCI!Z$2:Z$130,MATCH('A1 - Raw Material Supply'!$B$21&'A1 - Raw Material Supply'!$D$21,LCI!$B$2:$B$130&LCI!$D$2:$D$130,0))*$C$21} -> 2.158225
B22: =Input!A57 -> Additive 3 | C22: =+Input!B57*(1-Input!E57) -> 0.02 | D22: =Input!$C$57 -> Cellulose_fibres | E22: {=INDEX(LCI!H$2:H$130,MATCH('A1 - Raw Material Supply'!$B$22&'A1 - Raw Material Supply'!$D$22,LCI!$B$2:$B$130&LCI!$D$2:$D$130,0))*$C$22} -> 0.031617304 | F22: {=INDEX(LCI!I$2:I$130,MATCH('A1 - Raw Material Supply'!$B$22&'A1 - Raw Material Supply'!$D$22,LCI!$B$2:$B$130&LCI!$D$2:$D$130,0))*$C$22} -> 3.9650622 | G22: {=INDEX(LCI!J$2:J$130,MATCH('A1 - Raw Material Supply'!$B$22&'A1 - Raw Material Supply'!$D$22,LCI!$B$2:$B$130&LCI!$D$2:$D$130,0))*$C$22} -> 0.64768552 | H22: {=INDEX(LCI!K$2:K$130,MATCH('A1 - Raw Material Supply'!$B$22&'A1 - Raw Material Supply'!$D$22,LCI!$B$2:$B$130&LCI!$D$2:$D$130,0))*$C$22} -> 3.3146438 | I22: {=INDEX(LCI!L$2:L$130,MATCH('A1 - Raw Material Supply'!$B$22&'A1 - Raw Material Supply'!$D$22,LCI!$B$2:$B$130&LCI!$D$2:$D$130,0))*$C$22} -> 0.0027329105 | J22: {=INDEX(LCI!M$2:M$130,MATCH('A1 - Raw Material Supply'!$B$22&'A1 - Raw Material Supply'!$D$22,LCI!$B$2:$B$130&LCI!$D$2:$D$130,0))*$C$22} -> 16.559907 | K22: {=INDEX(LCI!N$2:N$130,MATCH('A1 - Raw Material Supply'!$B$22&'A1 - Raw Material Supply'!$D$22,LCI!$B$2:$B$130&LCI!$D$2:$D$130,0))*$C$22} -> 45.769593 | L22: {=INDEX(LCI!O$2:O$130,MATCH('A1 - Raw Material Supply'!$B$22&'A1 - Raw Material Supply'!$D$22,LCI!$B$2:$B$130&LCI!$D$2:$D$130,0))*$C$22} -> 0.0010455422 | ... W22: {=INDEX(LCI!Z$2:Z$130,MATCH('A1 - Raw Material Supply'!$B$22&'A1 - Raw Material Supply'!$D$22,LCI!$B$2:$B$130&LCI!$D$2:$D$130,0))*$C$22} -> 2.001299
A23: Total | C23: =SUM(C4:C22) -> 0.548 | E23: =SUM(E4:E22) -> 0.24187406 | F23: =SUM(F4:F22) -> 38.014504 | G23: =SUM(G4:G22) -> 1.4611768 | H23: =SUM(H4:H22) -> 36.543411 | I23: =SUM(I4:I22) -> 0.016486822 | J23: =SUM(J4:J22) -> 597.12493 | K23: =SUM(K4:K22) -> 2001.4858 | L23: =SUM(L4:L22) -> 0.0057433189 | ... W23: =SUM(W4:W22) -> 9.2820033
A26: Impacts: Biogenic asphalt mix components
A27: Components | B27: Materials | C27: Mass (ton] | D27: List | E27: acidification | accumulated exceedance (AE) mol H+ -eq | F27: climate change | global warming potential (GWP100) kgCO2-Eq | G27: climate change: biogenic | global warming potential (GWP100) kgCO2-Eq | H27: climate change: fossil | global warming potential (GWP100) kgCO2-Eq | I27: land use and land use change | global warming potential (GWP100) kgCO2-Eq | J27: ecotoxicity: freshwater | comparative toxic unit for ecosystems (CTUe) | K27: energy resources: non-renewable | abiotic depletion potential (ADP): fossil fuels MJ, net calorific value | L27: eutrophication: freshwater | fraction of nutrients reaching freshwater end compartment (P) | M27: eutrophication: marine | fraction of nutrients reaching marine end compartment (N) kg N-Eq | N27: eutrophication: terrestrial | accumulated exceedance (AE) mol N-Eq | O27: human toxicity: carcinogenic | comparative toxic unit for human (CTUh) | P27: human toxicity: non-carcinogenic | comparative toxic unit for human (CTUh) | Q27: ionising radiation: human health | human exposure efficiency relative to u235 kBq U235-Eq | R27: land use | soil quality index dimensionless | S27: material resources: metals/minerals | abiotic depletion potential (ADP): elements (ultimate reserves) kg Sb-Eq | T27: ozone depletion|ozone depletion potential (ODP) kg CFC-11-Eq | U27: particulate matter formation | impact on human health | V27: photochemical oxidant formation: human health | tropospheric ozone concentration increase kg NMVOC-Eq | W27: water use | user deprivation potential (deprivation-weighted water consumption) m3 world eq deprived
A28: Binder | B28: Binder_biogenic | C28: =Input!B39*Input!E39 -> 0.002 | D28: =Input!$D39 -> Binder_bio | E28: {=_xlfn.IFNA(INDEX(LCI!H$2:H$137,MATCH('A1 - Raw Material Supply'!$B$28&'A1 - Raw Material Supply'!$D$28,LCI!$B$2:$B$137&LCI!$D$2:$D$137,0))*$C28,0)} -> 0.001142 | F28: {=_xlfn.IFNA(INDEX(LCI!I$2:I$137,MATCH('A1 - Raw Material Supply'!$B$28&'A1 - Raw Material Supply'!$D$28,LCI!$B$2:$B$137&LCI!$D$2:$D$137,0))*$C28,0)} -> -5.86 | G28: {=_xlfn.IFNA(INDEX(LCI!J$2:J$137,MATCH('A1 - Raw Material Supply'!$B$28&'A1 - Raw Material Supply'!$D$28,LCI!$B$2:$B$137&LCI!$D$2:$D$137,0))*$C28,0)} -> -6 | H28: {=_xlfn.IFNA(INDEX(LCI!K$2:K$137,MATCH('A1 - Raw Material Supply'!$B$28&'A1 - Raw Material Supply'!$D$28,LCI!$B$2:$B$137&LCI!$D$2:$D$137,0))*$C28,0)} -> 0.138 | I28: {=_xlfn.IFNA(INDEX(LCI!L$2:L$137,MATCH('A1 - Raw Material Supply'!$B$28&'A1 - Raw Material Supply'!$D$28,LCI!$B$2:$B$137&LCI!$D$2:$D$137,0))*$C28,0)} -> 0.00048 | J28: {=_xlfn.IFNA(INDEX(LCI!M$2:M$137,MATCH('A1 - Raw Material Supply'!$B$28&'A1 - Raw Material Supply'!$D$28,LCI!$B$2:$B$137&LCI!$D$2:$D$137,0))*$C28,0)} -> 11.24 | K28: {=_xlfn.IFNA(INDEX(LCI!N$2:N$137,MATCH('A1 - Raw Material Supply'!$B$28&'A1 - Raw Material Supply'!$D$28,LCI!$B$2:$B$137&LCI!$D$2:$D$137,0))*$C28,0)} -> 1.23 | L28: {=_xlfn.IFNA(INDEX(LCI!O$2:O$137,MATCH('A1 - Raw Material Supply'!$B$28&'A1 - Raw Material Supply'!$D$28,LCI!$B$2:$B$137&LCI!$D$2:$D$137,0))*$C28,0)} -> 9.2e-06 | ... W28: {=_xlfn.IFNA(INDEX(LCI!Z$2:Z$137,MATCH('A1 - Raw Material Supply'!$B$28&'A1 - Raw Material Supply'!$D$28,LCI!$B$2:$B$137&LCI!$D$2:$D$137,0))*$C28,0)} -> 0.1024
A29: Aggregate | B29: =Input!A40 -> Virgin crushed coarse aggregate 1 (>2 mm)
B30: =Input!A41 -> Virgin crushed coarse aggregate 2 (>2 mm)
B31: =Input!A42 -> Virgin crushed coarse aggregate 3 (>2 mm)
B32: =Input!A43 -> Virgin crushed fine aggregate 1 (≤2 mm)
B33: =Input!A44 -> Virgin crushed fine aggregate 2 (≤2 mm)
B34: =Input!A45 -> Virgin crushed fine aggregate 3 (≤2 mm)
B35: =Input!A46 -> Virgin natural fine aggregate 1 (≤2 mm)
B36: =Input!A47 -> Virgin natural fine aggregate 2 (≤2 mm)
B37: =Input!A48 -> Virgin natural fine aggregate 3 (≤2 mm)
A38: Filler | B38: =Input!A49 -> Filler 1
B39: =Input!A50 -> Filler 2
A40: Reclaimed Asphalt Pavement | B40: =Input!A51 -> RAP 1
B41: =Input!A52 -> RAP 2
A42: Recycled Waste | B42: =Input!A53 -> Other_waste 1
B43: =Input!A54 -> Other_waste 2
...

Sheet C3' - Secondary Raw Material 
A1: Waste Processing
A2: The processing of waste comprises of two sections A: Reclamed Asphalt Pavement and Recycled Concrete Aggregate) processing and B; Crumb rubber recycling.
A4: A. Reclaimed Asphalt Pavement (RAP) and Recycled Concrete Aggregate (RCA) Processing Input Parameters
A6: RAP processing | B6: Type | C6: Energy source
A7: Crushing of reclaimed asphalt pavement | B7: Mobile_jaw_crusher_400tph_RAP | C7: Diesel
A8: Stacking of RCA by a wheel loader | B8: Wheel_loader_338tph_Komatsu_WA500_RAP | C8: Diesel
A9: Conveying of RCA in a conveyor belt (feeders) | B9: Tracked_stacker_500tph_RAP | C9: Diesel
A10: Screening operation by mobile screener | B10: Mobile_screener_500tph_RAP | C10: Diesel
A13: RCA Processing | B13: Type | C13: Energy source
A14: Crushing of recycled concrete aggregate | B14: Mobile_jaw_crusher_400tph_RCA | C14: Diesel
A15: Stacking of RCA by a wheel loader | B15: Wheel_loader_338tph_Komatsu_WA500_RCA | C15: Diesel
A16: Conveying of RCA in a conveyor belt (feeders) | B16: Tracked_stacker_500tph_RCA | C16: Diesel
A17: Screening operation by mobile screener | B17: Mobile_screener_500tph_RCA | C17: Diesel
A20: Electric equipment load factor | B20: 0.51 | C20: Load factor for all electric equipments
A26: Step 1: Reclaimed Asphalt Pavement Processing
A27: 1a. Wheel loading operations RAP
A29: Details | B29: Input | C29: Source | D29: Source link
A30: Type of wheel loader | B30: Komatsu WA500 | C30: Komatsu Wheel Loader WA500-8 | D30: https://www.komatsu.eu/en/wheel-loaders/wheel-loaders/wa500-8
A31: Number of wheel loaders | B31: 1
A32: Power rating (kW) | B32: 263.2 | C32: Komatsu Wheel Loader WA500-8 | D32: https://www.komatsu.eu/en/wheel-loaders/wheel-loaders/wa500-8
A33: Load factor (steady state) | B33: 0.51 | C33: Median Life, Annual Activity, and Load Factor Values for Nonroad Engine Emissions Modeling - Report No. NR-005A (1998)
A34: Specific fuel consumption (kg/kWh/h) | B34: 0.25 | C34: Klanfar, Mario & Korman, Tomislav & Kujundžić, Trpimir. (2016). Fuel consumption and engine load factors of equipment in quarrying of crushed stone. Tehnicki Vjesnik. 23. 163-169. 10.17559/TV-20141027115647. | D34: https://doi.org/10.17559/TV-20141027115647
A35: Density of RAP (ton/m3) | B35: 2.2 | C35: User Guidelines for Waste and Byproduct Materials in Pavement Construction; Publication Number: FHWA-RD-97-148 | D35: https://www.fhwa.dot.gov/publications/research/infrastructure/pavements/97148/046.cfm
A36: Cycle time in minutes | B36: 0.45 | C36: SEBD0351-42, Caterpillar English Performance Handbook, Edition 42, Section
