Workbook
Name Barge: 'Aux - Lists'!$D$5
Name Barge_tanker: 'Aux - Lists'!$E$5
Name Crusher_types_RAP: 'Aux - Lists'!$A$48:$A$49
Name Crusher_types_RCA: 'Aux - Lists'!$A$58:$A$59
Name Electric_component: 'Aux - Lists'!$A$169:$A$170
Name Excavator_Hitachi_ZX1357_160kW: 'Aux - Lists'!$C$146:$C$153
Name Excavator_types: 'Aux - Lists'!$A$145:$A$146
Name Milling_large_scale_project_Wirtgen_W250Fi_753kW: 'Aux - Lists'!$E$135:$E$142
Name Milling_medium_scale_project_Wirtgen_W210XPi_571kW: 'Aux - Lists'!$D$135:$D$142
Name Milling_small_scale_project_Wirtgen_W35Ri_45kW: 'Aux - Lists'!$C$135:$C$142
Name Milling_types: 'Aux - Lists'!$A$134:$A$137
Name Mobile_jaw_crusher_400tph_RAP: 'Aux - Lists'!$C$48:$C$55
Name Mobile_jaw_crusher_400tph_RCA: 'Aux - Lists'!$C$58:$C$65
Name Mobile_screener_500tph_RAP: 'Aux - Lists'!$C$91:$C$98
Name Mobile_screener_500tph_RCA: 'Aux - Lists'!$C$101:$C$108
Name No: 'Aux - Lists'!$B$5
Name No_crusher_RAP: 'Aux - Lists'!$B$48
Name No_crusher_RCA: 'Aux - Lists'!$B$58
Name No_excavator: 'Aux - Lists'!$B$145
Name No_milling_machine: 'Aux - Lists'!$B$134
Name No_paver: 'Aux - Lists'!$B$112
Name No_roller: 'Aux - Lists'!$B$123
Name No_screener_RAP: 'Aux - Lists'!$B$91
Name No_screener_RCA: 'Aux - Lists'!$B$101
Name No_stacker_RAP: 'Aux - Lists'!$B$68
Name No_stacker_RCA: 'Aux - Lists'!$B$80
Name No_sweeper_truck: 'Aux - Lists'!$B$156
Name No_wheel_loader: 'Aux - Lists'!$B$17
Name Paver_large_scale_project_354kW: 'Aux - Lists'!$E$112:$E$119
Name Paver_medium_scale_project_129kW: 'Aux - Lists'!$D$112:$D$119
Name Paver_small_scale_project_25kW: 'Aux - Lists'!$C$112:$C$119
Name Paver_types: 'Aux - Lists'!$A$112:$A$115
Name Roller_large_scale_project_100kW: 'Aux - Lists'!$E$124:$E$131
Name Roller_medium_scale_project_55kW: 'Aux - Lists'!$D$124:$D$131
Name Roller_small_scale_project_30kW: 'Aux - Lists'!$C$124:$C$131
Name Roller_types: 'Aux - Lists'!$A$123:$A$126
Name Screener_types_RAP: 'Aux - Lists'!$A$91:$A$92
Name Screener_types_RCA: 'Aux - Lists'!$A$101:$A$102
Name Ship: 'Aux - Lists'!$F$5
Name Stacker_types_RAP: 'Aux - Lists'!$A$68:$A$69
Name Stacker_types_RCA: 'Aux - Lists'!$A$80:$A$81
Name Sweeper_truck_volvo_186kW: 'Aux - Lists'!$C$157:$C$164
Name Tracked_stacker_500tph_RAP: 'Aux - Lists'!$C$68:$C$75
Name Tracked_stacker_500tph_RCA: 'Aux - Lists'!$C$80:$C$87
Name Train: 'Aux - Lists'!$G$5:$G$6
Name Transport_mode: 'Aux - Lists'!$A$5:$A$10
Name Truck: 'Aux - Lists'!$C$5:$C$13
Name Types_sweeper_truck: 'Aux - Lists'!$A$156:$A$157
Name Wheel_loader_338tph_Komatsu_WA500: 'Aux - Lists'!$C$17:$C$24
Name Wheel_loader_338tph_Komatsu_WA500_RAP: 'Aux - Lists'!$C$28:$C$35
Name Wheel_loader_338tph_Komatsu_WA500_RCA: 'Aux - Lists'!$C$38:$C$45
Name Wheel_loader_types: 'Aux - Lists'!$A$17:$A$18
Name Wheel_loader_types_RAP: 'Aux - Lists'!$A$28:$A$29
Name Wheel_loader_types_RCA: 'Aux - Lists'!$A$38:$A$39
Name Yes: 'Aux - Lists'!$B$169:$B$170

Sheet ReadMe
A2: This LCA-based tool has been developed by the University of Antwerp as part of the PIONEERS (Portable Innovation Open Network for Efficiency and Emissions Reduction Solutions) project using funding from the European Union’s Horizon 2020 research and innovation programme under Grant Agreement 101037564.
A4: https://pioneers-ports.eu/
A5: https://cordis.europa.eu/project/id/101037564
A12: Use of this spreadsheet is restricted to consortium partners during the duration of the project only (from Oct 1, 2021 to Sep 30, 2026). This spreadsheet contains confidential information that falls under the regulations of the collaboration agreement of the PIONEERS project.
A15: Version 2.1 (released date: March 31, 2025)
A17: For more information and access, contact the Sustainable Pavements and Asphalt Research (SuPAR) group at the University of Antwerp.

Sheet Input
A1: Data collection form for LCA-based tool
A4: 1. General Information | C4: Example
A5: Date | B5: 40409 | C5: 45747
A6: Mixture ID | B6: 801/64/2010/13RE-1234/0 | C6: 2221
A7: Mixture type (SB250) | B7: AB-3A1 | C7: APO-A
A8: Mixture type (EN 13108) | B8: AC 20 onderlaag 50/70 | C8: AC 20 base 70/100
A9: Total binder cotent (by weight of mix) | B9: 0.03716 | C9: 0.043
A10: Asphalt binder replacement | B10: =(B9-B39)/B9 -> 0.40365985
A13: 2. Mixture Production
A14: Asphalt plant location (city/town) | B14: straat 1, 1000 Gaurain-Ramecroix
A15: Plant type | B15: Batch with parallel drum
A16: Average hour plant production (t/h) | B16: 350
A17: Asphalt plant: primary energy source type for heating and drying | B17: Natural_gas | C17: 1 | D17: =IF(AND(C17 + C18 = 100%, OR(B18 <> "No", C18 = 0%)), "Correct", IF(B18 = "No", "Error", "Error: Check %")) -> Correct
A18: Asphalt plant: secondary energy source type for heating and drying | B18: No | C18: 0
A19: Asphalt plant: electric components | B19: Yes | C19: Electricity | D19: =IF(OR(AND(B19="Yes", C19<>"No"), AND(B19="No",C19="No")), "Correct", "Error") -> Correct
A20: Secondary energy source for asphalt plant operation & percentage | B20: No
A21: Mixture production temperature range (°C) | B21: 155⁰C - 185⁰C
A22: Mixture bulk density (SVM) (kg/m3) | B22: 2400
B25: Type | C25: Energy source
A26: Asphalt mix loading operation | B26: Wheel_loader_338tph_Komatsu_WA500 | C26: Diesel | D26: =IF(OR(AND(B26="No_wheel_loader", C26<>"No"), AND(C26="No", B26<>"No_wheel_loader")), "Error", "") | U26: =IF(OR(AND(B26="No_wheel_loader", C26<>"No"), AND(C26="No", B26<>"No_wheel_loader")), 1, 0) -> 0
A29: 3. Layer Specifications
A30: Layer | B30: Thickness (mm) | C30: Mass per FU (ton/m2)
A31: Wearing Course 1 | B31: 80 | C31: =($B$22/1000)*($B$31/1000) -> 0.192
A34: 4. Mixture Components and Transporation Distances
A35: - For virgin binder, enter the location and transportation mode and distance from the refinery - For aggregate and filler, enter the location and transportation mode and distance from the quarry - For waste, enter the location and transportation mode and distance from the processing plant - For additives, enter the location and transportation mode and distance from the factory
A36: Mixture Components | B36: % (by weight of mixture) | C36: Type | D36: Biogenic origin - type | E36: % Biogenic content (by weight of product) | F36: Biogenic status | G36: Stockpile covered? | H36: Transportation distance (km) from point of extraction to asphalt plant and fuel type
H37: Location (city/town) | I37: Transport status | J37: Route 1 | M37: Route 2 | P37: Route 3
J38: Mode of transport | K38: Energy source | L38: Distance (km) | M38: Mode of transport | N38: Energy source | O38: Distance (km) | P38: Mode of transport | Q38: Energy source | R38: Distance (km) | T38: List | U38: Check
A39: Virgin binder | B39: 0.02216 | C39: Conventional_Bitumen | D39: No | E39: 0 | F39: =IF(AND(D39="No",E39>0), "Check biogenic content","Correct") -> Correct | H39: Koudekerk-aan-de-Rijn | I39: =IF($B39=0%,"Do not fill Transport", "Fill Transport") -> Fill Transport | J39: Truck | K39: Diesel_Euro6 | L39: 262 | M39: No | N39: No | O39: 0 | P39: No | Q39: No | R39: 0 | U39: =+IF(B39>0,IF(K39="No",1,IF(SUM(L39,O39,R39)>0,0,2)),0) -> 0
A40: Virgin crushed coarse aggregate 1 (>2 mm) | B40: 0 | G40: No | H40: Productieproces | I40: =IF($B40=0%,"Do not fill Transport", "Fill Transport") -> Do not fill Transport | J40: Truck | K40: Diesel_Euro6 | L40: 0 | M40: No | N40: No | O40: 0 | P40: No | Q40: No | R40: 0 | U40: =+IF(B40>0,IF(K40="No",1,IF(SUM(L40,O40,R40)>0,0,2)),0) -> 0
A41: Virgin crushed coarse aggregate 2 (>2 mm) | B41: 0.102 | G41: No | H41: Soignies | I41: =IF($B41=0%,"Do not fill Transport", "Fill Transport") -> Fill Transport | J41: Barge | K41: Diesel | L41: 51 | M41: No | N41: No | O41: 0 | P41: No | Q41: No | R41: 0 | U41: =+IF(B41>0,IF(K41="No",1,IF(SUM(L41,O41,R41)>0,0,2)),0) -> 0
A42: Virgin crushed coarse aggregate 3 (>2 mm) | B42: 0.353 | G42: Yes | H42: Genk | I42: =IF($B42=0%,"Do not fill Transport", "Fill Transport") -> Fill Transport | J42: Truck | K42: Diesel_Euro6 | L42: 188 | M42: No | N42: No | O42: 0 | P42: No | Q42: No | R42: 0 | U42: =+IF(B42>0,IF(K42="No",1,IF(SUM(L42,O42,R42)>0,0,2)),0) -> 0
A43: Virgin crushed fine aggregate 1 (≤2 mm) | B43: 0 | G43: No | H43: Gaurain-Ramecroix | I43: =IF($B43=0%,"Do not fill Transport", "Fill Transport") -> Do not fill Transport | J43: No | K43: No | L43: 0 | M43: No | N43: No | O43: 0 | P43: No | Q43: No | R43: 0 | U43: =+IF(B43>0,IF(K43="No",1,IF(SUM(L43,O43,R43)>0,0,2)),0) -> 0
A44: Virgin crushed fine aggregate 2 (≤2 mm) | B44: 0 | G44: No | I44: =IF($B44=0%,"Do not fill Transport", "Fill Transport") -> Do not fill Transport | J44: No | K44: No | L44: 0 | M44: No | N44: No | O44: 0 | P44: No | Q44: No | R44: 0 | U44: =+IF(B44>0,IF(K44="No",1,IF(SUM(L44,O44,R44)>0,0,2)),0) -> 0
A45: Virgin crushed fine aggregate 3 (≤2 mm) | B45: 0 | G45: No | I45: =IF($B45=0%,"Do not fill Transport", "Fill Transport") -> Do not fill Transport | J45: No | K45: No | L45: 0 | M45: No | N45: No | O45: 0 | P45: No | Q45: No | R45: 0 | U45: =+IF(B45>0,IF(K45="No",1,IF(SUM(L45,O45,R45)>0,0,2)),0) -> 0
A46: Virgin natural fine aggregate 1 (≤2 mm) | B46: 0.153 | G46: No | H46: Neufvilles | I46: =IF($B46=0%,"Do not fill Transport", "Fill Transport") -> Fill Transport | J46: Barge | K46: Diesel | L46: 44 | M46: No | N46: No | O46: 0 | P46: No | Q46: No | R46: 0 | U46: =+IF(B46>0,IF(K46="No",1,IF(SUM(L46,O46,R46)>0,0,2)),0) -> 0
A47: Virgin natural fine aggregate 2 (≤2 mm) | B47: 0 | G47: No | I47: =IF($B47=0%,"Do not fill Transport", "Fill Transport") -> Do not fill Transport | J47: No | K47: No | L47: 0 | M47: No | N47: No | O47: 0 | P47: No | Q47: No | R47: 0 | U47: =+IF(B47>0,IF(K47="No",1,IF(SUM(L47,O47,R47)>0,0,2)),0) -> 0
A48: Virgin natural fine aggregate 3 (≤2 mm) | B48: 0 | G48: No | I48: =IF($B48=0%,"Do not fill Transport", "Fill Transport") -> Do not fill Transport | J48: No | K48: No | L48: 0 | M48: No | N48: No | O48: 0 | P48: No | Q48: No | R48: 0 | U48: =+IF(B48>0,IF(K48="No",1,IF(SUM(L48,O48,R48)>0,0,2)),0) -> 0
A49: Filler 1 | B49: 0.0055 | C49: Limestone_residue | G49: No | H49: Ankersmit Maastricht | I49: =IF($B49=0%,"Do not fill Transport", "Fill Transport") -> Fill Transport | J49: Truck | K49: Diesel_Euro6 | L49: 190 | M49: No | N49: No | O49: 0 | P49: No | Q49: No | R49: 0 | T49: =+IF(B49>0,IF(C49="No_filler",1,0),0) -> 0 | U49: =+IF(B49>0,IF(K49="No",1,IF(SUM(L49,O49,R49)>0,0,2)),0) -> 0
A50: Filler 2 | B50: 0 | C50: No_filler | G50: No | I50: =IF($B50=0%,"Do not fill Transport", "Fill Transport") -> Do not fill Transport | J50: No | K50: No | L50: 0 | M50: No | N50: No | O50: 0 | P50: No | Q50: No | R50: 0 | T50: =+IF(B50>0,IF(C50="No_filler",1,0),0) -> 0 | U50: =+IF(B50>0,IF(K50="No",1,IF(SUM(L50,O50,R50)>0,0,2)),0) -> 0
...

Sheet Result Dashboard
A1: LCA results for declared unit (cradle-to-gate analysis: A1-A3, D)
A3: General Information
A4: Date | B4: =Input!$B$5 -> 40409 | D4: Impact results (per declared unit)
A5: Mixture ID | B5: =Input!$B$6 -> 801/64/2010/13RE-1234/0 | D5: Declared unit | E5: 1 ton of asphalt mixture
A6: Mixture type (SB250) | B6: =Input!$B$7 -> AB-3A1 | D6: Total PEF Score | E6: =IF(ABS('Aux - Check'!$B$11)>10^-10,"Error",Results!$M$47) -> Error | F6: mpt/ton
A7: Mixture type (EN 13108) | B7: =+Input!B8 -> AC 20 onderlaag 50/70 | D7: Global Warming | E7: =IF(ABS('Aux - Check'!$B$11)>10^-10,"Error",Results!$L$53) -> Error | F7: kgCO2-eq/ton
A8: Asphalt plant location | B8: =Input!$B$14 -> straat 1, 1000 Gaurain-Ramecroix
A9: Mix temperature range | B9: =Input!$B$21 -> 155⁰C - 185⁰C
A10: Total binder (by weight of mix) | B10: =Input!$B$9 -> 0.03716
A11: Asphalt binder replacement | B11: =+Input!B10 -> 0.40365985
A12: Bulk density [kg/m3] | B12: =Input!$B$22 -> 2400
A53: LCA results for functional unit (cradle-to-grave analysis: A1-C3, D)
A55: General Information
A56: Date | B56: =Input!$B$5 -> 40409 | D56: Impact results (per funtional unit)
A57: Mixture ID | B57: =Input!$B$6 -> 801/64/2010/13RE-1234/0 | D57: Functional unit | E57: =+CONCATENATE("1 m2 (",Input!B31/10,"-cm thick)") -> 1 m2 (8-cm thick)
A58: Mixture type (SB250) | B58: =Input!$B$7 -> AB-3A1 | D58: Total PEF Score | E58: =IF(E6="Error","Error",Results!$N$111) -> Error | F58: mpt/m2
A59: Mixture type (EN 13108) | B59: =Input!$B$8 -> AC 20 onderlaag 50/70 | D59: Global Warming | E59: =IF(E7="Error","Error",Results!$M$118) -> Error | F59: kgCO2-eq/m2
A60: Asphalt plant | B60: =Input!$B$14 -> straat 1, 1000 Gaurain-Ramecroix
A61: Mix temperature range | B61: =Input!$B$21 -> 155⁰C - 185⁰C
A62: Total binder | B62: =Input!$B$9 -> 0.03716
A63: Asphalt binder replacement | B63: =+Input!B10 -> 0.40365985
A64: Bulk density [kg/m3] | B64: =Input!$B$22 -> 2400
A105: LCA results for a modified declared unit (cradle-to-grave analysis: A1-C3, D)
A107: General Information
A108: Date | B108: =Input!$B$5 -> 40409 | D108: Impact results (per ton excl. module D)
A109: Mixture ID | B109: =Input!$B$6 -> 801/64/2010/13RE-1234/0 | D109: Declared unit | E109: =+CONCATENATE("1 ton (",Input!B31/10,"-cm thick)") -> 1 ton (8-cm thick)
A110: Mixture type (SB250) | B110: =Input!$B$7 -> AB-3A1 | D110: Total PEF Score | E110: =IF(E6="Error","Error",Results!$N$47) -> Error | F110: mpt/ton
A111: Mixture type (EN 13108) | B111: =Input!$B$8 -> AC 20 onderlaag 50/70 | D111: Global Warming | E111: =IF(E7="Error","Error",Results!$M$53) -> Error | F111: kgCO2-eq/ ton
A112: Asphalt plant | B112: =Input!$B$14 -> straat 1, 1000 Gaurain-Ramecroix
A113: Mix temperature range | B113: =Input!$B$21 -> 155⁰C - 185⁰C
A114: Total binder | B114: =Input!$B$9 -> 0.03716
A115: Asphalt binder replacement | B115: =+Input!$B$10 -> 0.40365985
A116: Bulk density [kg/m3] | B116: =Input!$B$22 -> 2400

Sheet Aux - Check
A2: Check machinery | B2: =+Input!U86 -> 0
A3: Check transportation | B3: =+Input!U58 -> 0
A4: Check sum of primary & secondary equals 100% | B4: =IF(Input!C17 + Input!C18 = 100%,0, 1) -> 0
A5: Check Asphalt plant: electric components | B5: =IF(OR(AND(Input!B19="Yes", Input!C19<>"No"), AND(Input!B19="No",Input!C19="No")), 0, 1) -> 0
A6: Check mix contents adds to 100% | B6: =IF(AND(Input!B58>=99.9%, Input!B58<=100.1%), 0, 1) -> 1
A7: Check asphalt mix components | B7: =IF( COUNTIFS( _xlfn.XLOOKUP(Input!$B$19,'Aux - Lists'!B168:C168,'Aux - Lists'!B169:C170,Input!$C$19), Input!$C$19)=0,1, 0) -> 0
A8: Checks asphalt mix loading operations | B8: =IF(COUNTIFS(_xlfn.XLOOKUP(Input!$B$26,'Aux - Lists'!B16:C16,'Aux - Lists'!B17:C24,Input!$C$26),Input!$C$26)=0,1,0) -> 0
A9: Check Results tab | B9: =+Results!B23+Results!B54+Results!B61+Results!B86+Results!B112+Results!B119+Results!B126+Results!B152+Results!B160 -> 3.6948222e-13
A10: Check table results in all life cycle phases | B10: ='A1 - Raw Material Supply'!$B$139+'A1 - Raw Material Supply'!$C$139+'A1 - Raw Material Supply'!$D$139+'C3'' - Secondary Raw Material '!B345+'A2 - Transport'!$B$143+'C2''- Transport Secondary'!B82+'A3 - Production '!$B$231+'A3 - Production '!$C$231+'A4 - Transport'!$B$42+'A5 - Construction'!$B$165+'C1 - Deconstruction'!$B$112+'D- Benefits & Burdens'!$B$213+'D- Benefits & Burdens'!C213 -> 0
B11: =+SUM(B2:B10) -> 1

Sheet Results
A1: Environmental impacts per ton of asphalt mix per life cycle stage
A3: Impact Categories | B3: Unit | C3: A1 - Primary Raw Material | D3: C3' - Secondary Raw Material | E3: A2 - Transport Primary Raw Material | F3: C2' - Transport Secondary Raw Material | G3: A3- Production | H3: A4- Transport | I3: A5- Construction | J3: C1 - Deconstruction | K3: D- Burdens & Savings | L3: Total: A1-A3,C2',C3' (excl D) | M3: Total A1-A5,C1,C2',C3' (excl. D)
A4: Acidification | B4: accumulated exceedance (AE) mol H+ -eq | C4: ='A1 - Raw Material Supply'!Z114 -> 0.07606603 | D4: ='C3'' - Secondary Raw Material '!F320 -> 0.00021323931 | E4: ='A2 - Transport'!Z118 -> 0.023580023 | F4: ='C2''- Transport Secondary'!H58 -> 0.0049001454 | G4: ='A3 - Production '!D206 -> 0.019088517 | H4: ='A4 - Transport'!B17 -> 0.0044454498 | I4: ='A5 - Construction'!E139 -> 0.0014781911 | J4: ='C1 - Deconstruction'!B87 -> 0.0011217073 | K4: ='D- Benefits & Burdens'!N161 -> -0.078398164 | L4: =+SUM(C4:G4) -> 0.12384795 | M4: =SUM(C4:J4) -> 0.1308933
A5: Climate change | B5: global warming potential (GWP100) kgCO2-Eq | C5: ='A1 - Raw Material Supply'!Z115 -> 14.605727 | D5: ='C3'' - Secondary Raw Material '!F321 -> 0.16679034 | E5: ='A2 - Transport'!Z119 -> 12.873445 | F5: ='C2''- Transport Secondary'!H59 -> 3.2860186 | G5: ='A3 - Production '!D207 -> 18.960239 | H5: ='A4 - Transport'!B18 -> 2.9811015 | I5: ='A5 - Construction'!E140 -> 1.1562033 | J5: ='C1 - Deconstruction'!B88 -> 0.8773708 | K5: ='D- Benefits & Burdens'!N162 -> -17.396908 | L5: =+SUM(C5:G5) -> 49.89222 | M5: =SUM(C5:J5) -> 54.906896
A6: Climate change: biogenic | B6: global warming potential (GWP100) kgCO2-Eq | C6: ='A1 - Raw Material Supply'!Z116 -> 0.15907702 | D6: ='C3'' - Secondary Raw Material '!F322 -> 3.4471332e-05 | E6: ='A2 - Transport'!Z120 -> 0.0059009661 | F6: ='C2''- Transport Secondary'!H60 -> 0.0015357392 | G6: ='A3 - Production '!D208 -> 0.0064771325 | H6: ='A4 - Transport'!B19 -> 0.0013932345 | I6: ='A5 - Construction'!E141 -> 0.0002389579 | J6: ='C1 - Deconstruction'!B89 -> 0.00018133029 | K6: ='D- Benefits & Burdens'!N163 -> -0.067189815 | L6: =+SUM(C6:G6) -> 0.17302533 | M6: =SUM(C6:J6) -> 0.17483886
A7: Climate change: fossil | B7: global warming potential (GWP100) kgCO2-Eq | C7: ='A1 - Raw Material Supply'!Z117 -> 14.447676 | D7: ='C3'' - Secondary Raw Material '!F323 -> 0.16674849 | E7: ='A2 - Transport'!Z121 -> 12.86601 | F7: ='C2''- Transport Secondary'!H61 -> 3.2842215 | G7: ='A3 - Production '!D209 -> 18.9503 | H7: ='A4 - Transport'!B20 -> 2.9794711 | I7: ='A5 - Construction'!E142 -> 1.1559132 | J7: ='C1 - Deconstruction'!B90 -> 0.87715067 | K7: ='D- Benefits & Burdens'!N164 -> -17.329856 | L7: =+SUM(C7:G7) -> 49.714957 | M7: =SUM(C7:J7) -> 54.727492
A8: Land use and land use change | B8: global warming potential (GWP100) kgCO2-Eq | C8: ='A1 - Raw Material Supply'!Z118 -> 0.0070618731 | D8: ='C3'' - Secondary Raw Material '!F324 -> 7.3759045e-06 | E8: ='A2 - Transport'!Z122 -> 0.0015343119 | F8: ='C2''- Transport Secondary'!H62 -> 0.00026136855 | G8: ='A3 - Production '!D210 -> 0.0034616186 | H8: ='A4 - Transport'!B21 -> 0.00023711557 | I8: ='A5 - Construction'!E143 -> 5.1130331e-05 | J8: ='C1 - Deconstruction'!B91 -> 3.8799629e-05 | K8: ='D- Benefits & Burdens'!N165 -> -0.0083879202 | L8: =+SUM(C8:G8) -> 0.012326548 | M8: =SUM(C8:J8) -> 0.012653594
A9: Ecotoxicity: freshwater | B9: comparative toxic unit for ecosystems (CTUe) | C9: ='A1 - Raw Material Supply'!Z119 -> 648.07216 | D9: ='C3'' - Secondary Raw Material '!F325 -> 0.073693079 | E9: ='A2 - Transport'!Z123 -> 11.149257 | F9: ='C2''- Transport Secondary'!H63 -> 2.8223197 | G9: ='A3 - Production '!D211 -> 10.578127 | H9: ='A4 - Transport'!B22 -> 2.5604303 | I9: ='A5 - Construction'!E144 -> 0.51084603 | J9: ='C1 - Deconstruction'!B92 -> 0.38764929 | K9: ='D- Benefits & Burdens'!N166 -> -679.37906 | L9: =+SUM(C9:G9) -> 672.69555 | M9: =SUM(C9:J9) -> 676.15448
A10: Energy resources: non-renewable | B10: abiotic depletion potential (ADP): fossil fuels MJ, net calorific value | C10: ='A1 - Raw Material Supply'!Z120 -> 1053.1269 | D10: ='C3'' - Secondary Raw Material '!F326 -> 2.2154215 | E10: ='A2 - Transport'!Z124 -> 172.54507 | F10: ='C2''- Transport Secondary'!H64 -> 44.226394 | G10: ='A3 - Production '!D212 -> 355.33723 | H10: ='A4 - Transport'!B23 -> 40.122526 | I10: ='A5 - Construction'!E145 -> 15.357471 | J10: ='C1 - Deconstruction'!B93 -> 11.65383 | K10: ='D- Benefits & Burdens'!N167 -> -1140.6957 | L10: =+SUM(C10:G10) -> 1627.451 | M10: =SUM(C10:J10) -> 1694.5849
A11: Eutrophication: freshwater | B11: fraction of nutrients reaching freshwater end compartment (P) | C11: ='A1 - Raw Material Supply'!Z121 -> 0.00038657618 | D11: ='C3'' - Secondary Raw Material '!F327 -> 1.7631993e-06 | E11: ='A2 - Transport'!Z125 -> 0.00034050525 | F11: ='C2''- Transport Secondary'!H65 -> 7.6645683e-05 | G11: ='A3 - Production '!D213 -> 0.00067523477 | H11: ='A4 - Transport'!B24 -> 6.9533556e-05 | I11: ='A5 - Construction'!E146 -> 1.2222632e-05 | J11: ='C1 - Deconstruction'!B94 -> 9.2749952e-06 | K11: ='D- Benefits & Burdens'!N168 -> -0.00074384614 | L11: =+SUM(C11:G11) -> 0.0014807251 | M11: =SUM(C11:J11) -> 0.0015717563
A12: Eutrophication: marine | B12: fraction of nutrients reaching marine end compartment (N) kg N-Eq | C12: ='A1 - Raw Material Supply'!Z122 -> 0.023205911 | D12: ='C3'' - Secondary Raw Material '!F328 -> 4.8220356e-05 | E12: ='A2 - Transport'!Z126 -> 0.0063826639 | F12: ='C2''- Transport Secondary'!H66 -> 0.001068062 | G12: ='A3 - Production '!D214 -> 0.0049703887 | H12: ='A4 - Transport'!B25 -> 0.00096895414 | I12: ='A5 - Construction'!E147 -> 0.00033426717 | J12: ='C1 - Deconstruction'!B95 -> 0.00025365457 | K12: ='D- Benefits & Burdens'!N169 -> -0.024154686 | L12: =+SUM(C12:G12) -> 0.035675245 | M12: =SUM(C12:J12) -> 0.037232121
A13: Eutrophication: terrestrial | B13: accumulated exceedance (AE) mol N-Eq | C13: ='A1 - Raw Material Supply'!Z123 -> 0.28032577 | D13: ='C3'' - Secondary Raw Material '!F329 -> 0.00052421469 | E13: ='A2 - Transport'!Z127 -> 0.06934929 | F13: ='C2''- Transport Secondary'!H67 -> 0.011560805 | G13: ='A3 - Production '!D215 -> 0.053551285 | H13: ='A4 - Transport'!B26 -> 0.010488052 | I13: ='A5 - Construction'!E148 -> 0.0036338961 | J13: ='C1 - Deconstruction'!B96 -> 0.0027575378 | K13: ='D- Benefits & Burdens'!N170 -> -0.28174334 | L13: =+SUM(C13:G13) -> 0.41531137 | M13: =SUM(C13:J13) -> 0.43219085
A14: Human toxicity: carcinogenic | B14: comparative toxic unit for human (CTUh) | C14: ='A1 - Raw Material Supply'!Z124 -> 1.1685486e-08 | D14: ='C3'' - Secondary Raw Material '!F330 -> 1.0192647e-11 | E14: ='A2 - Transport'!Z128 -> 1.1688925e-09 | F14: ='C2''- Transport Secondary'!H68 -> 2.9124279e-10 | G14: ='A3 - Production '!D216 -> 1.8958767e-09 | H14: ='A4 - Transport'!B27 -> 2.6421771e-10 | I14: ='A5 - Construction'!E149 -> 7.0656203e-11 | J14: ='C1 - Deconstruction'!B97 -> 5.36166e-11 | K14: ='D- Benefits & Burdens'!N171 -> -1.2277426e-08 | L14: =+SUM(C14:G14) -> 1.5051691e-08 | M14: =SUM(C14:J14) -> 1.5440181e-08
A15: Human toxicity: non-carcinogenic | B15: comparative toxic unit for human (CTUh) | C15: ='A1 - Raw Material Supply'!Z125 -> 3.4070688e-07 | D15: ='C3'' - Secondary Raw Material '!F331 -> 2.7167564e-10 | E15: ='A2 - Transport'!Z129 -> 9.0290244e-08 | F15: ='C2''- Transport Secondary'!H69 -> 2.3696946e-08 | G15: ='A3 - Production '!D217 -> 3.7539188e-08 | H15: ='A4 - Transport'!B28 -> 2.1498053e-08 | I15: ='A5 - Construction'!E150 -> 1.8832762e-09 | J15: ='C1 - Deconstruction'!B98 -> 1.4291012e-09 | K15: ='D- Benefits & Burdens'!N172 -> -3.6768655e-07 | L15: =+SUM(C15:G15) -> 4.9250493e-07 | M15: =SUM(C15:J15) -> 5.1731536e-07
... A22: Water use | B22: user deprivation potential (deprivation-weighted water consumption) m3 world eq deprived | C22: ='A1 - Raw Material Supply'!Z132 -> 3.5963311 | D22: ='C3'' - Secondary Raw Material '!F338 -> 0.0029984053 | E22: ='A2 - Transport'!Z136 -> 0.43325273 | F22: ='C2''- Transport Secondary'!H76 -> 0.10073011 | G22: ='A3 - Production '!D224 -> 0.82098728 | H22: ='A4 - Transport'!B35 -> 0.091383136 | I22: ='A5 - Construction'!E157 -> 0.020785174 | J22: ='C1 - Deconstruction'!B105 -> 0.015772576 | K22: ='D- Benefits & Burdens'!N179 -> -4.6045059 | L22: =+SUM(C22:G22) -> 4.9542996 | M22: =SUM(C22:J22) -> 5.0822405
A23: Check | B23: =+SUM(C23:K23) -> 0 | C23: =+SUM(C4:C22)-'A1 - Raw Material Supply'!D137 -> 0 | D23: =+SUM(D4:D22)-'C3'' - Secondary Raw Material '!B344 -> 0 | E23: =+SUM(E4:E22)-'A2 - Transport'!B142 -> 0 | F23: =+SUM(F4:F22)-'C2''- Transport Secondary'!B81 -> 0 | G23: =+SUM(G4:G22)-'A3 - Production '!B230 -> 0 | H23: =+SUM(H4:H22)-'A4 - Transport'!B41 -> 0 | I23: =+SUM(I4:I22)-'A5 - Construction'!B164 -> 0 | J23: =+SUM(J4:J22)-'C1 - Deconstruction'!B111 -> 0 | K23: =+SUM(K4:K22)-'D- Benefits & Burdens'!B212 -> 0
A25: Single score per ton of asphalt mix per life cycle stage
A26: The total single score per impact categories are multiplied by 1000 to convert them from Points scale to Millipoint scale
A27: Impact Categories | B27: Normalization factor [unit/person.year] | C27: Weighting factor [%] | D27: A1 - Primary Material | E27: C3' - Secondary Material | F27: A2 - Transport Primary | G27: C2' - Transport Secondary | H27: A3- Production | I27: A4- Transport | J27: A5- Construction | K27: C1 - Deconstruction | L27: D- Burdens & Savings | M27: Total: A1-A3,C2',C3' (excl D) | N27: Total A1-A5,C1,C2',C3' (excl. D) | O27: Total (incl. D)
A28: Acidification | B28: 55.6 | C28: 0.062 | D28: =(C4/$B28)*$C28 -> 8.4821832e-05 | E28: =(D4/$B28)*$C28 -> 2.3778484e-07 | F28: =(E4/$B28)*$C28 -> 2.629427e-05 | G28: =(F4/$B28)*$C28 -> 5.4641909e-06 | H28: =(G4/$B28)*$C28 -> 2.1285757e-05 | I28: =(H4/$B28)*$C28 -> 4.9571562e-06 | J28: =(I4/$B28)*$C28 -> 1.6483426e-06 | K28: =(J4/$B28)*$C28 -> 1.2508247e-06 | L28: =(K4/$B28)*$C28 -> -8.7422413e-05 | M28: =SUM(D28:H28)*1000 -> 0.13810383 | N28: =SUM(D28:K28)*1000 -> 0.14596016 | O28: =SUM(D28:L28)*1000 -> 0.058537745
A29: Climate change | B29: 8100 | C29: 0.2106 | D29: =(C5/$B29)*$C29 -> 0.0003797489 | E29: =(D5/$B29)*$C29 -> 4.3365488e-06 | F29: =(E5/$B29)*$C29 -> 0.00033470958 | G29: =(F5/$B29)*$C29 -> 8.5436483e-05 | H29: =(G5/$B29)*$C29 -> 0.00049296622 | I29: =(H5/$B29)*$C29 -> 7.7508638e-05 | J29: =(I5/$B29)*$C29 -> 3.0061286e-05 | K29: =(J5/$B29)*$C29 -> 2.2811641e-05 | L29: =(K5/$B29)*$C29 -> -0.0004523196 | M29: =SUM(D29:H29)*1000 -> 1.2971977 | N29: =SUM(D29:K29)*1000 -> 1.4275793 | O29: =SUM(D29:L29)*1000 -> 0.97525969
A30: Climate change: biogenic
A31: Climate change: fossil
A32: Land use and land use change
A33: Ecotoxicity: freshwater | B33: 42700 | C33: 0.0192 | D33: =(C9/$B33)*$C33 -> 0.00029140481 | E33: =(D9/$B33)*$C33 -> 3.3135998e-08 | F33: =(E9/$B33)*$C33 -> 5.0132492e-06 | G33: =(F9/$B33)*$C33 -> 1.2690524e-06 | H33: =(G9/$B33)*$C33 -> 4.7564411e-06 | I33: =(H9/$B33)*$C33 -> 1.1512942e-06 | J33: =(I9/$B33)*$C33 -> 2.2970126e-07 | K33: =(J9/$B33)*$C33 -> 1.74306e-07 | L33: =(K9/$B33)*$C33 -> -0.00030548192 | M33: =SUM(D33:H33)*1000 -> 0.30247669 | N33: =SUM(D33:K33)*1000 -> 0.30403199 | O33: =SUM(D33:L33)*1000 -> -0.0014499274
A34: Energy resources: non-renewable | B34: 65000 | C34: 0.0755 | D34: =(C10/$B34)*$C34 -> 0.0012232474 | E34: =(D10/$B34)*$C34 -> 2.5732973e-06 | F34: =(E10/$B34)*$C34 -> 0.00020041774 | G34: =(F10/$B34)*$C34 -> 5.1370657e-05 | H34: =(G10/$B34)*$C34 -> 0.00041273786 | I34: =(H10/$B34)*$C34 -> 4.6603857e-05 | J34: =(I10/$B34)*$C34 -> 1.7838293e-05 | K34: =(J10/$B34)*$C34 -> 1.3536371e-05 | L34: =(K10/$B34)*$C34 -> -0.001324962 | M34: =SUM(D34:H34)*1000 -> 1.890347 | N34: =SUM(D34:K34)*1000 -> 1.9683255 | O34: =SUM(D34:L34)*1000 -> 0.64336352
A35: Eutrophication: freshwater | B35: 1.61 | C35: 0.028 | D35: =(C11/$B35)*$C35 -> 6.723064e-06 | E35: =(D11/$B35)*$C35 -> 3.0664336e-08 | F35: =(E11/$B35)*$C35 -> 5.9218305e-06 | G35: =(F11/$B35)*$C35 -> 1.3329684e-06 | H35: =(G11/$B35)*$C35 -> 1.1743213e-05 | I35: =(H11/$B35)*$C35 -> 1.2092792e-06 | J35: =(I11/$B35)*$C35 -> 2.1256751e-07 | K35: =(J11/$B35)*$C35 -> 1.6130426e-07 | L35: =(K11/$B35)*$C35 -> -1.2936455e-05 | M35: =SUM(D35:H35)*1000 -> 0.025751741 | N35: =SUM(D35:K35)*1000 -> 0.027334892 | O35: =SUM(D35:L35)*1000 -> 0.014398437
A36: Eutrophication: marine | B36: 19.5 | C36: 0.0296 | D36: =(C12/$B36)*$C36 -> 3.5225382e-05 | E36: =(D12/$B36)*$C36 -> 7.3196027e-08 | F36: =(E12/$B36)*$C36 -> 9.6885564e-06 | G36: =(F12/$B36)*$C36 -> 1.6212634e-06 | H36: =(G12/$B36)*$C36 -> 7.5447951e-06 | I36: =(H12/$B36)*$C36 -> 1.4708227e-06 | J36: =(I12/$B36)*$C36 -> 5.0740043e-07 | K36: =(J12/$B36)*$C36 -> 3.8503464e-07 | L36: =(K12/$B36)*$C36 -> -3.6665575e-05 | M36: =SUM(D36:H36)*1000 -> 0.054153193 | N36: =SUM(D36:K36)*1000 -> 0.056516451 | O36: =SUM(D36:L36)*1000 -> 0.019850876
A37: Eutrophication: terrestrial | B37: 177 | C37: 0.0371 | D37: =(C13/$B37)*$C37 -> 5.8757549e-05 | E37: =(D13/$B37)*$C37 -> 1.0987777e-07 | F37: =(E13/$B37)*$C37 -> 1.4535925e-05 | G37: =(F13/$B37)*$C37 -> 2.423197e-06 | H37: =(G13/$B37)*$C37 -> 1.1224591e-05 | I37: =(H13/$B37)*$C37 -> 2.198343e-06 | J37: =(I13/$B37)*$C37 -> 7.6168104e-07 | K37: =(J13/$B37)*$C37 -> 5.7799238e-07 | L37: =(K13/$B37)*$C37 -> -5.9054677e-05 | M37: =SUM(D37:H37)*1000 -> 0.08705114 | N37: =SUM(D37:K37)*1000 -> 0.090589156 | O37: =SUM(D37:L37)*1000 -> 0.031534479
A38: Human toxicity: carcinogenic | B38: 1.69e-05 | C38: 0.0213 | D38: =(C14/$B38)*$C38 -> 1.4727861e-05 | E38: =(D14/$B38)*$C38 -> 1.2846354e-08 | F38: =(E14/$B38)*$C38 -> 1.4732196e-06 | G38: =(F14/$B38)*$C38 -> 3.6706932e-07 | H38: =(G14/$B38)*$C38 -> 2.3894778e-06 | I38: =(H14/$B38)*$C38 -> 3.3300812e-07 | J38: =(I14/$B38)*$C38 -> 8.9051901e-08 | K38: =(J14/$B38)*$C38 -> 6.7575951e-08 | L38: =(K14/$B38)*$C38 -> -1.5473915e-05 | M38: =SUM(D38:H38)*1000 -> 0.018970474 | N38: =SUM(D38:K38)*1000 -> 0.01946011 | O38: =SUM(D38:L38)*1000 -> 0.0039861949
A39: Human toxicity: non-carcinogenic | B39: 0.00023 | C39: 0.0184 | D39: =(C15/$B39)*$C39 -> 2.725655e-05 | E39: =(D15/$B39)*$C39 -> 2.1734051e-08 | F39: =(E15/$B39)*$C39 -> 7.2232195e-06 | G39: =(F15/$B39)*$C39 -> 1.8957557e-06 | H39: =(G15/$B39)*$C39 -> 3.0031351e-06 | I39: =(H15/$B39)*$C39 -> 1.7198442e-06 | J39: =(I15/$B39)*$C39 -> 1.5066209e-07 | K39: =(J15/$B39)*$C39 -> 1.143281e-07 | L39: =(K15/$B39)*$C39 -> -2.9414924e-05 | M39: =SUM(D39:H39)*1000 -> 0.039400395 | N39: =SUM(D39:K39)*1000 -> 0.041385229 | O39: =SUM(D39:L39)*1000 -> 0.011970305
A40: Ionising radiation: human health | B40: 4220 | C40: 0.0501 | D40: =(C16/$B40)*$C40 -> 4.3727996e-06 | E40: =(D16/$B40)*$C40 -> 7.897264e-09 | F40: =(E16/$B40)*$C40 -> 1.1288766e-06 | G40: =(F16/$B40)*$C40 -> 2.3808522e-07 | H40: =(G16/$B40)*$C40 -> 2.8902488e-05 | I40: =(H16/$B40)*$C40 -> 2.1599275e-07 | J40: =(I16/$B40)*$C40 -> 5.4744434e-08 | K40: =(J16/$B40)*$C40 -> 4.1542147e-08 | L40: =(K16/$B40)*$C40 -> -6.3374756e-06 | M40: =SUM(D40:H40)*1000 -> 0.034650147 | N40: =SUM(D40:K40)*1000 -> 0.034962426 | O40: =SUM(D40:L40)*1000 -> 0.02862495
A41: Land use | B41: 819000 | C41: 0.0794 | D41: =(C17/$B41)*$C41 -> 3.8640459e-05 | E41: =(D17/$B41)*$C41 -> 1.1042769e-08 | F41: =(E17/$B41)*$C41 -> 1.4877222e-06 | G41: =(F17/$B41)*$C41 -> 2.7045122e-07 | H41: =(G17/$B41)*$C41 -> 1.2147918e-06 | I41: =(H17/$B41)*$C41 -> 2.4535543e-07 | J41: =(I17/$B41)*$C41 -> 7.6549314e-08 | K41: =(J17/$B41)*$C41 -> 5.8088515e-08 | L41: =(K17/$B41)*$C41 -> -4.8188582e-05 | M41: =SUM(D41:H41)*1000 -> 0.041624467 | N41: =SUM(D41:K41)*1000 -> 0.042004461 | O41: =SUM(D41:L41)*1000 -> -0.0061841216
A42: Material resources: metals/minerals | B42: 65000 | C42: 0.0832 | D42: =(C18/$B42)*$C42 -> 2.6481788e-10 | E42: =(D18/$B42)*$C42 -> 3.3290156e-14 | F42: =(E18/$B42)*$C42 -> 1.8391028e-11 | G42: =(F18/$B42)*$C42 -> 4.64043e-12 | H42: =(G18/$B42)*$C42 -> 3.8298041e-11 | I42: =(H18/$B42)*$C42 -> 4.2098339e-12 | J42: =(I18/$B42)*$C42 -> 2.3076989e-13 | K42: =(J18/$B42)*$C42 -> 1.7511693e-13 | L42: =(K18/$B42)*$C42 -> -1.4360236e-11 | M42: =SUM(D42:H42)*1000 -> 3.2618067e-07 | N42: =SUM(D42:K42)*1000 -> 3.3079639e-07 | O42: =SUM(D42:L42)*1000 -> 3.1643615e-07
A43: Ozone depletion | B43: 0.0536 | C43: 0.0631 | D43: =(C19/$B43)*$C43 -> 4.8395478e-08 | E43: =(D19/$B43)*$C43 -> 4.4247185e-09 | F43: =(E19/$B43)*$C43 -> 3.3434921e-07 | G43: =(F19/$B43)*$C43 -> 8.601763e-08 | H43: =(G19/$B43)*$C43 -> 2.9924485e-06 | I43: =(H19/$B43)*$C43 -> 7.8035859e-08 | J43: =(I19/$B43)*$C43 -> 3.0672485e-08 | K43: =(J19/$B43)*$C43 -> 2.3275442e-08 | L43: =(K19/$B43)*$C43 -> -1.0627294e-07 | M43: =SUM(D43:H43)*1000 -> 0.0034656355 | N43: =SUM(D43:K43)*1000 -> 0.0035976193 | O43: =SUM(D43:L43)*1000 -> 0.0034913464
A44: Particulate matter formation | B44: 0.000595 | C44: 0.0896 | D44: =(C20/$B44)*$C44 -> 0.00019177259 | E44: =(D20/$B44)*$C44 -> 2.4738054e-07 | F44: =(E20/$B44)*$C44 -> 0.00011645631 | G44: =(F20/$B44)*$C44 -> 3.0671676e-05 | H44: =(G20/$B44)*$C44 -> 1.2813296e-05 | I44: =(H20/$B44)*$C44 -> 2.7825582e-05 | J44: =(I20/$B44)*$C44 -> 1.7148607e-06 | K44: =(J20/$B44)*$C44 -> 1.3013012e-06 | L44: =(K20/$B44)*$C44 -> -0.00020952499 | M44: =SUM(D44:H44)*1000 -> 0.35196126 | N44: =SUM(D44:K44)*1000 -> 0.382803 | O44: =SUM(D44:L44)*1000 -> 0.17327801
... A46: Water use | B46: 11500 | C46: 0.0851 | D46: =(C22/$B46)*$C46 -> 2.661285e-05 | E46: =(D22/$B46)*$C46 -> 2.2188199e-08 | F46: =(E22/$B46)*$C46 -> 3.2060702e-06 | G46: =(F22/$B46)*$C46 -> 7.4540283e-07 | H46: =(G22/$B46)*$C46 -> 6.0753059e-06 | I46: =(H22/$B46)*$C46 -> 6.7623521e-07 | J46: =(I22/$B46)*$C46 -> 1.5381029e-07 | K46: =(J22/$B46)*$C46 -> 1.1671706e-07 | L46: =(K22/$B46)*$C46 -> -3.4073344e-05 | M46: =SUM(D46:H46)*1000 -> 0.036661817 | N46: =SUM(D46:K46)*1000 -> 0.03760858 | O46: =SUM(D46:L46)*1000 -> 0.0035352361
A47: Total | C47: =SUM(C28:C46) -> 1 | D47: =SUM(D28:D46)*1000 -> 2.4866622 | E47: =SUM(E28:E46)*1000 -> 0.0082057025 | F47: =SUM(F28:F46)*1000 -> 0.77406938 | G47: =SUM(G28:G46)*1000 -> 0.19325055 | H47: =SUM(H28:H46)*1000 -> 1.0409458 | I47: =SUM(I28:I46)*1000 -> 0.17531839 | J47: =SUM(J28:J46)*1000 -> 0.056882553 | K47: =SUM(K28:K46)*1000 -> 0.043164633 | L47: =SUM(L28:L46)*1000 -> -2.7324625 | M47: =+SUM(M28:M46) -> 4.5031336 | N47: =+SUM(N28:N46) -> 4.7784991 | O47: =SUM(O28:O46) -> 2.0460367
A50: Global warming impact per ton of asphalt mix per life cycle stage
A51: Same as row 5
...

Sheet DDN_Results_TP
A1: Asphalt Transport Results
A2: Bruto (ton) | B2: =Input!$F$63 -> 20
A3: Transport distance | B3: =Input!$D$63 -> 20
A5: Impacts
A6: Impact categories | B6: =" Impacts per ton for "&B3&" km." -> Impacts per ton for 20 km. | C6: =" Impacts for "&B2&" ton." -> Impacts for 20 ton.
A8: Acidification | B8: ='A4 - Transport'!$B$17 -> 0.0044454498 | C8: =$B$2*B8 -> 0.088908996
A9: Climate change | B9: ='A4 - Transport'!$B$18 -> 2.9811015 | C9: =$B$2*B9 -> 59.622029
A10: Climate change: biogenic | B10: ='A4 - Transport'!$B$19 -> 0.0013932345 | C10: =$B$2*B10 -> 0.02786469
A11: Climate change: fossil | B11: ='A4 - Transport'!$B$20 -> 2.9794711 | C11: =$B$2*B11 -> 59.589422
A12: Land use and land use change | B12: ='A4 - Transport'!$B$21 -> 0.00023711557 | C12: =$B$2*B12 -> 0.0047423114
A13: Ecotoxicity: freshwater | B13: ='A4 - Transport'!$B$22 -> 2.5604303 | C13: =$B$2*B13 -> 51.208606
A14: Energy resources: non-renewable | B14: ='A4 - Transport'!$B$23 -> 40.122526 | C14: =$B$2*B14 -> 802.45052
A15: Eutrophication: freshwater | B15: ='A4 - Transport'!$B$24 -> 6.9533556e-05 | C15: =$B$2*B15 -> 0.0013906711
A16: Eutrophication: marine | B16: ='A4 - Transport'!$B$25 -> 0.00096895414 | C16: =$B$2*B16 -> 0.019379083
A17: Eutrophication: terrestrial | B17: ='A4 - Transport'!$B$26 -> 0.010488052 | C17: =$B$2*B17 -> 0.20976103
A18: Human toxicity: carcinogenic | B18: ='A4 - Transport'!$B$27 -> 2.6421771e-10 | C18: =$B$2*B18 -> 5.2843542e-09
A19: Human toxicity: non-carcinogenic | B19: ='A4 - Transport'!$B$28 -> 2.1498053e-08 | C19: =$B$2*B19 -> 4.2996105e-07
A20: Ionising radiation: human health | B20: ='A4 - Transport'!$B$29 -> 0.018193402 | C20: =$B$2*B20 -> 0.36386803
A21: Land use | B21: ='A4 - Transport'!$B$30 -> 2.5308073 | C21: =$B$2*B21 -> 50.616146
A22: Material resources: metals/minerals | B22: ='A4 - Transport'!$B$31 -> 3.2889328e-06 | C22: =$B$2*B22 -> 6.5778655e-05
A23: Ozone depletion | B23: ='A4 - Transport'!$B$32 -> 6.6287196e-08 | C23: =$B$2*B23 -> 1.3257439e-06
A24: Particulate matter formation | B24: ='A4 - Transport'!$B$33 -> 1.8477925e-07 | C24: =$B$2*B24 -> 3.6955851e-06
A25: Photochemical oxidant formation: human health | B25: ='A4 - Transport'!$B$34 -> 0.0077504763 | C25: =$B$2*B25 -> 0.15500953
A26: Water use | B26: ='A4 - Transport'!$B$35 -> 0.091383136 | C26: =$B$2*B26 -> 1.8276627
A28: Single Score
A29: Impact Category | B29: =" Single Score (mPt) per ton for "&B3&" km." -> Single Score (mPt) per ton for 20 km. | C29: =" Single Score (mPt) for "&B2&" ton." -> Single Score (mPt) for 20 ton.
A30: Acidification | B30: =Results!$I$28*1000 -> 0.0049571562 | C30: =$B$2*B30 -> 0.099143125
A31: Climate change | B31: =Results!$I$29*1000 -> 0.077508638 | C31: =$B$2*B31 -> 1.5501728
A32: Ecotoxicity: freshwater | B32: =Results!$I$33*1000 -> 0.0011512942 | C32: =$B$2*B32 -> 0.023025884
A33: Energy resources: non-renewable | B33: =Results!$I$34*1000 -> 0.046603857 | C33: =$B$2*B33 -> 0.93207715
A34: Eutrophication: freshwater | B34: =Results!$I$35*1000 -> 0.0012092792 | C34: =$B$2*B34 -> 0.024185585
A35: Eutrophication: marine | B35: =Results!$I$36*1000 -> 0.0014708227 | C35: =$B$2*B35 -> 0.029416454
A36: Eutrophication: terrestrial | B36: =Results!$I$37*1000 -> 0.002198343 | C36: =$B$2*B36 -> 0.043966861
A37: Human toxicity: carcinogenic | B37: =Results!$I$38*1000 -> 0.00033300812 | C37: =$B$2*B37 -> 0.0066601624
A38: Human toxicity: non-carcinogenic | B38: =Results!$I$39*1000 -> 0.0017198442 | C38: =$B$2*B38 -> 0.034396884
A39: Ionising radiation: human health | B39: =Results!$I$40*1000 -> 0.00021599275 | C39: =$B$2*B39 -> 0.0043198551
A40: Land use | B40: =Results!$I$41*1000 -> 0.00024535543 | C40: =$B$2*B40 -> 0.0049071087
A41: Material resources: metals/minerals | B41: =Results!$I$42*1000 -> 4.2098339e-09 | C41: =$B$2*B41 -> 8.4196678e-08
A42: Ozone depletion | B42: =Results!$I$43*1000 -> 7.8035859e-05 | C42: =$B$2*B42 -> 0.0015607172
A43: Particulate matter formation | B43: =Results!$I$44*1000 -> 0.027825582 | C43: =$B$2*B43 -> 0.55651163
...

Sheet A1 - Raw Material Supply
A2: Impacts: Asphalt mix components
A3: Components | B3: Materials | C3: Mass (ton] | D3: List | E3: acidification | accumulated exceedance (AE) mol H+ -eq | F3: climate change | global warming potential (GWP100) kgCO2-Eq | G3: climate change: biogenic | global warming potential (GWP100) kgCO2-Eq | H3: climate change: fossil | global warming potential (GWP100) kgCO2-Eq | I3: land use and land use change | global warming potential (GWP100) kgCO2-Eq | J3: ecotoxicity: freshwater | comparative toxic unit for ecosystems (CTUe) | K3: energy resources: non-renewable | abiotic depletion potential (ADP): fossil fuels MJ, net calorific value | L3: eutrophication: freshwater | fraction of nutrients reaching freshwater end compartment (P) | M3: eutrophication: marine | fraction of nutrients reaching marine end compartment (N) kg N-Eq | N3: eutrophication: terrestrial | accumulated exceedance (AE) mol N-Eq | O3: human toxicity: carcinogenic | comparative toxic unit for human (CTUh) | P3: human toxicity: non-carcinogenic | comparative toxic unit for human (CTUh) | Q3: ionising radiation: human health | human exposure efficiency relative to u235 kBq U235-Eq | R3: land use | soil quality index dimensionless | S3: material resources: metals/minerals | abiotic depletion potential (ADP): elements (ultimate reserves) kg Sb-Eq | T3: ozone depletion|ozone depletion potential (ODP) kg CFC-11-Eq | U3: particulate matter formation | impact on human health | V3: photochemical oxidant formation: human health | tropospheric ozone concentration increase kg NMVOC-Eq | W3: water use | user deprivation potential (deprivation-weighted water consumption) m3 world eq deprived
A4: Binder | B4: =Input!A39 -> Virgin binder | C4: =+Input!B39*(1-Input!E39) -> 0.02216 | D4: =Input!$C$39 -> Conventional_Bitumen | E4: {=INDEX(LCI!H$2:H$137,MATCH('A1 - Raw Material Supply'!$B4&'A1 - Raw Material Supply'!$D4,LCI!$B2:$B137&LCI!$D2:$D137,0))*$C4} -> 0.0381152 | F4: {=INDEX(LCI!I$2:I$137,MATCH('A1 - Raw Material Supply'!$B4&'A1 - Raw Material Supply'!$D4,LCI!$B2:$B137&LCI!$D2:$D137,0))*$C4} -> 11.7448 | G4: {=INDEX(LCI!J$2:J$137,MATCH('A1 - Raw Material Supply'!$B4&'A1 - Raw Material Supply'!$D4,LCI!$B2:$B137&LCI!$D2:$D137,0))*$C4} -> 0.046536 | H4: {=INDEX(LCI!K$2:K$137,MATCH('A1 - Raw Material Supply'!$B4&'A1 - Raw Material Supply'!$D4,LCI!$B2:$B137&LCI!$D2:$D137,0))*$C4} -> 11.70048 | I4: {=INDEX(LCI!L$2:L$137,MATCH('A1 - Raw Material Supply'!$B4&'A1 - Raw Material Supply'!$D4,LCI!$B2:$B137&LCI!$D2:$D137,0))*$C4} -> 0.0058724 | J4: {=INDEX(LCI!M$2:M$137,MATCH('A1 - Raw Material Supply'!$B4&'A1 - Raw Material Supply'!$D4,LCI!$B2:$B137&LCI!$D2:$D137,0))*$C4} -> 631.56 | K4: {=INDEX(LCI!N$2:N$137,MATCH('A1 - Raw Material Supply'!$B4&'A1 - Raw Material Supply'!$D4,LCI!$B2:$B137&LCI!$D2:$D137,0))*$C4} -> 1014.928 | L4: {=INDEX(LCI!O$2:O$137,MATCH('A1 - Raw Material Supply'!$B4&'A1 - Raw Material Supply'!$D4,LCI!$B2:$B137&LCI!$D2:$D137,0))*$C4} -> 9.8612e-06 | ... W4: {=INDEX(LCI!Z$2:Z$137,MATCH('A1 - Raw Material Supply'!$B4&'A1 - Raw Material Supply'!$D4,LCI!$B2:$B137&LCI!$D2:$D137,0))*$C4} -> 0.1597736
A5: Aggregate | B5: =Input!A40 -> Virgin crushed coarse aggregate 1 (>2 mm) | C5: =+Input!B40*(1-Input!E40) -> 0 | E5: =INDEX(LCI!H$2:H$130,MATCH('A1 - Raw Material Supply'!$B5,LCI!$D$2:$D$130,0))*$C5 -> 0 | F5: =INDEX(LCI!I$2:I$130,MATCH('A1 - Raw Material Supply'!$B5,LCI!$D$2:$D$130,0))*$C5 -> 0 | G5: =INDEX(LCI!J$2:J$130,MATCH('A1 - Raw Material Supply'!$B5,LCI!$D$2:$D$130,0))*$C5 -> 0 | H5: =INDEX(LCI!K$2:K$130,MATCH('A1 - Raw Material Supply'!$B5,LCI!$D$2:$D$130,0))*$C5 -> 0 | I5: =INDEX(LCI!L$2:L$130,MATCH('A1 - Raw Material Supply'!$B5,LCI!$D$2:$D$130,0))*$C5 -> 0 | J5: =INDEX(LCI!M$2:M$130,MATCH('A1 - Raw Material Supply'!$B5,LCI!$D$2:$D$130,0))*$C5 -> 0 | K5: =INDEX(LCI!N$2:N$130,MATCH('A1 - Raw Material Supply'!$B5,LCI!$D$2:$D$130,0))*$C5 -> 0 | L5: =INDEX(LCI!O$2:O$130,MATCH('A1 - Raw Material Supply'!$B5,LCI!$D$2:$D$130,0))*$C5 -> 0 | ... W5: =INDEX(LCI!Z$2:Z$130,MATCH('A1 - Raw Material Supply'!$B5,LCI!$D$2:$D$130,0))*$C5 -> 0
B6: =Input!A41 -> Virgin crushed coarse aggregate 2 (>2 mm) | C6: =+Input!B41*(1-Input!E41) -> 0.102 | E6: =INDEX(LCI!H$2:H$130,MATCH('A1 - Raw Material Supply'!$B6,LCI!$D$2:$D$130,0))*$C6 -> 0.0055525776 | F6: =INDEX(LCI!I$2:I$130,MATCH('A1 - Raw Material Supply'!$B6,LCI!$D$2:$D$130,0))*$C6 -> 0.28854915 | G6: =INDEX(LCI!J$2:J$130,MATCH('A1 - Raw Material Supply'!$B6,LCI!$D$2:$D$130,0))*$C6 -> 0.00088941089 | H6: =INDEX(LCI!K$2:K$130,MATCH('A1 - Raw Material Supply'!$B6,LCI!$D$2:$D$130,0))*$C6 -> 0.28756488 | I6: =INDEX(LCI!L$2:L$130,MATCH('A1 - Raw Material Supply'!$B6,LCI!$D$2:$D$130,0))*$C6 -> 9.485434e-05 | J6: =INDEX(LCI!M$2:M$130,MATCH('A1 - Raw Material Supply'!$B6,LCI!$D$2:$D$130,0))*$C6 -> 2.8511987 | K6: =INDEX(LCI!N$2:N$130,MATCH('A1 - Raw Material Supply'!$B6,LCI!$D$2:$D$130,0))*$C6 -> 4.0886678 | L6: =INDEX(LCI!O$2:O$130,MATCH('A1 - Raw Material Supply'!$B6,LCI!$D$2:$D$130,0))*$C6 -> 2.132093e-05 | ... W6: =INDEX(LCI!Z$2:Z$130,MATCH('A1 - Raw Material Supply'!$B6,LCI!$D$2:$D$130,0))*$C6 -> 0.41061397
B7: =Input!A42 -> Virgin crushed coarse aggregate 3 (>2 mm) | C7: =+Input!B42*(1-Input!E42) -> 0.353 | E7: =INDEX(LCI!H$2:H$130,MATCH('A1 - Raw Material Supply'!$B7,LCI!$D$2:$D$130,0))*$C7 -> 0.019216273 | F7: =INDEX(LCI!I$2:I$130,MATCH('A1 - Raw Material Supply'!$B7,LCI!$D$2:$D$130,0))*$C7 -> 0.99860636 | G7: =INDEX(LCI!J$2:J$130,MATCH('A1 - Raw Material Supply'!$B7,LCI!$D$2:$D$130,0))*$C7 -> 0.0030780593 | H7: =INDEX(LCI!K$2:K$130,MATCH('A1 - Raw Material Supply'!$B7,LCI!$D$2:$D$130,0))*$C7 -> 0.99520003 | I7: =INDEX(LCI!L$2:L$130,MATCH('A1 - Raw Material Supply'!$B7,LCI!$D$2:$D$130,0))*$C7 -> 0.00032827041 | J7: =INDEX(LCI!M$2:M$130,MATCH('A1 - Raw Material Supply'!$B7,LCI!$D$2:$D$130,0))*$C7 -> 9.8673837 | K7: =INDEX(LCI!N$2:N$130,MATCH('A1 - Raw Material Supply'!$B7,LCI!$D$2:$D$130,0))*$C7 -> 14.149997 | L7: =INDEX(LCI!O$2:O$130,MATCH('A1 - Raw Material Supply'!$B7,LCI!$D$2:$D$130,0))*$C7 -> 7.3787142e-05 | ... W7: =INDEX(LCI!Z$2:Z$130,MATCH('A1 - Raw Material Supply'!$B7,LCI!$D$2:$D$130,0))*$C7 -> 1.4210464
B8: =Input!A43 -> Virgin crushed fine aggregate 1 (≤2 mm) | C8: =+Input!B43*(1-Input!E43) -> 0 | E8: =INDEX(LCI!H$2:H$130,MATCH('A1 - Raw Material Supply'!$B8,LCI!$D$2:$D$130,0))*$C8 -> 0 | F8: =INDEX(LCI!I$2:I$130,MATCH('A1 - Raw Material Supply'!$B8,LCI!$D$2:$D$130,0))*$C8 -> 0 | G8: =INDEX(LCI!J$2:J$130,MATCH('A1 - Raw Material Supply'!$B8,LCI!$D$2:$D$130,0))*$C8 -> 0 | H8: =INDEX(LCI!K$2:K$130,MATCH('A1 - Raw Material Supply'!$B8,LCI!$D$2:$D$130,0))*$C8 -> 0 | I8: =INDEX(LCI!L$2:L$130,MATCH('A1 - Raw Material Supply'!$B8,LCI!$D$2:$D$130,0))*$C8 -> 0 | J8: =INDEX(LCI!M$2:M$130,MATCH('A1 - Raw Material Supply'!$B8,LCI!$D$2:$D$130,0))*$C8 -> 0 | K8: =INDEX(LCI!N$2:N$130,MATCH('A1 - Raw Material Supply'!$B8,LCI!$D$2:$D$130,0))*$C8 -> 0 | L8: =INDEX(LCI!O$2:O$130,MATCH('A1 - Raw Material Supply'!$B8,LCI!$D$2:$D$130,0))*$C8 -> 0 | ... W8: =INDEX(LCI!Z$2:Z$130,MATCH('A1 - Raw Material Supply'!$B8,LCI!$D$2:$D$130,0))*$C8 -> 0
B9: =Input!A44 -> Virgin crushed fine aggregate 2 (≤2 mm) | C9: =+Input!B44*(1-Input!E44) -> 0 | E9: =INDEX(LCI!H$2:H$130,MATCH('A1 - Raw Material Supply'!$B9,LCI!$D$2:$D$130,0))*$C9 -> 0 | F9: =INDEX(LCI!I$2:I$130,MATCH('A1 - Raw Material Supply'!$B9,LCI!$D$2:$D$130,0))*$C9 -> 0 | G9: =INDEX(LCI!J$2:J$130,MATCH('A1 - Raw Material Supply'!$B9,LCI!$D$2:$D$130,0))*$C9 -> 0 | H9: =INDEX(LCI!K$2:K$130,MATCH('A1 - Raw Material Supply'!$B9,LCI!$D$2:$D$130,0))*$C9 -> 0 | I9: =INDEX(LCI!L$2:L$130,MATCH('A1 - Raw Material Supply'!$B9,LCI!$D$2:$D$130,0))*$C9 -> 0 | J9: =INDEX(LCI!M$2:M$130,MATCH('A1 - Raw Material Supply'!$B9,LCI!$D$2:$D$130,0))*$C9 -> 0 | K9: =INDEX(LCI!N$2:N$130,MATCH('A1 - Raw Material Supply'!$B9,LCI!$D$2:$D$130,0))*$C9 -> 0 | L9: =INDEX(LCI!O$2:O$130,MATCH('A1 - Raw Material Supply'!$B9,LCI!$D$2:$D$130,0))*$C9 -> 0 | ... W9: =INDEX(LCI!Z$2:Z$130,MATCH('A1 - Raw Material Supply'!$B9,LCI!$D$2:$D$130,0))*$C9 -> 0
B10: =Input!A45 -> Virgin crushed fine aggregate 3 (≤2 mm) | C10: =+Input!B45*(1-Input!E45) -> 0 | E10: =INDEX(LCI!H$2:H$130,MATCH('A1 - Raw Material Supply'!$B10,LCI!$D$2:$D$130,0))*$C10 -> 0 | F10: =INDEX(LCI!I$2:I$130,MATCH('A1 - Raw Material Supply'!$B10,LCI!$D$2:$D$130,0))*$C10 -> 0 | G10: =INDEX(LCI!J$2:J$130,MATCH('A1 - Raw Material Supply'!$B10,LCI!$D$2:$D$130,0))*$C10 -> 0 | H10: =INDEX(LCI!K$2:K$130,MATCH('A1 - Raw Material Supply'!$B10,LCI!$D$2:$D$130,0))*$C10 -> 0 | I10: =INDEX(LCI!L$2:L$130,MATCH('A1 - Raw Material Supply'!$B10,LCI!$D$2:$D$130,0))*$C10 -> 0 | J10: =INDEX(LCI!M$2:M$130,MATCH('A1 - Raw Material Supply'!$B10,LCI!$D$2:$D$130,0))*$C10 -> 0 | K10: =INDEX(LCI!N$2:N$130,MATCH('A1 - Raw Material Supply'!$B10,LCI!$D$2:$D$130,0))*$C10 -> 0 | L10: =INDEX(LCI!O$2:O$130,MATCH('A1 - Raw Material Supply'!$B10,LCI!$D$2:$D$130,0))*$C10 -> 0 | ... W10: =INDEX(LCI!Z$2:Z$130,MATCH('A1 - Raw Material Supply'!$B10,LCI!$D$2:$D$130,0))*$C10 -> 0
B11: =Input!A46 -> Virgin natural fine aggregate 1 (≤2 mm) | C11: =+Input!B46*(1-Input!E46) -> 0.153 | E11: =INDEX(LCI!H$2:H$130,MATCH('A1 - Raw Material Supply'!$B11,LCI!$D$2:$D$130,0))*$C11 -> 0.0070343064 | F11: =INDEX(LCI!I$2:I$130,MATCH('A1 - Raw Material Supply'!$B11,LCI!$D$2:$D$130,0))*$C11 -> 0.79787172 | G11: =INDEX(LCI!J$2:J$130,MATCH('A1 - Raw Material Supply'!$B11,LCI!$D$2:$D$130,0))*$C11 -> -0.00019195363 | H11: =INDEX(LCI!K$2:K$130,MATCH('A1 - Raw Material Supply'!$B11,LCI!$D$2:$D$130,0))*$C11 -> 0.79795388 | I11: =INDEX(LCI!L$2:L$130,MATCH('A1 - Raw Material Supply'!$B11,LCI!$D$2:$D$130,0))*$C11 -> 0.00010979808 | J11: =INDEX(LCI!M$2:M$130,MATCH('A1 - Raw Material Supply'!$B11,LCI!$D$2:$D$130,0))*$C11 -> 0.68141438 | K11: =INDEX(LCI!N$2:N$130,MATCH('A1 - Raw Material Supply'!$B11,LCI!$D$2:$D$130,0))*$C11 -> 10.370945 | L11: =INDEX(LCI!O$2:O$130,MATCH('A1 - Raw Material Supply'!$B11,LCI!$D$2:$D$130,0))*$C11 -> 3.5986534e-05 | ... W11: =INDEX(LCI!Z$2:Z$130,MATCH('A1 - Raw Material Supply'!$B11,LCI!$D$2:$D$130,0))*$C11 -> 1.0207571
B12: =Input!A47 -> Virgin natural fine aggregate 2 (≤2 mm) | C12: =+Input!B47*(1-Input!E47) -> 0 | E12: =INDEX(LCI!H$2:H$130,MATCH('A1 - Raw Material Supply'!$B12,LCI!$D$2:$D$130,0))*$C12 -> 0 | F12: =INDEX(LCI!I$2:I$130,MATCH('A1 - Raw Material Supply'!$B12,LCI!$D$2:$D$130,0))*$C12 -> 0 | G12: =INDEX(LCI!J$2:J$130,MATCH('A1 - Raw Material Supply'!$B12,LCI!$D$2:$D$130,0))*$C12 -> 0 | H12: =INDEX(LCI!K$2:K$130,MATCH('A1 - Raw Material Supply'!$B12,LCI!$D$2:$D$130,0))*$C12 -> 0 | I12: =INDEX(LCI!L$2:L$130,MATCH('A1 - Raw Material Supply'!$B12,LCI!$D$2:$D$130,0))*$C12 -> 0 | J12: =INDEX(LCI!M$2:M$130,MATCH('A1 - Raw Material Supply'!$B12,LCI!$D$2:$D$130,0))*$C12 -> 0 | K12: =INDEX(LCI!N$2:N$130,MATCH('A1 - Raw Material Supply'!$B12,LCI!$D$2:$D$130,0))*$C12 -> 0 | L12: =INDEX(LCI!O$2:O$130,MATCH('A1 - Raw Material Supply'!$B12,LCI!$D$2:$D$130,0))*$C12 -> 0 | ... W12: =INDEX(LCI!Z$2:Z$130,MATCH('A1 - Raw Material Supply'!$B12,LCI!$D$2:$D$130,0))*$C12 -> 0
B13: =Input!A48 -> Virgin natural fine aggregate 3 (≤2 mm) | C13: =+Input!B48*(1-Input!E48) -> 0 | E13: =INDEX(LCI!H$2:H$130,MATCH('A1 - Raw Material Supply'!$B13,LCI!$D$2:$D$130,0))*$C13 -> 0 | F13: =INDEX(LCI!I$2:I$130,MATCH('A1 - Raw Material Supply'!$B13,LCI!$D$2:$D$130,0))*$C13 -> 0 | G13: =INDEX(LCI!J$2:J$130,MATCH('A1 - Raw Material Supply'!$B13,LCI!$D$2:$D$130,0))*$C13 -> 0 | H13: =INDEX(LCI!K$2:K$130,MATCH('A1 - Raw Material Supply'!$B13,LCI!$D$2:$D$130,0))*$C13 -> 0 | I13: =INDEX(LCI!L$2:L$130,MATCH('A1 - Raw Material Supply'!$B13,LCI!$D$2:$D$130,0))*$C13 -> 0 | J13: =INDEX(LCI!M$2:M$130,MATCH('A1 - Raw Material Supply'!$B13,LCI!$D$2:$D$130,0))*$C13 -> 0 | K13: =INDEX(LCI!N$2:N$130,MATCH('A1 - Raw Material Supply'!$B13,LCI!$D$2:$D$130,0))*$C13 -> 0 | L13: =INDEX(LCI!O$2:O$130,MATCH('A1 - Raw Material Supply'!$B13,LCI!$D$2:$D$130,0))*$C13 -> 0 | ... W13: =INDEX(LCI!Z$2:Z$130,MATCH('A1 - Raw Material Supply'!$B13,LCI!$D$2:$D$130,0))*$C13 -> 0
A14: Filler | B14: =Input!A49 -> Filler 1 | C14: =+Input!B49*(1-Input!E49) -> 0.0055 | D14: =Input!$C$49 -> Limestone_residue | E14: {=INDEX(LCI!H$2:H$130,MATCH('A1 - Raw Material Supply'!$B$14&'A1 - Raw Material Supply'!$D$14,LCI!$B$2:$B$130&LCI!$D$2:$D$130,0))*$C14} -> 0.00093081697 | F14: {=INDEX(LCI!I$2:I$130,MATCH('A1 - Raw Material Supply'!$B$14&'A1 - Raw Material Supply'!$D$14,LCI!$B$2:$B$130&LCI!$D$2:$D$130,0))*$C14} -> 0.12166438 | G14: {=INDEX(LCI!J$2:J$130,MATCH('A1 - Raw Material Supply'!$B$14&'A1 - Raw Material Supply'!$D$14,LCI!$B$2:$B$130&LCI!$D$2:$D$130,0))*$C14} -> 0.0018973974 | H14: {=INDEX(LCI!K$2:K$130,MATCH('A1 - Raw Material Supply'!$B$14&'A1 - Raw Material Supply'!$D$14,LCI!$B$2:$B$130&LCI!$D$2:$D$130,0))*$C14} -> 0.11956136 | I14: {=INDEX(LCI!L$2:L$130,MATCH('A1 - Raw Material Supply'!$B$14&'A1 - Raw Material Supply'!$D$14,LCI!$B$2:$B$130&LCI!$D$2:$D$130,0))*$C14} -> 0.00020562003 | J14: {=INDEX(LCI!M$2:M$130,MATCH('A1 - Raw Material Supply'!$B$14&'A1 - Raw Material Supply'!$D$14,LCI!$B$2:$B$130&LCI!$D$2:$D$130,0))*$C14} -> 0.37977549 | K14: {=INDEX(LCI!N$2:N$130,MATCH('A1 - Raw Material Supply'!$B$14&'A1 - Raw Material Supply'!$D$14,LCI!$B$2:$B$130&LCI!$D$2:$D$130,0))*$C14} -> 2.0373321 | L14: {=INDEX(LCI!O$2:O$130,MATCH('A1 - Raw Material Supply'!$B$14&'A1 - Raw Material Supply'!$D$14,LCI!$B$2:$B$130&LCI!$D$2:$D$130,0))*$C14} -> 7.3105915e-05 | ... W14: {=INDEX(LCI!Z$2:Z$130,MATCH('A1 - Raw Material Supply'!$B$14&'A1 - Raw Material Supply'!$D$14,LCI!$B$2:$B$130&LCI!$D$2:$D$130,0))*$C14} -> 0.25392573
B15: =Input!A50 -> Filler 2 | C15: =+Input!B50*(1-Input!E50) -> 0 | D15: =Input!$C$50 -> No_filler | E15: {=INDEX(LCI!H$2:H$130,MATCH('A1 - Raw Material Supply'!$B$15&'A1 - Raw Material Supply'!$D$15,LCI!$B$2:$B$130&LCI!$D$2:$D$130,0))*$C15} -> 0 | F15: {=INDEX(LCI!I$2:I$130,MATCH('A1 - Raw Material Supply'!$B$15&'A1 - Raw Material Supply'!$D$15,LCI!$B$2:$B$130&LCI!$D$2:$D$130,0))*$C15} -> 0 | G15: {=INDEX(LCI!J$2:J$130,MATCH('A1 - Raw Material Supply'!$B$15&'A1 - Raw Material Supply'!$D$15,LCI!$B$2:$B$130&LCI!$D$2:$D$130,0))*$C15} -> 0 | H15: {=INDEX(LCI!K$2:K$130,MATCH('A1 - Raw Material Supply'!$B$15&'A1 - Raw Material Supply'!$D$15,LCI!$B$2:$B$130&LCI!$D$2:$D$130,0))*$C15} -> 0 | I15: {=INDEX(LCI!L$2:L$130,MATCH('A1 - Raw Material Supply'!$B$15&'A1 - Raw Material Supply'!$D$15,LCI!$B$2:$B$130&LCI!$D$2:$D$130,0))*$C15} -> 0 | J15: {=INDEX(LCI!M$2:M$130,MATCH('A1 - Raw Material Supply'!$B$15&'A1 - Raw Material Supply'!$D$15,LCI!$B$2:$B$130&LCI!$D$2:$D$130,0))*$C15} -> 0 | K15: {=INDEX(LCI!N$2:N$130,MATCH('A1 - Raw Material Supply'!$B$15&'A1 - Raw Material Supply'!$D$15,LCI!$B$2:$B$130&LCI!$D$2:$D$130,0))*$C15} -> 0 | L15: {=INDEX(LCI!O$2:O$130,MATCH('A1 - Raw Material Supply'!$B$15&'A1 - Raw Material Supply'!$D$15,LCI!$B$2:$B$130&LCI!$D$2:$D$130,0))*$C15} -> 0 | ... W15: {=INDEX(LCI!Z$2:Z$130,MATCH('A1 - Raw Material Supply'!$B$15&'A1 - Raw Material Supply'!$D$15,LCI!$B$2:$B$130&LCI!$D$2:$D$130,0))*$C15} -> 0
A16: Reclaimed Asphalt Pavement | B16: =Input!A51 -> RAP 1
B17: =Input!A52 -> RAP 2
A18: Recycled Waste | B18: =Input!A53 -> Other_waste 1
B19: =Input!A54 -> Other_waste 2
A20: Additive | B20: =Input!A55 -> Additive 1 | C20: =+Input!B55*(1-Input!E55) -> 0.0033 | D20: =Input!$C$55 -> Cellulose_fibres | E20: {=INDEX(LCI!H$2:H$130,MATCH('A1 - Raw Material Supply'!$B$20&'A1 - Raw Material Supply'!$D$20,LCI!$B$2:$B$130&LCI!$D$2:$D$130,0))*$C$20} -> 0.0052168552 | F20: {=INDEX(LCI!I$2:I$130,MATCH('A1 - Raw Material Supply'!$B$20&'A1 - Raw Material Supply'!$D$20,LCI!$B$2:$B$130&LCI!$D$2:$D$130,0))*$C$20} -> 0.65423526 | G20: {=INDEX(LCI!J$2:J$130,MATCH('A1 - Raw Material Supply'!$B$20&'A1 - Raw Material Supply'!$D$20,LCI!$B$2:$B$130&LCI!$D$2:$D$130,0))*$C$20} -> 0.10686811 | H20: {=INDEX(LCI!K$2:K$130,MATCH('A1 - Raw Material Supply'!$B$20&'A1 - Raw Material Supply'!$D$20,LCI!$B$2:$B$130&LCI!$D$2:$D$130,0))*$C$20} -> 0.54691622 | I20: {=INDEX(LCI!L$2:L$130,MATCH('A1 - Raw Material Supply'!$B$20&'A1 - Raw Material Supply'!$D$20,LCI!$B$2:$B$130&LCI!$D$2:$D$130,0))*$C$20} -> 0.00045093023 | J20: {=INDEX(LCI!M$2:M$130,MATCH('A1 - Raw Material Supply'!$B$20&'A1 - Raw Material Supply'!$D$20,LCI!$B$2:$B$130&LCI!$D$2:$D$130,0))*$C$20} -> 2.7323847 | K20: {=INDEX(LCI!N$2:N$130,MATCH('A1 - Raw Material Supply'!$B$20&'A1 - Raw Material Supply'!$D$20,LCI!$B$2:$B$130&LCI!$D$2:$D$130,0))*$C$20} -> 7.5519829 | L20: {=INDEX(LCI!O$2:O$130,MATCH('A1 - Raw Material Supply'!$B$20&'A1 - Raw Material Supply'!$D$20,LCI!$B$2:$B$130&LCI!$D$2:$D$130,0))*$C$20} -> 0.00017251446 | ... W20: {=INDEX(LCI!Z$2:Z$130,MATCH('A1 - Raw Material Supply'!$B$20&'A1 - Raw Material Supply'!$D$20,LCI!$B$2:$B$130&LCI!$D$2:$D$130,0))*$C$20} -> 0.33021434
B21: =Input!A56 -> Additive 2 | C21: =+Input!B56*(1-Input!E56) -> 0 | D21: =Input!$C$56 -> No_additives | E21: {=INDEX(LCI!H$2:H$130,MATCH('A1 - Raw Material Supply'!$B$21&'A1 - Raw Material Supply'!$D$21,LCI!$B$2:$B$130&LCI!$D$2:$D$130,0))*$C$21} -> 0 | F21: {=INDEX(LCI!I$2:I$130,MATCH('A1 - Raw Material Supply'!$B$21&'A1 - Raw Material Supply'!$D$21,LCI!$B$2:$B$130&LCI!$D$2:$D$130,0))*$C$21} -> 0 | G21: {=INDEX(LCI!J$2:J$130,MATCH('A1 - Raw Material Supply'!$B$21&'A1 - Raw Material Supply'!$D$21,LCI!$B$2:$B$130&LCI!$D$2:$D$130,0))*$C$21} -> 0 | H21: {=INDEX(LCI!K$2:K$130,MATCH('A1 - Raw Material Supply'!$B$21&'A1 - Raw Material Supply'!$D$21,LCI!$B$2:$B$130&LCI!$D$2:$D$130,0))*$C$21} -> 0 | I21: {=INDEX(LCI!L$2:L$130,MATCH('A1 - Raw Material Supply'!$B$21&'A1 - Raw Material Supply'!$D$21,LCI!$B$2:$B$130&LCI!$D$2:$D$130,0))*$C$21} -> 0 | J21: {=INDEX(LCI!M$2:M$130,MATCH('A1 - Raw Material Supply'!$B$21&'A1 - Raw Material Supply'!$D$21,LCI!$B$2:$B$130&LCI!$D$2:$D$130,0))*$C$21} -> 0 | K21: {=INDEX(LCI!N$2:N$130,MATCH('A1 - Raw Material Supply'!$B$21&'A1 - Raw Material Supply'!$D$21,LCI!$B$2:$B$130&LCI!$D$2:$D$130,0))*$C$21} -> 0 | L21: {=INDEX(LCI!O$2:O$130,MATCH('A1 - Raw Material Supply'!$B$21&'A1 - Raw Material Supply'!$D$21,LCI!$B$2:$B$130&LCI!$D$2:$D$130,0))*$C$21} -> 0 | ... W21: {=INDEX(LCI!Z$2:Z$130,MATCH('A1 - Raw Material Supply'!$B$21&'A1 - Raw Material Supply'!$D$21,LCI!$B$2:$B$130&LCI!$D$2:$D$130,0))*$C$21} -> 0
B22: =Input!A57 -> Additive 3 | C22: =+Input!B57*(1-Input!E57) -> 0 | D22: =Input!$C$57 -> No_additives | E22: {=INDEX(LCI!H$2:H$130,MATCH('A1 - Raw Material Supply'!$B$22&'A1 - Raw Material Supply'!$D$22,LCI!$B$2:$B$130&LCI!$D$2:$D$130,0))*$C$22} -> 0 | F22: {=INDEX(LCI!I$2:I$130,MATCH('A1 - Raw Material Supply'!$B$22&'A1 - Raw Material Supply'!$D$22,LCI!$B$2:$B$130&LCI!$D$2:$D$130,0))*$C$22} -> 0 | G22: {=INDEX(LCI!J$2:J$130,MATCH('A1 - Raw Material Supply'!$B$22&'A1 - Raw Material Supply'!$D$22,LCI!$B$2:$B$130&LCI!$D$2:$D$130,0))*$C$22} -> 0 | H22: {=INDEX(LCI!K$2:K$130,MATCH('A1 - Raw Material Supply'!$B$22&'A1 - Raw Material Supply'!$D$22,LCI!$B$2:$B$130&LCI!$D$2:$D$130,0))*$C$22} -> 0 | I22: {=INDEX(LCI!L$2:L$130,MATCH('A1 - Raw Material Supply'!$B$22&'A1 - Raw Material Supply'!$D$22,LCI!$B$2:$B$130&LCI!$D$2:$D$130,0))*$C$22} -> 0 | J22: {=INDEX(LCI!M$2:M$130,MATCH('A1 - Raw Material Supply'!$B$22&'A1 - Raw Material Supply'!$D$22,LCI!$B$2:$B$130&LCI!$D$2:$D$130,0))*$C$22} -> 0 | K22: {=INDEX(LCI!N$2:N$130,MATCH('A1 - Raw Material Supply'!$B$22&'A1 - Raw Material Supply'!$D$22,LCI!$B$2:$B$130&LCI!$D$2:$D$130,0))*$C$22} -> 0 | L22: {=INDEX(LCI!O$2:O$130,MATCH('A1 - Raw Material Supply'!$B$22&'A1 - Raw Material Supply'!$D$22,LCI!$B$2:$B$130&LCI!$D$2:$D$130,0))*$C$22} -> 0 | ... W22: {=INDEX(LCI!Z$2:Z$130,MATCH('A1 - Raw Material Supply'!$B$22&'A1 - Raw Material Supply'!$D$22,LCI!$B$2:$B$130&LCI!$D$2:$D$130,0))*$C$22} -> 0
A23: Total | C23: =SUM(C4:C22) -> 0.63896 | E23: =SUM(E4:E22) -> 0.07606603 | F23: =SUM(F4:F22) -> 14.605727 | G23: =SUM(G4:G22) -> 0.15907702 | H23: =SUM(H4:H22) -> 14.447676 | I23: =SUM(I4:I22) -> 0.0070618731 | J23: =SUM(J4:J22) -> 648.07216 | K23: =SUM(K4:K22) -> 1053.1269 | L23: =SUM(L4:L22) -> 0.00038657618 | ... W23: =SUM(W4:W22) -> 3.5963311
A26: Impacts: Biogenic asphalt mix components
A27: Components | B27: Materials | C27: Mass (ton] | D27: List | E27: acidification | accumulated exceedance (AE) mol H+ -eq | F27: climate change | global warming potential (GWP100) kgCO2-Eq | G27: climate change: biogenic | global warming potential (GWP100) kgCO2-Eq | H27: climate change: fossil | global warming potential (GWP100) kgCO2-Eq | I27: land use and land use change | global warming potential (GWP100) kgCO2-Eq | J27: ecotoxicity: freshwater | comparative toxic unit for ecosystems (CTUe) | K27: energy resources: non-renewable | abiotic depletion potential (ADP): fossil fuels MJ, net calorific value | L27: eutrophication: freshwater | fraction of nutrients reaching freshwater end compartment (P) | M27: eutrophication: marine | fraction of nutrients reaching marine end compartment (N) kg N-Eq | N27: eutrophication: terrestrial | accumulated exceedance (AE) mol N-Eq | O27: human toxicity: carcinogenic | comparative toxic unit for human (CTUh) | P27: human toxicity: non-carcinogenic | comparative toxic unit for human (CTUh) | Q27: ionising radiation: human health | human exposure efficiency relative to u235 kBq U235-Eq | R27: land use | soil quality index dimensionless | S27: material resources: metals/minerals | abiotic depletion potential (ADP): elements (ultimate reserves) kg Sb-Eq | T27: ozone depletion|ozone depletion potential (ODP) kg CFC-11-Eq | U27: particulate matter formation | impact on human health | V27: photochemical oxidant formation: human health | tropospheric ozone concentration increase kg NMVOC-Eq | W27: water use | user deprivation potential (deprivation-weighted water consumption) m3 world eq deprived
