Workbook

Sheet algemeen
A1: ALGEMENE GEGEVENS BEDRIJVEN EN INSTALLATIES
B3: GEGEVENS FIRMA (CERTIFICAATHOUDER)
B4: Bedrijfsnaam: | E4: ASFALT PRODUCTIE BEDRIJF nv
B5: Adres: | D5: straat en nr. | E5: Dendermondsesteenweg 123
D6: postnummer en gemeente | E6: 1234 Brussel | J6: Eventueel aangevuld met het land, indien verschillend van België.
B7: Contactpersoon: | D7: naam | E7: Elfver Vandenbraembussche | J7: Contactpersoon i.v.m. deze verantwoordingsnota.
D8: tel. | E8: 02 345 67 89
D9: e-mail | E9: tom.christianen@apb.be
B10: Verantwoordelijke DoP: | E10: Jan Baas
D11: functie | E11: gedelegeerd bestuurder
B14: GEGEVENS GEMACHTIGDE VOOR PRESTATIEVERKLARING (indien verschillend van certificaathouder)
B15: Naam (bedrijf of persoon): | E15: Dekmantelvennootschap bvba | J15: In principe niet van toepassing. Leeg maken indien niet van toepassing.
B16: Adres: | D16: straat en nr. | E16: Blue Lagoon 69
D17: postnummer en gemeente | E17: 666 Bananenstad, Curaçao | J17: Eventueel aangevuld met het land, indien verschillend van België.
B20: PRODUCTIE-EENHEDEN | F20: 1 | I20: 2 | L20: 3
B21: Bedrijfsnaam: | E21: ABC nv | H21: DEF nv | K21: GHI nv
B22: Adres: | D22: straat en nr. | E22: straat 1 | H22: straat 2 | K22: straat 3
D23: postnummer | E23: 1000 | H23: 2000 | K23: 3000
D24: gemeente | E24: Gaurain-Ramecroix | H24: Antwerpen | K24: Hasselt | N24: Eventueel aangevuld met het land, indien verschillend van België.
B25: Contactpersoon: | D25: naam | E25: Jan Molenbaas | H25: Piet Molenbaas | K25: Jef Molenbaas | N25: Contactpersoon i.v.m. de productie.
D26: tel. | E26: 02 345 00 00 | H26: 03 456 00 00 | K26: 04 789 00 00
B27: Identificatienummers:
D28: productie-eenheid COPRO | E28: 801 | H28: 802 | K28: 8031 | N28: Vb. 803.
D29: nummer DoP | E29: 0801/3100-CPR-2014/03/18 | H29: 0802/3100-CPR-2014/03/18 | K29: 0803/3100-CPR-2014/03/18 | N29: Vb. 0803/1234-CPR-2014/03/18
D30: nummer FPC-certificaat | E30: 1137-CPR-0801/64-65 | H30: 1137-CPR-0802/64-65 | K30: 1137-CPR-0802/64-65 | N30: Vb. 1137-CPR-803/64-65
B31: Asfaltmenginstallatie:
D32: merk en bouwjaar | E32: Ammann 2010 | H32: Benninghoven 2010 | K32: Marini 2000
D33: productiecapaciteit (ton/h) | E33: 350 | H33: 350 | K33: 300
D34: type menginstallatie | E34: discontinu | H34: discontinu | K34: discontinu | N34: continu, discontinu, ...
D35: type asfaltcentrale | E35: aardgas | H35: propaan | K35: elektrisch | N35: aardgas, propaan, elektrisch, aardgas/elektrisch (nodig in kader van GPP)
A37: ALGEMENE GEGEVENS VOORSTUDIE
B39: MENGSEL
B40: Naam volgens bestek: | F40: AB-3A1
B41: Naam volgens Europese Norm: | F41: AC 20 onderlaag 50/70
B42: Commerciële benaming: | F42: toplaag 0/10 | K42: Eigen keuze, maar niet in tegenstrijd met officiële benamingen.
B43: Type mengsel volgens productnorm: | F43: EN 13108-1 | K43: Keuze uit pull-down menu.
B44: Toepassing: | F44: voor onderlagen van asfaltverhardingen | K44: Waar het mengsel voor gebruikt kan worden.
B46: REFERENTIEDOCUMENTEN
B47: Bestek: | D47: SB 250 (5.0) | H47: Naam en versie van het typebestek, standaardbestek of bijzonder bestek. Vb. SB 250 (5.0)
B48: Europese Norm: | D48: EN 13108-1 (2006) + EN 13108-1/AC (2008) | H48: Naam en jaartal van de Europese Norm in volgend formaat : EN 13108-1 (2006) + EN 13108-1/AC (2008)
...

Sheet Info voor GPP
A1: INFO VOOR GPP tool
E2: =algemeen!E28 -> 801 | G2: =algemeen!H28 -> 802 | I2: =algemeen!K28 -> 8031
B3: GPP Onderdeel | C3: Parameter (GPP-tool)
B4: 1. Algemene gegevens | C4: Datum | E4: =algemeen!G78 -> 40409 | G4: =algemeen!G78 -> 40409 | I4: =algemeen!G78 -> 40409
C5: Mengsel ID | E5: =E2&"/64/"&algemeen!J66 -> 801/64/2010/13RE-1234/0 | G5: =G2&"/64/"&algemeen!J66 -> 802/64/2010/13RE-1234/0 | I5: =I2&"/64/"&algemeen!J66 -> 8031/64/2010/13RE-1234/0
C6: Mengseltype (SB250) | E6: =algemeen!F40 -> AB-3A1 | G6: =algemeen!F40 -> AB-3A1 | I6: =algemeen!F40 -> AB-3A1
C7: Mengseltype (EN 13108) | E7: =algemeen!F41 -> AC 20 onderlaag 50/70 | G7: =algemeen!F41 -> AC 20 onderlaag 50/70 | I7: =algemeen!F41 -> AC 20 onderlaag 50/70
C8: Totaal bindmiddelgehalte (%) | E8: =samenstelling!C151 -> 3.71605 | G8: =samenstelling!C151 -> 3.71605 | I8: =samenstelling!C151 -> 3.71605 | K8: Aan te passen indien nodig
C9: Bindmiddelvervanging (% bindmiddel van AG) | E9: =samenstelling!C148 -> 1.5 | G9: =samenstelling!C148 -> 1.5 | I9: =samenstelling!C148 -> 1.5 | K9: Aan te passen indien nodig
C10: Virgin binder | E10: =samenstelling!C145 -> 2.21605 | G10: =samenstelling!C145 -> 2.21605 | I10: =samenstelling!C145 -> 2.21605
B12: 2. Productie asfaltmengsel | C12: Locatie asfaltcentrale | E12: =_xlfn.CONCAT(algemeen!E24," ,",algemeen!E23," ,",algemeen!E22) -> Gaurain-Ramecroix ,1000 ,straat 1 | G12: =_xlfn.CONCAT(algemeen!H24," ,",algemeen!H23," ,",algemeen!H22) -> Antwerpen ,2000 ,straat 2 | I12: =_xlfn.CONCAT(algemeen!K24," ,",algemeen!K23," ,",algemeen!K22) -> Hasselt ,3000 ,straat 3
C13: Type primair asfaltcentrale: aardgas, propaan, elektrisch | E13: =algemeen!E35 -> aardgas | G13: =algemeen!H35 -> propaan | I13: =algemeen!K35 -> elektrisch | K13: Aan te passen indien nodig
C14: Energiebron (primair) % | E14: 1 | G14: 1 | I14: 1
C15: Type secundair asfaltcentrale: aardgas, propaan, elektrisch | E15: Geen | G15: Geen | I15: Geen
C16: Energiebron (secundair) % | E16: 0 | G16: 0 | I16: 0
C17: Productiecapaciteit (ton/h) | E17: =algemeen!E33 -> 350 | G17: =algemeen!H33 -> 350 | I17: =algemeen!K33 -> 300 | K17: Aan te passen indien nodig
C18: Productietemperatuur | E18: =algemeen!F129 -> 145-185 | G18: =algemeen!I129 -> 150-190 | I18: =algemeen!L129 -> 155-195
C19: Elektrisch aandeel equipment | E19: Ja | G19: Ja | I19: No | K19: zelf in te vullen
C20: Elektrisch aandeel equipment bron | E20: Elektriciteit normaal | G20: elektriciteit groen | I20: Geen
C21: Wheel loader fuel source | E21: Diesel | G21: Diesel | I21: Diesel | K21: zelf in te vullen
F22: aanvoer per | H22: aanvoer per | J22: aanvoer per
B23: 3. Samenstelling mengsel | C23: Bindmiddeltype
C24: =samenstelling!E43 -> synthetisch pigmenteerbaar bindmiddel | D24: =E8 -> 3.71605 | E24: =samenstelling!N43 -> Koudekerk-aan-de-Rijn | F24: vrachtwagen | G24: =samenstelling!N43 -> Koudekerk-aan-de-Rijn | H24: vrachtwagen | I24: =samenstelling!N43 -> Koudekerk-aan-de-Rijn | J24: vrachtwagen
C25: =samenstelling!E44 | E25: =samenstelling!N44
C26: =samenstelling!E45 | E26: =samenstelling!N45
K27: Aan te passen indien nodig
C28: Aggregaten | D28: %
C29: =samenstelling!E8&" "&samenstelling!H8 -> Kalksteen 14/20 | D29: =samenstelling!C8 -> 5.1 | E29: =samenstelling!N8 -> Beez | F29: vrachtwagen | G29: =samenstelling!N8 -> Beez | H29: schip | I29: =samenstelling!N8 -> Beez | J29: schip | K29: Aan te passen indien nodig
C30: =samenstelling!E9&" "&samenstelling!H9 -> Porfier 6/14 | D30: =samenstelling!C9 -> 10.2 | E30: =samenstelling!N9 -> Soignies | F30: schip | G30: =samenstelling!N9 -> Soignies | H30: schip | I30: =samenstelling!N9 -> Soignies | J30: vrachtwagen | K30: Aan te passen indien nodig
C31: =samenstelling!E10&" "&samenstelling!H10 -> Rode zandsteen 0/2 (0/0,05) | D31: =samenstelling!C10 -> 15.3 | E31: =samenstelling!N10 -> Neufvilles | F31: schip | G31: =samenstelling!N10 -> Neufvilles | I31: =samenstelling!N10 -> Neufvilles | K31: Aan te passen indien nodig
C32: =samenstelling!E11&" "&samenstelling!H11 | D32: =samenstelling!C11 | E32: =samenstelling!N11 | G32: =samenstelling!N11 | I32: =samenstelling!N11 | K32: Aan te passen indien nodig
C33: =samenstelling!E12&" "&samenstelling!H12 | D33: =samenstelling!C12 | E33: =samenstelling!N12 | G33: =samenstelling!N12 | I33: =samenstelling!N12 | K33: Aan te passen indien nodig
C34: =samenstelling!E13&" "&samenstelling!H13 -> Slakken 6/10 | D34: =samenstelling!C13 -> 35.3 | E34: =samenstelling!N13 -> Genk | F34: vrachtwagen | G34: =samenstelling!N13 -> Genk | I34: =samenstelling!N13 -> Genk | K34: Aan te passen indien nodig
C35: =samenstelling!E14&" "&samenstelling!H14 -> Kalksteen 14/20 | D35: =samenstelling!C14 -> 0 | E35: =samenstelling!N14 -> Beez | G35: =samenstelling!N14 -> Beez | I35: =samenstelling!N14 -> Beez | K35: Aan te passen indien nodig
C36: =samenstelling!E15&" "&samenstelling!H15 -> Porfier 6/14 | D36: =samenstelling!C15 -> 0 | E36: =samenstelling!N15 -> Soignies | G36: =samenstelling!N15 -> Soignies | I36: =samenstelling!N15 -> Soignies | K36: Aan te passen indien nodig
C37: =samenstelling!E16&" "&samenstelling!H16 -> Slakken 6/10 | D37: =samenstelling!C16 -> 0 | E37: =samenstelling!N16 -> Genk | G37: =samenstelling!N16 -> Genk | I37: =samenstelling!N16 -> Genk | K37: Aan te passen indien nodig
C38: =samenstelling!E26&" "&samenstelling!H26 -> Aanvoervulstof IIa | D38: =samenstelling!C26 -> 0.55 | E38: =samenstelling!N26 -> Ankersmit Maastricht | G38: =samenstelling!N26 -> Ankersmit Maastricht | I38: =samenstelling!N26 -> Ankersmit Maastricht | K38: Aan te passen indien nodig
C39: =samenstelling!E27&" "&samenstelling!H27 | D39: =samenstelling!C27 | E39: =samenstelling!N27 | G39: =samenstelling!N27 | I39: =samenstelling!N27
C40: =samenstelling!E29&" "&samenstelling!H29 -> Extra teruggew. stof | D40: =samenstelling!C29 -> 1 | E40: =samenstelling!N29 -> Productieproces
C41: =samenstelling!E56&" "&samenstelling!K56 -> Asfaltgranulaat onderlaag 14/2 | D41: =samenstelling!C56 -> 30 | E41: Add location manually | F41: Truck | G41: Add location manually | H41: Truck | I41: Add location manually | J41: Truck | K41: Aan te passen indien nodig
...

Sheet grondstoffen
A1: GEGEVENS GRONDSTOFFEN
B3: Hieronder kan u alle mogelijke grondstoffen ingeven die u bij voorstudies kan gebruiken.
B5: AGGREGATEN (Steenslag en zand)
B6: Nr. | E6: Aard | H6: Kaliber | I6: PTV | K6: Leverancier | N6: Herkomst | Q6: Keuring | S6: Volumemassa | U6: Hoekigheid | W6: Korrelverdeling (in % doorval door de zeef van … mm) | AM6: Andere klassen
I7: klasse | S7: (Mg/m³) | W7: =berekeningen!D9 -> 40 | X7: =berekeningen!E9 -> 31.5 | Y7: =berekeningen!F9 -> 20 | Z7: =berekeningen!G9 -> 16 | AA7: =berekeningen!H9 -> 14 | AB7: =berekeningen!I9 -> 12.5 | AC7: =berekeningen!J9 -> 10 | AD7: =berekeningen!K9 -> 8 | ... AL7: =berekeningen!S9 -> 0.063 | AM7: FI | AN7: C | AO7: Ecs | AP7: LA | AQ7: MD | AR7: PSV
B8: 1 | E8: Kalksteen | H8: 14/20 | I8: Aa1 I f1 | K8: Gralex | N8: Beez | Q8: BENOR | S8: 2.789 | U8: B | W8: 100 | X8: 100 | Y8: 99 | Z8: 55 | AA8: 25 | AB8: 10 | AC8: 2 | AD8: 1 | AE8: 0.9 | AF8: 0.8 | AG8: 0.7 | AH8: 0.6 | AI8: 0.5 | AJ8: 0.4 | AK8: 0.3 | AL8: 0.2 | AM8: 15 | AN8: 100/0 | AO8: 25 | AP8: 10 | AQ8: 35 | AR8: 50
B9: 2 | E9: Porfier | H9: 6/14 | I9: BB2 II f2 | K9: Holcim | N9: Soignies | Q9: BENOR | S9: 2.788 | U9: B | Y9: 100 | Z9: 98 | AA9: 97 | AB9: 72 | AC9: 65 | AD9: 44 | AE9: 21 | AF9: 10 | AG9: 4 | AH9: 3 | AI9: 2 | AJ9: 1 | AK9: 0.5 | AL9: 0.2 | AM9: 20 | AN9: 100/0 | AO9: 30 | AP9: 15 | AQ9: 40 | AR9: 52
B10: 3 | E10: Rode zandsteen | H10: 0/2 (0/0,05) | I10: Af22aPA Ecs30 | K10: Porfibel | N10: Neufvilles | Q10: BENOR | S10: 2.786 | U10: R | AC10: 100 | AD10: 98 | AE10: 85 | AF10: 64 | AG10: 23 | AH10: 11 | AI10: 4 | AJ10: 3 | AK10: 2 | AL10: 1 | AM10: 25 | AN10: 95/3 | AO10: 35 | AP10: 20 | AQ10: 45 | AR10: 54
B11: 4
B12: 5
B13: 6 | E13: Slakken | H13: 6/10 | I13: Dd4 IV f4 | K13: SDF | N13: Genk | Q13: intern | S13: 3.21 | U13: B | AA13: 100 | AB13: 100 | AC13: 95 | AD13: 50 | AE13: 12 | AF13: 7 | AG13: 6 | AH13: 5 | AI13: 4 | AJ13: 3 | AK13: 2 | AL13: 1 | AM13: 30 | AN13: 100/0 | AO13: 38 | AP13: 25 | AQ13: 50 | AR13: 56
B14: 7
B15: 8
B16: 9
B17: 10
B18: 11 | E18: Kalksteen | H18: 14/20 | I18: Aa1 I f1 | K18: Gralex | N18: Beez | Q18: BENOR | S18: 2.779 | U18: B | W18: 100 | X18: 100 | Y18: 99 | Z18: 55 | AA18: 25 | AB18: 10 | AC18: 2 | AD18: 1 | AE18: 0.9 | AF18: 0.8 | AG18: 0.7 | AH18: 0.6 | AI18: 0.5 | AJ18: 0.4 | AK18: 0.3 | AL18: 0.2 | AM18: 15 | AN18: 100/0 | AO18: 25 | AP18: 10 | AQ18: 35 | AR18: 58
B19: 12 | E19: Porfier | H19: 6/14 | I19: BB2 II f2 | K19: Holcim | N19: Soignies | Q19: BENOR | S19: 2.778 | U19: B | Y19: 100 | Z19: 98 | AA19: 97 | AB19: 72 | AC19: 65 | AD19: 44 | AE19: 21 | AF19: 10 | AG19: 4 | AH19: 3 | AI19: 2 | AJ19: 1 | AK19: 0.5 | AL19: 0.2 | AM19: 20 | AN19: 100/0 | AO19: 30 | AP19: 15 | AQ19: 40 | AR19: 60
B20: 13 | E20: Grind | H20: 2/6 | I20: Cc3 III f3 | K20: Porfibel | N20: Neufvilles | Q20: BENOR | S20: 2.776 | U20: R | AC20: 100 | AD20: 98 | AE20: 85 | AF20: 64 | AG20: 23 | AH20: 11 | AI20: 4 | AJ20: 3 | AK20: 2 | AL20: 1 | AM20: 25 | AN20: 95/3 | AO20: 35 | AP20: 20 | AQ20: 45 | AR20: 62
B21: 14
B22: 15
B23: 16 | E23: Slakken | H23: 6/10 | I23: Dd4 IV f4 | K23: SDF | N23: Genk | Q23: intern | S23: 3.2 | U23: B | AA23: 100 | AB23: 100 | AC23: 95 | AD23: 50 | AE23: 12 | AF23: 7 | AG23: 6 | AH23: 5 | AI23: 4 | AJ23: 3 | AK23: 2 | AL23: 1 | AM23: 30 | AN23: 100/0 | AO23: 38 | AP23: 25 | AQ23: 50 | AR23: 64
B24: 17
B25: 18
B26: 19
B27: 20
B28: 21 | E28: Kalksteen | H28: 14/20 | I28: Aa1 I f1 | K28: Gralex | N28: Beez | Q28: BENOR | S28: 2.769 | U28: B | W28: 100 | X28: 100 | Y28: 99 | Z28: 55 | AA28: 25 | AB28: 10 | AC28: 2 | AD28: 1 | AE28: 0.9 | AF28: 0.8 | AG28: 0.7 | AH28: 0.6 | AI28: 0.5 | AJ28: 0.4 | AK28: 0.3 | AL28: 0.2 | AM28: 15 | AN28: 100/0 | AO28: 25 | AP28: 10 | AQ28: 35 | AR28: 40
B29: 22 | E29: Porfier | H29: 6/14 | I29: BB2 II f2 | K29: Holcim | N29: Carrières du Hainaut | Q29: BENOR | S29: 2.768 | U29: B | Y29: 100 | Z29: 98 | AA29: 97 | AB29: 72 | AC29: 65 | AD29: 44 | AE29: 21 | AF29: 10 | AG29: 4 | AH29: 3 | AI29: 2 | AJ29: 1 | AK29: 0.5 | AL29: 0.2 | AM29: 20 | AN29: 100/0 | AO29: 30 | AP29: 15 | AQ29: 40 | AR29: 42
B30: 23 | E30: Grind | H30: 2/6 | I30: Cc3 III f3 | K30: Porfibel | N30: Neufvilles | Q30: BENOR | S30: 2.767 | U30: R | AC30: 100 | AD30: 98 | AE30: 85 | AF30: 64 | AG30: 23 | AH30: 11 | AI30: 4 | AJ30: 3 | AK30: 2 | AL30: 1 | AM30: 25 | AN30: 95/1 | AO30: 35 | AP30: 20 | AQ30: 45 | AR30: 44
B31: 24
B32: 25
B33: 26 | E33: Slakken | H33: 6/10 | I33: Dd4 IV f4 | K33: SDF | N33: Genk | Q33: intern | S33: 3.22 | U33: B | AA33: 100 | AB33: 100 | AC33: 95 | AD33: 50 | AE33: 12 | AF33: 7 | AG33: 6 | AH33: 5 | AI33: 4 | AJ33: 3 | AK33: 2 | AL33: 1 | AM33: 30 | AN33: 100/0 | AO33: 38 | AP33: 25 | AQ33: 50 | AR33: 46
B34: 27
B35: 28
B36: 29
B37: 30
B38: 31 | E38: Kalksteen | H38: 14/20 | I38: Aa1 I f1 | K38: Gralex | N38: Beez | Q38: BENOR | S38: 2.8 | U38: B | W38: 100 | X38: 100 | Y38: 99 | Z38: 55 | AA38: 25 | AB38: 10 | AC38: 2 | AD38: 1 | AE38: 0.9 | AF38: 0.8 | AG38: 0.7 | AH38: 0.6 | AI38: 0.5 | AJ38: 0.4 | AK38: 0.3 | AL38: 0.2 | AM38: 15 | AN38: 100/0 | AO38: 25 | AP38: 10 | AQ38: 35 | AR38: 48
B39: 32 | E39: Porfier | H39: 6/14 | I39: BB2 II f2 | K39: Holcim | N39: Soignies | Q39: BENOR | S39: 2.801 | U39: B | Y39: 100 | Z39: 98 | AA39: 97 | AB39: 72 | AC39: 65 | AD39: 44 | AE39: 21 | AF39: 10 | AG39: 4 | AH39: 3 | AI39: 2 | AJ39: 1 | AK39: 0.5 | AL39: 0.2 | AM39: 20 | AN39: 100/0 | AO39: 30 | AP39: 15 | AQ39: 40 | AR39: 50
B40: 33 | E40: Grind | H40: 2/6 | I40: Cc3 III f3 | K40: Porfibel | N40: Neufvilles | Q40: BENOR | S40: 2.802 | U40: R | AC40: 100 | AD40: 98 | AE40: 85 | AF40: 64 | AG40: 23 | AH40: 11 | AI40: 4 | AJ40: 3 | AK40: 2 | AL40: 1 | AM40: 25 | AN40: 95/1 | AO40: 35 | AP40: 20 | AQ40: 45 | AR40: 52
B41: 34
B42: 35
...

Sheet samenstelling
A1: GEGEVENS GRONDSTOFFEN
B3: Hieronder kiest u de grondstoffen die u effectief bij de voorstudie gebruikt.
B5: AGGREGATEN (Steenslag en zand)
B6: Nr. | C6: Hoeveelheid | E6: Aard | H6: Kaliber | I6: BENOR | K6: Leverancier | N6: Herkomst | Q6: Keuring | S6: Volumemassa | U6: Hoekigheid | W6: Korrelverdeling (in % doorval door de zeef van … mm) | AM6: Andere klassen
B7: 1-40 | C7: (%) | I7: klasse | S7: (Mg/m³) | W7: =berekeningen!D9 -> 40 | X7: =berekeningen!E9 -> 31.5 | Y7: =berekeningen!F9 -> 20 | Z7: =berekeningen!G9 -> 16 | AA7: =berekeningen!H9 -> 14 | AB7: =berekeningen!I9 -> 12.5 | AC7: =berekeningen!J9 -> 10 | AD7: =berekeningen!K9 -> 8 | ... AL7: =berekeningen!S9 -> 0.063 | AM7: FI | AN7: C | AO7: Ecs | AP7: LA | AQ7: MD | AR7: PSV
B8: 1 | C8: =IF(B8="","",C88) -> 5.1 | E8: =IF($B8="","",IF(VLOOKUP($B8,grondstoffen!$B$8:$AL$47,4,FALSE)="","",VLOOKUP($B8,grondstoffen!$B$8:$AL$47,4,FALSE))) -> Kalksteen | H8: =IF($B8="","",IF(VLOOKUP($B8,grondstoffen!$B$8:$AL$47,7,FALSE)="","",VLOOKUP($B8,grondstoffen!$B$8:$AL$47,7,FALSE))) -> 14/20 | I8: =IF($B8="","",IF(VLOOKUP($B8,grondstoffen!$B$8:$AL$47,8,FALSE)="","",VLOOKUP($B8,grondstoffen!$B$8:$AL$47,8,FALSE))) -> Aa1 I f1 | K8: =IF($B8="","",IF(VLOOKUP($B8,grondstoffen!$B$8:$AL$47,10,FALSE)="","",VLOOKUP($B8,grondstoffen!$B$8:$AL$47,10,FALSE))) -> Gralex | N8: =IF($B8="","",IF(VLOOKUP($B8,grondstoffen!$B$8:$AL$47,13,FALSE)="","",VLOOKUP($B8,grondstoffen!$B$8:$AL$47,13,FALSE))) -> Beez | Q8: =IF($B8="","",IF(VLOOKUP($B8,grondstoffen!$B$8:$AL$47,16,FALSE)="","",VLOOKUP($B8,grondstoffen!$B$8:$AL$47,16,FALSE))) -> BENOR | S8: =IF($B8="","",IF(VLOOKUP($B8,grondstoffen!$B$8:$AL$47,18,FALSE)="","",VLOOKUP($B8,grondstoffen!$B$8:$AL$47,18,FALSE))) -> 2.789 | U8: =IF($B8="","",IF(VLOOKUP($B8,grondstoffen!$B$8:$AL$47,20,FALSE)="","",VLOOKUP($B8,grondstoffen!$B$8:$AL$47,20,FALSE))) -> B | W8: =IF($B8="","",IF(VLOOKUP($B8,grondstoffen!$B$8:$AL$47,22,FALSE)="","",VLOOKUP($B8,grondstoffen!$B$8:$AL$47,22,FALSE))) -> 100 | X8: =IF($B8="","",IF(VLOOKUP($B8,grondstoffen!$B$8:$AL$47,23,FALSE)="","",VLOOKUP($B8,grondstoffen!$B$8:$AL$47,23,FALSE))) -> 100 | Y8: =IF($B8="","",IF(VLOOKUP($B8,grondstoffen!$B$8:$AL$47,24,FALSE)="","",VLOOKUP($B8,grondstoffen!$B$8:$AL$47,24,FALSE))) -> 99 | Z8: =IF($B8="","",IF(VLOOKUP($B8,grondstoffen!$B$8:$AL$47,25,FALSE)="","",VLOOKUP($B8,grondstoffen!$B$8:$AL$47,25,FALSE))) -> 55 | AA8: =IF($B8="","",IF(VLOOKUP($B8,grondstoffen!$B$8:$AL$47,26,FALSE)="","",VLOOKUP($B8,grondstoffen!$B$8:$AL$47,26,FALSE))) -> 25 | AB8: =IF($B8="","",IF(VLOOKUP($B8,grondstoffen!$B$8:$AL$47,27,FALSE)="","",VLOOKUP($B8,grondstoffen!$B$8:$AL$47,27,FALSE))) -> 10 | AC8: =IF($B8="","",IF(VLOOKUP($B8,grondstoffen!$B$8:$AL$47,28,FALSE)="","",VLOOKUP($B8,grondstoffen!$B$8:$AL$47,28,FALSE))) -> 2 | AD8: =IF($B8="","",IF(VLOOKUP($B8,grondstoffen!$B$8:$AL$47,29,FALSE)="","",VLOOKUP($B8,grondstoffen!$B$8:$AL$47,29,FALSE))) -> 1 | AE8: =IF($B8="","",IF(VLOOKUP($B8,grondstoffen!$B$8:$AL$47,30,FALSE)="","",VLOOKUP($B8,grondstoffen!$B$8:$AL$47,30,FALSE))) -> 0.9 | AF8: =IF($B8="","",IF(VLOOKUP($B8,grondstoffen!$B$8:$AL$47,31,FALSE)="","",VLOOKUP($B8,grondstoffen!$B$8:$AL$47,31,FALSE))) -> 0.8 | AG8: =IF($B8="","",IF(VLOOKUP($B8,grondstoffen!$B$8:$AL$47,32,FALSE)="","",VLOOKUP($B8,grondstoffen!$B$8:$AL$47,32,FALSE))) -> 0.7 | AH8: =IF($B8="","",IF(VLOOKUP($B8,grondstoffen!$B$8:$AL$47,33,FALSE)="","",VLOOKUP($B8,grondstoffen!$B$8:$AL$47,33,FALSE))) -> 0.6 | AI8: =IF($B8="","",IF(VLOOKUP($B8,grondstoffen!$B$8:$AL$47,34,FALSE)="","",VLOOKUP($B8,grondstoffen!$B$8:$AL$47,34,FALSE))) -> 0.5 | AJ8: =IF($B8="","",IF(VLOOKUP($B8,grondstoffen!$B$8:$AL$47,35,FALSE)="","",VLOOKUP($B8,grondstoffen!$B$8:$AL$47,35,FALSE))) -> 0.4 | AK8: =IF($B8="","",IF(VLOOKUP($B8,grondstoffen!$B$8:$AL$47,36,FALSE)="","",VLOOKUP($B8,grondstoffen!$B$8:$AL$47,36,FALSE))) -> 0.3 | AL8: =IF($B8="","",IF(VLOOKUP($B8,grondstoffen!$B$8:$AL$47,37,FALSE)="","",VLOOKUP($B8,grondstoffen!$B$8:$AL$47,37,FALSE))) -> 0.2 | AM8: =IF($B8="","",IF(VLOOKUP($B8,grondstoffen!$B$8:$AQ$47,38,FALSE)="","",VLOOKUP($B8,grondstoffen!$B$8:$AQ$47,38,FALSE))) -> 15 | AN8: =IF($B8="","",IF(VLOOKUP($B8,grondstoffen!$B$8:$AQ$47,39,FALSE)="","",VLOOKUP($B8,grondstoffen!$B$8:$AQ$47,39,FALSE))) -> 100/0 | AO8: =IF($B8="","",IF(VLOOKUP($B8,grondstoffen!$B$8:$AQ$47,40,FALSE)="","",VLOOKUP($B8,grondstoffen!$B$8:$AQ$47,40,FALSE))) -> 25 | AP8: =IF($B8="","",IF(VLOOKUP($B8,grondstoffen!$B$8:$AQ$47,41,FALSE)="","",VLOOKUP($B8,grondstoffen!$B$8:$AQ$47,41,FALSE))) -> 10 | AQ8: =IF($B8="","",IF(VLOOKUP($B8,grondstoffen!$B$8:$AQ$47,42,FALSE)="","",VLOOKUP($B8,grondstoffen!$B$8:$AQ$47,42,FALSE))) -> 35 | AR8: =IF($B8="","",IF(VLOOKUP($B8,grondstoffen!$B$8:$AR$47,43,FALSE)="","",VLOOKUP($B8,grondstoffen!$B$8:$AR$47,43,FALSE))) -> 50
B9: 2 | C9: =IF(B9="","",C89) -> 10.2 | E9: =IF($B9="","",IF(VLOOKUP($B9,grondstoffen!$B$8:$AL$47,4,FALSE)="","",VLOOKUP($B9,grondstoffen!$B$8:$AL$47,4,FALSE))) -> Porfier | H9: =IF($B9="","",IF(VLOOKUP($B9,grondstoffen!$B$8:$AL$47,7,FALSE)="","",VLOOKUP($B9,grondstoffen!$B$8:$AL$47,7,FALSE))) -> 6/14 | I9: =IF($B9="","",IF(VLOOKUP($B9,grondstoffen!$B$8:$AL$47,8,FALSE)="","",VLOOKUP($B9,grondstoffen!$B$8:$AL$47,8,FALSE))) -> BB2 II f2 | K9: =IF($B9="","",IF(VLOOKUP($B9,grondstoffen!$B$8:$AL$47,10,FALSE)="","",VLOOKUP($B9,grondstoffen!$B$8:$AL$47,10,FALSE))) -> Holcim | N9: =IF($B9="","",IF(VLOOKUP($B9,grondstoffen!$B$8:$AL$47,13,FALSE)="","",VLOOKUP($B9,grondstoffen!$B$8:$AL$47,13,FALSE))) -> Soignies | Q9: =IF($B9="","",IF(VLOOKUP($B9,grondstoffen!$B$8:$AL$47,16,FALSE)="","",VLOOKUP($B9,grondstoffen!$B$8:$AL$47,16,FALSE))) -> BENOR | S9: =IF($B9="","",IF(VLOOKUP($B9,grondstoffen!$B$8:$AL$47,18,FALSE)="","",VLOOKUP($B9,grondstoffen!$B$8:$AL$47,18,FALSE))) -> 2.788 | U9: =IF($B9="","",IF(VLOOKUP($B9,grondstoffen!$B$8:$AL$47,20,FALSE)="","",VLOOKUP($B9,grondstoffen!$B$8:$AL$47,20,FALSE))) -> B | W9: =IF($B9="","",IF(VLOOKUP($B9,grondstoffen!$B$8:$AL$47,22,FALSE)="","",VLOOKUP($B9,grondstoffen!$B$8:$AL$47,22,FALSE))) | X9: =IF($B9="","",IF(VLOOKUP($B9,grondstoffen!$B$8:$AL$47,23,FALSE)="","",VLOOKUP($B9,grondstoffen!$B$8:$AL$47,23,FALSE))) | Y9: =IF($B9="","",IF(VLOOKUP($B9,grondstoffen!$B$8:$AL$47,24,FALSE)="","",VLOOKUP($B9,grondstoffen!$B$8:$AL$47,24,FALSE))) -> 100 | Z9: =IF($B9="","",IF(VLOOKUP($B9,grondstoffen!$B$8:$AL$47,25,FALSE)="","",VLOOKUP($B9,grondstoffen!$B$8:$AL$47,25,FALSE))) -> 98 | AA9: =IF($B9="","",IF(VLOOKUP($B9,grondstoffen!$B$8:$AL$47,26,FALSE)="","",VLOOKUP($B9,grondstoffen!$B$8:$AL$47,26,FALSE))) -> 97 | AB9: =IF($B9="","",IF(VLOOKUP($B9,grondstoffen!$B$8:$AL$47,27,FALSE)="","",VLOOKUP($B9,grondstoffen!$B$8:$AL$47,27,FALSE))) -> 72 | AC9: =IF($B9="","",IF(VLOOKUP($B9,grondstoffen!$B$8:$AL$47,28,FALSE)="","",VLOOKUP($B9,grondstoffen!$B$8:$AL$47,28,FALSE))) -> 65 | AD9: =IF($B9="","",IF(VLOOKUP($B9,grondstoffen!$B$8:$AL$47,29,FALSE)="","",VLOOKUP($B9,grondstoffen!$B$8:$AL$47,29,FALSE))) -> 44 | AE9: =IF($B9="","",IF(VLOOKUP($B9,grondstoffen!$B$8:$AL$47,30,FALSE)="","",VLOOKUP($B9,grondstoffen!$B$8:$AL$47,30,FALSE))) -> 21 | AF9: =IF($B9="","",IF(VLOOKUP($B9,grondstoffen!$B$8:$AL$47,31,FALSE)="","",VLOOKUP($B9,grondstoffen!$B$8:$AL$47,31,FALSE))) -> 10 | AG9: =IF($B9="","",IF(VLOOKUP($B9,grondstoffen!$B$8:$AL$47,32,FALSE)="","",VLOOKUP($B9,grondstoffen!$B$8:$AL$47,32,FALSE))) -> 4 | AH9: =IF($B9="","",IF(VLOOKUP($B9,grondstoffen!$B$8:$AL$47,33,FALSE)="","",VLOOKUP($B9,grondstoffen!$B$8:$AL$47,33,FALSE))) -> 3 | AI9: =IF($B9="","",IF(VLOOKUP($B9,grondstoffen!$B$8:$AL$47,34,FALSE)="","",VLOOKUP($B9,grondstoffen!$B$8:$AL$47,34,FALSE))) -> 2 | AJ9: =IF($B9="","",IF(VLOOKUP($B9,grondstoffen!$B$8:$AL$47,35,FALSE)="","",VLOOKUP($B9,grondstoffen!$B$8:$AL$47,35,FALSE))) -> 1 | AK9: =IF($B9="","",IF(VLOOKUP($B9,grondstoffen!$B$8:$AL$47,36,FALSE)="","",VLOOKUP($B9,grondstoffen!$B$8:$AL$47,36,FALSE))) -> 0.5 | AL9: =IF($B9="","",IF(VLOOKUP($B9,grondstoffen!$B$8:$AL$47,37,FALSE)="","",VLOOKUP($B9,grondstoffen!$B$8:$AL$47,37,FALSE))) -> 0.2 | AM9: =IF($B9="","",IF(VLOOKUP($B9,grondstoffen!$B$8:$AQ$47,38,FALSE)="","",VLOOKUP($B9,grondstoffen!$B$8:$AQ$47,38,FALSE))) -> 20 | AN9: =IF($B9="","",IF(VLOOKUP($B9,grondstoffen!$B$8:$AQ$47,39,FALSE)="","",VLOOKUP($B9,grondstoffen!$B$8:$AQ$47,39,FALSE))) -> 100/0 | AO9: =IF($B9="","",IF(VLOOKUP($B9,grondstoffen!$B$8:$AQ$47,40,FALSE)="","",VLOOKUP($B9,grondstoffen!$B$8:$AQ$47,40,FALSE))) -> 30 | AP9: =IF($B9="","",IF(VLOOKUP($B9,grondstoffen!$B$8:$AQ$47,41,FALSE)="","",VLOOKUP($B9,grondstoffen!$B$8:$AQ$47,41,FALSE))) -> 15 | AQ9: =IF($B9="","",IF(VLOOKUP($B9,grondstoffen!$B$8:$AQ$47,42,FALSE)="","",VLOOKUP($B9,grondstoffen!$B$8:$AQ$47,42,FALSE))) -> 40 | AR9: =IF($B9="","",IF(VLOOKUP($B9,grondstoffen!$B$8:$AR$47,43,FALSE)="","",VLOOKUP($B9,grondstoffen!$B$8:$AR$47,43,FALSE))) -> 52
B10: 3 | C10: =IF(B10="","",C90) -> 15.3 | E10: =IF($B10="","",IF(VLOOKUP($B10,grondstoffen!$B$8:$AL$47,4,FALSE)="","",VLOOKUP($B10,grondstoffen!$B$8:$AL$47,4,FALSE))) -> Rode zandsteen | H10: =IF($B10="","",IF(VLOOKUP($B10,grondstoffen!$B$8:$AL$47,7,FALSE)="","",VLOOKUP($B10,grondstoffen!$B$8:$AL$47,7,FALSE))) -> 0/2 (0/0,05) | I10: =IF($B10="","",IF(VLOOKUP($B10,grondstoffen!$B$8:$AL$47,8,FALSE)="","",VLOOKUP($B10,grondstoffen!$B$8:$AL$47,8,FALSE))) -> Af22aPA Ecs30 | K10: =IF($B10="","",IF(VLOOKUP($B10,grondstoffen!$B$8:$AL$47,10,FALSE)="","",VLOOKUP($B10,grondstoffen!$B$8:$AL$47,10,FALSE))) -> Porfibel | N10: =IF($B10="","",IF(VLOOKUP($B10,grondstoffen!$B$8:$AL$47,13,FALSE)="","",VLOOKUP($B10,grondstoffen!$B$8:$AL$47,13,FALSE))) -> Neufvilles | Q10: =IF($B10="","",IF(VLOOKUP($B10,grondstoffen!$B$8:$AL$47,16,FALSE)="","",VLOOKUP($B10,grondstoffen!$B$8:$AL$47,16,FALSE))) -> BENOR | S10: =IF($B10="","",IF(VLOOKUP($B10,grondstoffen!$B$8:$AL$47,18,FALSE)="","",VLOOKUP($B10,grondstoffen!$B$8:$AL$47,18,FALSE))) -> 2.786 | U10: =IF($B10="","",IF(VLOOKUP($B10,grondstoffen!$B$8:$AL$47,20,FALSE)="","",VLOOKUP($B10,grondstoffen!$B$8:$AL$47,20,FALSE))) -> R | W10: =IF($B10="","",IF(VLOOKUP($B10,grondstoffen!$B$8:$AL$47,22,FALSE)="","",VLOOKUP($B10,grondstoffen!$B$8:$AL$47,22,FALSE))) | X10: =IF($B10="","",IF(VLOOKUP($B10,grondstoffen!$B$8:$AL$47,23,FALSE)="","",VLOOKUP($B10,grondstoffen!$B$8:$AL$47,23,FALSE))) | Y10: =IF($B10="","",IF(VLOOKUP($B10,grondstoffen!$B$8:$AL$47,24,FALSE)="","",VLOOKUP($B10,grondstoffen!$B$8:$AL$47,24,FALSE))) | Z10: =IF($B10="","",IF(VLOOKUP($B10,grondstoffen!$B$8:$AL$47,25,FALSE)="","",VLOOKUP($B10,grondstoffen!$B$8:$AL$47,25,FALSE))) | AA10: =IF($B10="","",IF(VLOOKUP($B10,grondstoffen!$B$8:$AL$47,26,FALSE)="","",VLOOKUP($B10,grondstoffen!$B$8:$AL$47,26,FALSE))) | AB10: =IF($B10="","",IF(VLOOKUP($B10,grondstoffen!$B$8:$AL$47,27,FALSE)="","",VLOOKUP($B10,grondstoffen!$B$8:$AL$47,27,FALSE))) | AC10: =IF($B10="","",IF(VLOOKUP($B10,grondstoffen!$B$8:$AL$47,28,FALSE)="","",VLOOKUP($B10,grondstoffen!$B$8:$AL$47,28,FALSE))) -> 100 | AD10: =IF($B10="","",IF(VLOOKUP($B10,grondstoffen!$B$8:$AL$47,29,FALSE)="","",VLOOKUP($B10,grondstoffen!$B$8:$AL$47,29,FALSE))) -> 98 | AE10: =IF($B10="","",IF(VLOOKUP($B10,grondstoffen!$B$8:$AL$47,30,FALSE)="","",VLOOKUP($B10,grondstoffen!$B$8:$AL$47,30,FALSE))) -> 85 | AF10: =IF($B10="","",IF(VLOOKUP($B10,grondstoffen!$B$8:$AL$47,31,FALSE)="","",VLOOKUP($B10,grondstoffen!$B$8:$AL$47,31,FALSE))) -> 64 | AG10: =IF($B10="","",IF(VLOOKUP($B10,grondstoffen!$B$8:$AL$47,32,FALSE)="","",VLOOKUP($B10,grondstoffen!$B$8:$AL$47,32,FALSE))) -> 23 | AH10: =IF($B10="","",IF(VLOOKUP($B10,grondstoffen!$B$8:$AL$47,33,FALSE)="","",VLOOKUP($B10,grondstoffen!$B$8:$AL$47,33,FALSE))) -> 11 | AI10: =IF($B10="","",IF(VLOOKUP($B10,grondstoffen!$B$8:$AL$47,34,FALSE)="","",VLOOKUP($B10,grondstoffen!$B$8:$AL$47,34,FALSE))) -> 4 | AJ10: =IF($B10="","",IF(VLOOKUP($B10,grondstoffen!$B$8:$AL$47,35,FALSE)="","",VLOOKUP($B10,grondstoffen!$B$8:$AL$47,35,FALSE))) -> 3 | AK10: =IF($B10="","",IF(VLOOKUP($B10,grondstoffen!$B$8:$AL$47,36,FALSE)="","",VLOOKUP($B10,grondstoffen!$B$8:$AL$47,36,FALSE))) -> 2 | AL10: =IF($B10="","",IF(VLOOKUP($B10,grondstoffen!$B$8:$AL$47,37,FALSE)="","",VLOOKUP($B10,grondstoffen!$B$8:$AL$47,37,FALSE))) -> 1 | AM10: =IF($B10="","",IF(VLOOKUP($B10,grondstoffen!$B$8:$AQ$47,38,FALSE)="","",VLOOKUP($B10,grondstoffen!$B$8:$AQ$47,38,FALSE))) -> 25 | AN10: =IF($B10="","",IF(VLOOKUP($B10,grondstoffen!$B$8:$AQ$47,39,FALSE)="","",VLOOKUP($B10,grondstoffen!$B$8:$AQ$47,39,FALSE))) -> 95/3 | AO10: =IF($B10="","",IF(VLOOKUP($B10,grondstoffen!$B$8:$AQ$47,40,FALSE)="","",VLOOKUP($B10,grondstoffen!$B$8:$AQ$47,40,FALSE))) -> 35 | AP10: =IF($B10="","",IF(VLOOKUP($B10,grondstoffen!$B$8:$AQ$47,41,FALSE)="","",VLOOKUP($B10,grondstoffen!$B$8:$AQ$47,41,FALSE))) -> 20 | AQ10: =IF($B10="","",IF(VLOOKUP($B10,grondstoffen!$B$8:$AQ$47,42,FALSE)="","",VLOOKUP($B10,grondstoffen!$B$8:$AQ$47,42,FALSE))) -> 45 | AR10: =IF($B10="","",IF(VLOOKUP($B10,grondstoffen!$B$8:$AR$47,43,FALSE)="","",VLOOKUP($B10,grondstoffen!$B$8:$AR$47,43,FALSE))) -> 54
C11: =IF(B11="","",C91) | E11: =IF($B11="","",IF(VLOOKUP($B11,grondstoffen!$B$8:$AL$47,4,FALSE)="","",VLOOKUP($B11,grondstoffen!$B$8:$AL$47,4,FALSE))) | H11: =IF($B11="","",IF(VLOOKUP($B11,grondstoffen!$B$8:$AL$47,7,FALSE)="","",VLOOKUP($B11,grondstoffen!$B$8:$AL$47,7,FALSE))) | I11: =IF($B11="","",IF(VLOOKUP($B11,grondstoffen!$B$8:$AL$47,8,FALSE)="","",VLOOKUP($B11,grondstoffen!$B$8:$AL$47,8,FALSE))) | K11: =IF($B11="","",IF(VLOOKUP($B11,grondstoffen!$B$8:$AL$47,10,FALSE)="","",VLOOKUP($B11,grondstoffen!$B$8:$AL$47,10,FALSE))) | N11: =IF($B11="","",IF(VLOOKUP($B11,grondstoffen!$B$8:$AL$47,13,FALSE)="","",VLOOKUP($B11,grondstoffen!$B$8:$AL$47,13,FALSE))) | Q11: =IF($B11="","",IF(VLOOKUP($B11,grondstoffen!$B$8:$AL$47,16,FALSE)="","",VLOOKUP($B11,grondstoffen!$B$8:$AL$47,16,FALSE))) | S11: =IF($B11="","",IF(VLOOKUP($B11,grondstoffen!$B$8:$AL$47,18,FALSE)="","",VLOOKUP($B11,grondstoffen!$B$8:$AL$47,18,FALSE))) | U11: =IF($B11="","",IF(VLOOKUP($B11,grondstoffen!$B$8:$AL$47,20,FALSE)="","",VLOOKUP($B11,grondstoffen!$B$8:$AL$47,20,FALSE))) | W11: =IF($B11="","",IF(VLOOKUP($B11,grondstoffen!$B$8:$AL$47,22,FALSE)="","",VLOOKUP($B11,grondstoffen!$B$8:$AL$47,22,FALSE))) | X11: =IF($B11="","",IF(VLOOKUP($B11,grondstoffen!$B$8:$AL$47,23,FALSE)="","",VLOOKUP($B11,grondstoffen!$B$8:$AL$47,23,FALSE))) | Y11: =IF($B11="","",IF(VLOOKUP($B11,grondstoffen!$B$8:$AL$47,24,FALSE)="","",VLOOKUP($B11,grondstoffen!$B$8:$AL$47,24,FALSE))) | Z11: =IF($B11="","",IF(VLOOKUP($B11,grondstoffen!$B$8:$AL$47,25,FALSE)="","",VLOOKUP($B11,grondstoffen!$B$8:$AL$47,25,FALSE))) | AA11: =IF($B11="","",IF(VLOOKUP($B11,grondstoffen!$B$8:$AL$47,26,FALSE)="","",VLOOKUP($B11,grondstoffen!$B$8:$AL$47,26,FALSE))) | AB11: =IF($B11="","",IF(VLOOKUP($B11,grondstoffen!$B$8:$AL$47,27,FALSE)="","",VLOOKUP($B11,grondstoffen!$B$8:$AL$47,27,FALSE))) | AC11: =IF($B11="","",IF(VLOOKUP($B11,grondstoffen!$B$8:$AL$47,28,FALSE)="","",VLOOKUP($B11,grondstoffen!$B$8:$AL$47,28,FALSE))) | AD11: =IF($B11="","",IF(VLOOKUP($B11,grondstoffen!$B$8:$AL$47,29,FALSE)="","",VLOOKUP($B11,grondstoffen!$B$8:$AL$47,29,FALSE))) | AE11: =IF($B11="","",IF(VLOOKUP($B11,grondstoffen!$B$8:$AL$47,30,FALSE)="","",VLOOKUP($B11,grondstoffen!$B$8:$AL$47,30,FALSE))) | AF11: =IF($B11="","",IF(VLOOKUP($B11,grondstoffen!$B$8:$AL$47,31,FALSE)="","",VLOOKUP($B11,grondstoffen!$B$8:$AL$47,31,FALSE))) | AG11: =IF($B11="","",IF(VLOOKUP($B11,grondstoffen!$B$8:$AL$47,32,FALSE)="","",VLOOKUP($B11,grondstoffen!$B$8:$AL$47,32,FALSE))) | AH11: =IF($B11="","",IF(VLOOKUP($B11,grondstoffen!$B$8:$AL$47,33,FALSE)="","",VLOOKUP($B11,grondstoffen!$B$8:$AL$47,33,FALSE))) | AI11: =IF($B11="","",IF(VLOOKUP($B11,grondstoffen!$B$8:$AL$47,34,FALSE)="","",VLOOKUP($B11,grondstoffen!$B$8:$AL$47,34,FALSE))) | AJ11: =IF($B11="","",IF(VLOOKUP($B11,grondstoffen!$B$8:$AL$47,35,FALSE)="","",VLOOKUP($B11,grondstoffen!$B$8:$AL$47,35,FALSE))) | AK11: =IF($B11="","",IF(VLOOKUP($B11,grondstoffen!$B$8:$AL$47,36,FALSE)="","",VLOOKUP($B11,grondstoffen!$B$8:$AL$47,36,FALSE))) | AL11: =IF($B11="","",IF(VLOOKUP($B11,grondstoffen!$B$8:$AL$47,37,FALSE)="","",VLOOKUP($B11,grondstoffen!$B$8:$AL$47,37,FALSE))) | AM11: =IF($B11="","",IF(VLOOKUP($B11,grondstoffen!$B$8:$AQ$47,38,FALSE)="","",VLOOKUP($B11,grondstoffen!$B$8:$AQ$47,38,FALSE))) | AN11: =IF($B11="","",IF(VLOOKUP($B11,grondstoffen!$B$8:$AQ$47,39,FALSE)="","",VLOOKUP($B11,grondstoffen!$B$8:$AQ$47,39,FALSE))) | AO11: =IF($B11="","",IF(VLOOKUP($B11,grondstoffen!$B$8:$AQ$47,40,FALSE)="","",VLOOKUP($B11,grondstoffen!$B$8:$AQ$47,40,FALSE))) | AP11: =IF($B11="","",IF(VLOOKUP($B11,grondstoffen!$B$8:$AQ$47,41,FALSE)="","",VLOOKUP($B11,grondstoffen!$B$8:$AQ$47,41,FALSE))) | AQ11: =IF($B11="","",IF(VLOOKUP($B11,grondstoffen!$B$8:$AQ$47,42,FALSE)="","",VLOOKUP($B11,grondstoffen!$B$8:$AQ$47,42,FALSE))) | AR11: =IF($B11="","",IF(VLOOKUP($B11,grondstoffen!$B$8:$AR$47,43,FALSE)="","",VLOOKUP($B11,grondstoffen!$B$8:$AR$47,43,FALSE)))
C12: =IF(B12="","",C92) | E12: =IF($B12="","",IF(VLOOKUP($B12,grondstoffen!$B$8:$AL$47,4,FALSE)="","",VLOOKUP($B12,grondstoffen!$B$8:$AL$47,4,FALSE))) | H12: =IF($B12="","",IF(VLOOKUP($B12,grondstoffen!$B$8:$AL$47,7,FALSE)="","",VLOOKUP($B12,grondstoffen!$B$8:$AL$47,7,FALSE))) | I12: =IF($B12="","",IF(VLOOKUP($B12,grondstoffen!$B$8:$AL$47,8,FALSE)="","",VLOOKUP($B12,grondstoffen!$B$8:$AL$47,8,FALSE))) | K12: =IF($B12="","",IF(VLOOKUP($B12,grondstoffen!$B$8:$AL$47,10,FALSE)="","",VLOOKUP($B12,grondstoffen!$B$8:$AL$47,10,FALSE))) | N12: =IF($B12="","",IF(VLOOKUP($B12,grondstoffen!$B$8:$AL$47,13,FALSE)="","",VLOOKUP($B12,grondstoffen!$B$8:$AL$47,13,FALSE))) | Q12: =IF($B12="","",IF(VLOOKUP($B12,grondstoffen!$B$8:$AL$47,16,FALSE)="","",VLOOKUP($B12,grondstoffen!$B$8:$AL$47,16,FALSE))) | S12: =IF($B12="","",IF(VLOOKUP($B12,grondstoffen!$B$8:$AL$47,18,FALSE)="","",VLOOKUP($B12,grondstoffen!$B$8:$AL$47,18,FALSE))) | U12: =IF($B12="","",IF(VLOOKUP($B12,grondstoffen!$B$8:$AL$47,20,FALSE)="","",VLOOKUP($B12,grondstoffen!$B$8:$AL$47,20,FALSE))) | W12: =IF($B12="","",IF(VLOOKUP($B12,grondstoffen!$B$8:$AL$47,22,FALSE)="","",VLOOKUP($B12,grondstoffen!$B$8:$AL$47,22,FALSE))) | X12: =IF($B12="","",IF(VLOOKUP($B12,grondstoffen!$B$8:$AL$47,23,FALSE)="","",VLOOKUP($B12,grondstoffen!$B$8:$AL$47,23,FALSE))) | Y12: =IF($B12="","",IF(VLOOKUP($B12,grondstoffen!$B$8:$AL$47,24,FALSE)="","",VLOOKUP($B12,grondstoffen!$B$8:$AL$47,24,FALSE))) | Z12: =IF($B12="","",IF(VLOOKUP($B12,grondstoffen!$B$8:$AL$47,25,FALSE)="","",VLOOKUP($B12,grondstoffen!$B$8:$AL$47,25,FALSE))) | AA12: =IF($B12="","",IF(VLOOKUP($B12,grondstoffen!$B$8:$AL$47,26,FALSE)="","",VLOOKUP($B12,grondstoffen!$B$8:$AL$47,26,FALSE))) | AB12: =IF($B12="","",IF(VLOOKUP($B12,grondstoffen!$B$8:$AL$47,27,FALSE)="","",VLOOKUP($B12,grondstoffen!$B$8:$AL$47,27,FALSE))) | AC12: =IF($B12="","",IF(VLOOKUP($B12,grondstoffen!$B$8:$AL$47,28,FALSE)="","",VLOOKUP($B12,grondstoffen!$B$8:$AL$47,28,FALSE))) | AD12: =IF($B12="","",IF(VLOOKUP($B12,grondstoffen!$B$8:$AL$47,29,FALSE)="","",VLOOKUP($B12,grondstoffen!$B$8:$AL$47,29,FALSE))) | AE12: =IF($B12="","",IF(VLOOKUP($B12,grondstoffen!$B$8:$AL$47,30,FALSE)="","",VLOOKUP($B12,grondstoffen!$B$8:$AL$47,30,FALSE))) | AF12: =IF($B12="","",IF(VLOOKUP($B12,grondstoffen!$B$8:$AL$47,31,FALSE)="","",VLOOKUP($B12,grondstoffen!$B$8:$AL$47,31,FALSE))) | AG12: =IF($B12="","",IF(VLOOKUP($B12,grondstoffen!$B$8:$AL$47,32,FALSE)="","",VLOOKUP($B12,grondstoffen!$B$8:$AL$47,32,FALSE))) | AH12: =IF($B12="","",IF(VLOOKUP($B12,grondstoffen!$B$8:$AL$47,33,FALSE)="","",VLOOKUP($B12,grondstoffen!$B$8:$AL$47,33,FALSE))) | AI12: =IF($B12="","",IF(VLOOKUP($B12,grondstoffen!$B$8:$AL$47,34,FALSE)="","",VLOOKUP($B12,grondstoffen!$B$8:$AL$47,34,FALSE))) | AJ12: =IF($B12="","",IF(VLOOKUP($B12,grondstoffen!$B$8:$AL$47,35,FALSE)="","",VLOOKUP($B12,grondstoffen!$B$8:$AL$47,35,FALSE))) | AK12: =IF($B12="","",IF(VLOOKUP($B12,grondstoffen!$B$8:$AL$47,36,FALSE)="","",VLOOKUP($B12,grondstoffen!$B$8:$AL$47,36,FALSE))) | AL12: =IF($B12="","",IF(VLOOKUP($B12,grondstoffen!$B$8:$AL$47,37,FALSE)="","",VLOOKUP($B12,grondstoffen!$B$8:$AL$47,37,FALSE))) | AM12: =IF($B12="","",IF(VLOOKUP($B12,grondstoffen!$B$8:$AQ$47,38,FALSE)="","",VLOOKUP($B12,grondstoffen!$B$8:$AQ$47,38,FALSE))) | AN12: =IF($B12="","",IF(VLOOKUP($B12,grondstoffen!$B$8:$AQ$47,39,FALSE)="","",VLOOKUP($B12,grondstoffen!$B$8:$AQ$47,39,FALSE))) | AO12: =IF($B12="","",IF(VLOOKUP($B12,grondstoffen!$B$8:$AQ$47,40,FALSE)="","",VLOOKUP($B12,grondstoffen!$B$8:$AQ$47,40,FALSE))) | AP12: =IF($B12="","",IF(VLOOKUP($B12,grondstoffen!$B$8:$AQ$47,41,FALSE)="","",VLOOKUP($B12,grondstoffen!$B$8:$AQ$47,41,FALSE))) | AQ12: =IF($B12="","",IF(VLOOKUP($B12,grondstoffen!$B$8:$AQ$47,42,FALSE)="","",VLOOKUP($B12,grondstoffen!$B$8:$AQ$47,42,FALSE))) | AR12: =IF($B12="","",IF(VLOOKUP($B12,grondstoffen!$B$8:$AR$47,43,FALSE)="","",VLOOKUP($B12,grondstoffen!$B$8:$AR$47,43,FALSE)))
B13: 6 | C13: =IF(B13="","",C93) -> 35.3 | E13: =IF($B13="","",IF(VLOOKUP($B13,grondstoffen!$B$8:$AL$47,4,FALSE)="","",VLOOKUP($B13,grondstoffen!$B$8:$AL$47,4,FALSE))) -> Slakken | H13: =IF($B13="","",IF(VLOOKUP($B13,grondstoffen!$B$8:$AL$47,7,FALSE)="","",VLOOKUP($B13,grondstoffen!$B$8:$AL$47,7,FALSE))) -> 6/10 | I13: =IF($B13="","",IF(VLOOKUP($B13,grondstoffen!$B$8:$AL$47,8,FALSE)="","",VLOOKUP($B13,grondstoffen!$B$8:$AL$47,8,FALSE))) -> Dd4 IV f4 | K13: =IF($B13="","",IF(VLOOKUP($B13,grondstoffen!$B$8:$AL$47,10,FALSE)="","",VLOOKUP($B13,grondstoffen!$B$8:$AL$47,10,FALSE))) -> SDF | N13: =IF($B13="","",IF(VLOOKUP($B13,grondstoffen!$B$8:$AL$47,13,FALSE)="","",VLOOKUP($B13,grondstoffen!$B$8:$AL$47,13,FALSE))) -> Genk | Q13: =IF($B13="","",IF(VLOOKUP($B13,grondstoffen!$B$8:$AL$47,16,FALSE)="","",VLOOKUP($B13,grondstoffen!$B$8:$AL$47,16,FALSE))) -> intern | S13: =IF($B13="","",IF(VLOOKUP($B13,grondstoffen!$B$8:$AL$47,18,FALSE)="","",VLOOKUP($B13,grondstoffen!$B$8:$AL$47,18,FALSE))) -> 3.21 | U13: =IF($B13="","",IF(VLOOKUP($B13,grondstoffen!$B$8:$AL$47,20,FALSE)="","",VLOOKUP($B13,grondstoffen!$B$8:$AL$47,20,FALSE))) -> B | W13: =IF($B13="","",IF(VLOOKUP($B13,grondstoffen!$B$8:$AL$47,22,FALSE)="","",VLOOKUP($B13,grondstoffen!$B$8:$AL$47,22,FALSE))) | X13: =IF($B13="","",IF(VLOOKUP($B13,grondstoffen!$B$8:$AL$47,23,FALSE)="","",VLOOKUP($B13,grondstoffen!$B$8:$AL$47,23,FALSE))) | Y13: =IF($B13="","",IF(VLOOKUP($B13,grondstoffen!$B$8:$AL$47,24,FALSE)="","",VLOOKUP($B13,grondstoffen!$B$8:$AL$47,24,FALSE))) | Z13: =IF($B13="","",IF(VLOOKUP($B13,grondstoffen!$B$8:$AL$47,25,FALSE)="","",VLOOKUP($B13,grondstoffen!$B$8:$AL$47,25,FALSE))) | AA13: =IF($B13="","",IF(VLOOKUP($B13,grondstoffen!$B$8:$AL$47,26,FALSE)="","",VLOOKUP($B13,grondstoffen!$B$8:$AL$47,26,FALSE))) -> 100 | AB13: =IF($B13="","",IF(VLOOKUP($B13,grondstoffen!$B$8:$AL$47,27,FALSE)="","",VLOOKUP($B13,grondstoffen!$B$8:$AL$47,27,FALSE))) -> 100 | AC13: =IF($B13="","",IF(VLOOKUP($B13,grondstoffen!$B$8:$AL$47,28,FALSE)="","",VLOOKUP($B13,grondstoffen!$B$8:$AL$47,28,FALSE))) -> 95 | AD13: =IF($B13="","",IF(VLOOKUP($B13,grondstoffen!$B$8:$AL$47,29,FALSE)="","",VLOOKUP($B13,grondstoffen!$B$8:$AL$47,29,FALSE))) -> 50 | AE13: =IF($B13="","",IF(VLOOKUP($B13,grondstoffen!$B$8:$AL$47,30,FALSE)="","",VLOOKUP($B13,grondstoffen!$B$8:$AL$47,30,FALSE))) -> 12 | AF13: =IF($B13="","",IF(VLOOKUP($B13,grondstoffen!$B$8:$AL$47,31,FALSE)="","",VLOOKUP($B13,grondstoffen!$B$8:$AL$47,31,FALSE))) -> 7 | AG13: =IF($B13="","",IF(VLOOKUP($B13,grondstoffen!$B$8:$AL$47,32,FALSE)="","",VLOOKUP($B13,grondstoffen!$B$8:$AL$47,32,FALSE))) -> 6 | AH13: =IF($B13="","",IF(VLOOKUP($B13,grondstoffen!$B$8:$AL$47,33,FALSE)="","",VLOOKUP($B13,grondstoffen!$B$8:$AL$47,33,FALSE))) -> 5 | AI13: =IF($B13="","",IF(VLOOKUP($B13,grondstoffen!$B$8:$AL$47,34,FALSE)="","",VLOOKUP($B13,grondstoffen!$B$8:$AL$47,34,FALSE))) -> 4 | AJ13: =IF($B13="","",IF(VLOOKUP($B13,grondstoffen!$B$8:$AL$47,35,FALSE)="","",VLOOKUP($B13,grondstoffen!$B$8:$AL$47,35,FALSE))) -> 3 | AK13: =IF($B13="","",IF(VLOOKUP($B13,grondstoffen!$B$8:$AL$47,36,FALSE)="","",VLOOKUP($B13,grondstoffen!$B$8:$AL$47,36,FALSE))) -> 2 | AL13: =IF($B13="","",IF(VLOOKUP($B13,grondstoffen!$B$8:$AL$47,37,FALSE)="","",VLOOKUP($B13,grondstoffen!$B$8:$AL$47,37,FALSE))) -> 1 | AM13: =IF($B13="","",IF(VLOOKUP($B13,grondstoffen!$B$8:$AQ$47,38,FALSE)="","",VLOOKUP($B13,grondstoffen!$B$8:$AQ$47,38,FALSE))) -> 30 | AN13: =IF($B13="","",IF(VLOOKUP($B13,grondstoffen!$B$8:$AQ$47,39,FALSE)="","",VLOOKUP($B13,grondstoffen!$B$8:$AQ$47,39,FALSE))) -> 100/0 | AO13: =IF($B13="","",IF(VLOOKUP($B13,grondstoffen!$B$8:$AQ$47,40,FALSE)="","",VLOOKUP($B13,grondstoffen!$B$8:$AQ$47,40,FALSE))) -> 38 | AP13: =IF($B13="","",IF(VLOOKUP($B13,grondstoffen!$B$8:$AQ$47,41,FALSE)="","",VLOOKUP($B13,grondstoffen!$B$8:$AQ$47,41,FALSE))) -> 25 | AQ13: =IF($B13="","",IF(VLOOKUP($B13,grondstoffen!$B$8:$AQ$47,42,FALSE)="","",VLOOKUP($B13,grondstoffen!$B$8:$AQ$47,42,FALSE))) -> 50 | AR13: =IF($B13="","",IF(VLOOKUP($B13,grondstoffen!$B$8:$AR$47,43,FALSE)="","",VLOOKUP($B13,grondstoffen!$B$8:$AR$47,43,FALSE))) -> 56
B14: 11 | C14: =IF(B14="","",C94) -> 0 | E14: =IF($B14="","",IF(VLOOKUP($B14,grondstoffen!$B$8:$AL$47,4,FALSE)="","",VLOOKUP($B14,grondstoffen!$B$8:$AL$47,4,FALSE))) -> Kalksteen | H14: =IF($B14="","",IF(VLOOKUP($B14,grondstoffen!$B$8:$AL$47,7,FALSE)="","",VLOOKUP($B14,grondstoffen!$B$8:$AL$47,7,FALSE))) -> 14/20 | I14: =IF($B14="","",IF(VLOOKUP($B14,grondstoffen!$B$8:$AL$47,8,FALSE)="","",VLOOKUP($B14,grondstoffen!$B$8:$AL$47,8,FALSE))) -> Aa1 I f1 | K14: =IF($B14="","",IF(VLOOKUP($B14,grondstoffen!$B$8:$AL$47,10,FALSE)="","",VLOOKUP($B14,grondstoffen!$B$8:$AL$47,10,FALSE))) -> Gralex | N14: =IF($B14="","",IF(VLOOKUP($B14,grondstoffen!$B$8:$AL$47,13,FALSE)="","",VLOOKUP($B14,grondstoffen!$B$8:$AL$47,13,FALSE))) -> Beez | Q14: =IF($B14="","",IF(VLOOKUP($B14,grondstoffen!$B$8:$AL$47,16,FALSE)="","",VLOOKUP($B14,grondstoffen!$B$8:$AL$47,16,FALSE))) -> BENOR | S14: =IF($B14="","",IF(VLOOKUP($B14,grondstoffen!$B$8:$AL$47,18,FALSE)="","",VLOOKUP($B14,grondstoffen!$B$8:$AL$47,18,FALSE))) -> 2.779 | U14: =IF($B14="","",IF(VLOOKUP($B14,grondstoffen!$B$8:$AL$47,20,FALSE)="","",VLOOKUP($B14,grondstoffen!$B$8:$AL$47,20,FALSE))) -> B | W14: =IF($B14="","",IF(VLOOKUP($B14,grondstoffen!$B$8:$AL$47,22,FALSE)="","",VLOOKUP($B14,grondstoffen!$B$8:$AL$47,22,FALSE))) -> 100 | X14: =IF($B14="","",IF(VLOOKUP($B14,grondstoffen!$B$8:$AL$47,23,FALSE)="","",VLOOKUP($B14,grondstoffen!$B$8:$AL$47,23,FALSE))) -> 100 | Y14: =IF($B14="","",IF(VLOOKUP($B14,grondstoffen!$B$8:$AL$47,24,FALSE)="","",VLOOKUP($B14,grondstoffen!$B$8:$AL$47,24,FALSE))) -> 99 | Z14: =IF($B14="","",IF(VLOOKUP($B14,grondstoffen!$B$8:$AL$47,25,FALSE)="","",VLOOKUP($B14,grondstoffen!$B$8:$AL$47,25,FALSE))) -> 55 | AA14: =IF($B14="","",IF(VLOOKUP($B14,grondstoffen!$B$8:$AL$47,26,FALSE)="","",VLOOKUP($B14,grondstoffen!$B$8:$AL$47,26,FALSE))) -> 25 | AB14: =IF($B14="","",IF(VLOOKUP($B14,grondstoffen!$B$8:$AL$47,27,FALSE)="","",VLOOKUP($B14,grondstoffen!$B$8:$AL$47,27,FALSE))) -> 10 | AC14: =IF($B14="","",IF(VLOOKUP($B14,grondstoffen!$B$8:$AL$47,28,FALSE)="","",VLOOKUP($B14,grondstoffen!$B$8:$AL$47,28,FALSE))) -> 2 | AD14: =IF($B14="","",IF(VLOOKUP($B14,grondstoffen!$B$8:$AL$47,29,FALSE)="","",VLOOKUP($B14,grondstoffen!$B$8:$AL$47,29,FALSE))) -> 1 | AE14: =IF($B14="","",IF(VLOOKUP($B14,grondstoffen!$B$8:$AL$47,30,FALSE)="","",VLOOKUP($B14,grondstoffen!$B$8:$AL$47,30,FALSE))) -> 0.9 | AF14: =IF($B14="","",IF(VLOOKUP($B14,grondstoffen!$B$8:$AL$47,31,FALSE)="","",VLOOKUP($B14,grondstoffen!$B$8:$AL$47,31,FALSE))) -> 0.8 | AG14: =IF($B14="","",IF(VLOOKUP($B14,grondstoffen!$B$8:$AL$47,32,FALSE)="","",VLOOKUP($B14,grondstoffen!$B$8:$AL$47,32,FALSE))) -> 0.7 | AH14: =IF($B14="","",IF(VLOOKUP($B14,grondstoffen!$B$8:$AL$47,33,FALSE)="","",VLOOKUP($B14,grondstoffen!$B$8:$AL$47,33,FALSE))) -> 0.6 | AI14: =IF($B14="","",IF(VLOOKUP($B14,grondstoffen!$B$8:$AL$47,34,FALSE)="","",VLOOKUP($B14,grondstoffen!$B$8:$AL$47,34,FALSE))) -> 0.5 | AJ14: =IF($B14="","",IF(VLOOKUP($B14,grondstoffen!$B$8:$AL$47,35,FALSE)="","",VLOOKUP($B14,grondstoffen!$B$8:$AL$47,35,FALSE))) -> 0.4 | AK14: =IF($B14="","",IF(VLOOKUP($B14,grondstoffen!$B$8:$AL$47,36,FALSE)="","",VLOOKUP($B14,grondstoffen!$B$8:$AL$47,36,FALSE))) -> 0.3 | AL14: =IF($B14="","",IF(VLOOKUP($B14,grondstoffen!$B$8:$AL$47,37,FALSE)="","",VLOOKUP($B14,grondstoffen!$B$8:$AL$47,37,FALSE))) -> 0.2 | AM14: =IF($B14="","",IF(VLOOKUP($B14,grondstoffen!$B$8:$AQ$47,38,FALSE)="","",VLOOKUP($B14,grondstoffen!$B$8:$AQ$47,38,FALSE))) -> 15 | AN14: =IF($B14="","",IF(VLOOKUP($B14,grondstoffen!$B$8:$AQ$47,39,FALSE)="","",VLOOKUP($B14,grondstoffen!$B$8:$AQ$47,39,FALSE))) -> 100/0 | AO14: =IF($B14="","",IF(VLOOKUP($B14,grondstoffen!$B$8:$AQ$47,40,FALSE)="","",VLOOKUP($B14,grondstoffen!$B$8:$AQ$47,40,FALSE))) -> 25 | AP14: =IF($B14="","",IF(VLOOKUP($B14,grondstoffen!$B$8:$AQ$47,41,FALSE)="","",VLOOKUP($B14,grondstoffen!$B$8:$AQ$47,41,FALSE))) -> 10 | AQ14: =IF($B14="","",IF(VLOOKUP($B14,grondstoffen!$B$8:$AQ$47,42,FALSE)="","",VLOOKUP($B14,grondstoffen!$B$8:$AQ$47,42,FALSE))) -> 35 | AR14: =IF($B14="","",IF(VLOOKUP($B14,grondstoffen!$B$8:$AR$47,43,FALSE)="","",VLOOKUP($B14,grondstoffen!$B$8:$AR$47,43,FALSE))) -> 58
B15: 12 | C15: =IF(B15="","",C95) -> 0 | E15: =IF($B15="","",IF(VLOOKUP($B15,grondstoffen!$B$8:$AL$47,4,FALSE)="","",VLOOKUP($B15,grondstoffen!$B$8:$AL$47,4,FALSE))) -> Porfier | H15: =IF($B15="","",IF(VLOOKUP($B15,grondstoffen!$B$8:$AL$47,7,FALSE)="","",VLOOKUP($B15,grondstoffen!$B$8:$AL$47,7,FALSE))) -> 6/14 | I15: =IF($B15="","",IF(VLOOKUP($B15,grondstoffen!$B$8:$AL$47,8,FALSE)="","",VLOOKUP($B15,grondstoffen!$B$8:$AL$47,8,FALSE))) -> BB2 II f2 | K15: =IF($B15="","",IF(VLOOKUP($B15,grondstoffen!$B$8:$AL$47,10,FALSE)="","",VLOOKUP($B15,grondstoffen!$B$8:$AL$47,10,FALSE))) -> Holcim | N15: =IF($B15="","",IF(VLOOKUP($B15,grondstoffen!$B$8:$AL$47,13,FALSE)="","",VLOOKUP($B15,grondstoffen!$B$8:$AL$47,13,FALSE))) -> Soignies | Q15: =IF($B15="","",IF(VLOOKUP($B15,grondstoffen!$B$8:$AL$47,16,FALSE)="","",VLOOKUP($B15,grondstoffen!$B$8:$AL$47,16,FALSE))) -> BENOR | S15: =IF($B15="","",IF(VLOOKUP($B15,grondstoffen!$B$8:$AL$47,18,FALSE)="","",VLOOKUP($B15,grondstoffen!$B$8:$AL$47,18,FALSE))) -> 2.778 | U15: =IF($B15="","",IF(VLOOKUP($B15,grondstoffen!$B$8:$AL$47,20,FALSE)="","",VLOOKUP($B15,grondstoffen!$B$8:$AL$47,20,FALSE))) -> B | W15: =IF($B15="","",IF(VLOOKUP($B15,grondstoffen!$B$8:$AL$47,22,FALSE)="","",VLOOKUP($B15,grondstoffen!$B$8:$AL$47,22,FALSE))) | X15: =IF($B15="","",IF(VLOOKUP($B15,grondstoffen!$B$8:$AL$47,23,FALSE)="","",VLOOKUP($B15,grondstoffen!$B$8:$AL$47,23,FALSE))) | Y15: =IF($B15="","",IF(VLOOKUP($B15,grondstoffen!$B$8:$AL$47,24,FALSE)="","",VLOOKUP($B15,grondstoffen!$B$8:$AL$47,24,FALSE))) -> 100 | Z15: =IF($B15="","",IF(VLOOKUP($B15,grondstoffen!$B$8:$AL$47,25,FALSE)="","",VLOOKUP($B15,grondstoffen!$B$8:$AL$47,25,FALSE))) -> 98 | AA15: =IF($B15="","",IF(VLOOKUP($B15,grondstoffen!$B$8:$AL$47,26,FALSE)="","",VLOOKUP($B15,grondstoffen!$B$8:$AL$47,26,FALSE))) -> 97 | AB15: =IF($B15="","",IF(VLOOKUP($B15,grondstoffen!$B$8:$AL$47,27,FALSE)="","",VLOOKUP($B15,grondstoffen!$B$8:$AL$47,27,FALSE))) -> 72 | AC15: =IF($B15="","",IF(VLOOKUP($B15,grondstoffen!$B$8:$AL$47,28,FALSE)="","",VLOOKUP($B15,grondstoffen!$B$8:$AL$47,28,FALSE))) -> 65 | AD15: =IF($B15="","",IF(VLOOKUP($B15,grondstoffen!$B$8:$AL$47,29,FALSE)="","",VLOOKUP($B15,grondstoffen!$B$8:$AL$47,29,FALSE))) -> 44 | AE15: =IF($B15="","",IF(VLOOKUP($B15,grondstoffen!$B$8:$AL$47,30,FALSE)="","",VLOOKUP($B15,grondstoffen!$B$8:$AL$47,30,FALSE))) -> 21 | AF15: =IF($B15="","",IF(VLOOKUP($B15,grondstoffen!$B$8:$AL$47,31,FALSE)="","",VLOOKUP($B15,grondstoffen!$B$8:$AL$47,31,FALSE))) -> 10 | AG15: =IF($B15="","",IF(VLOOKUP($B15,grondstoffen!$B$8:$AL$47,32,FALSE)="","",VLOOKUP($B15,grondstoffen!$B$8:$AL$47,32,FALSE))) -> 4 | AH15: =IF($B15="","",IF(VLOOKUP($B15,grondstoffen!$B$8:$AL$47,33,FALSE)="","",VLOOKUP($B15,grondstoffen!$B$8:$AL$47,33,FALSE))) -> 3 | AI15: =IF($B15="","",IF(VLOOKUP($B15,grondstoffen!$B$8:$AL$47,34,FALSE)="","",VLOOKUP($B15,grondstoffen!$B$8:$AL$47,34,FALSE))) -> 2 | AJ15: =IF($B15="","",IF(VLOOKUP($B15,grondstoffen!$B$8:$AL$47,35,FALSE)="","",VLOOKUP($B15,grondstoffen!$B$8:$AL$47,35,FALSE))) -> 1 | AK15: =IF($B15="","",IF(VLOOKUP($B15,grondstoffen!$B$8:$AL$47,36,FALSE)="","",VLOOKUP($B15,grondstoffen!$B$8:$AL$47,36,FALSE))) -> 0.5 | AL15: =IF($B15="","",IF(VLOOKUP($B15,grondstoffen!$B$8:$AL$47,37,FALSE)="","",VLOOKUP($B15,grondstoffen!$B$8:$AL$47,37,FALSE))) -> 0.2 | AM15: =IF($B15="","",IF(VLOOKUP($B15,grondstoffen!$B$8:$AQ$47,38,FALSE)="","",VLOOKUP($B15,grondstoffen!$B$8:$AQ$47,38,FALSE))) -> 20 | AN15: =IF($B15="","",IF(VLOOKUP($B15,grondstoffen!$B$8:$AQ$47,39,FALSE)="","",VLOOKUP($B15,grondstoffen!$B$8:$AQ$47,39,FALSE))) -> 100/0 | AO15: =IF($B15="","",IF(VLOOKUP($B15,grondstoffen!$B$8:$AQ$47,40,FALSE)="","",VLOOKUP($B15,grondstoffen!$B$8:$AQ$47,40,FALSE))) -> 30 | AP15: =IF($B15="","",IF(VLOOKUP($B15,grondstoffen!$B$8:$AQ$47,41,FALSE)="","",VLOOKUP($B15,grondstoffen!$B$8:$AQ$47,41,FALSE))) -> 15 | AQ15: =IF($B15="","",IF(VLOOKUP($B15,grondstoffen!$B$8:$AQ$47,42,FALSE)="","",VLOOKUP($B15,grondstoffen!$B$8:$AQ$47,42,FALSE))) -> 40 | AR15: =IF($B15="","",IF(VLOOKUP($B15,grondstoffen!$B$8:$AR$47,43,FALSE)="","",VLOOKUP($B15,grondstoffen!$B$8:$AR$47,43,FALSE))) -> 60
B16: 16 | C16: =IF(B16="","",C96) -> 0 | E16: =IF($B16="","",IF(VLOOKUP($B16,grondstoffen!$B$8:$AL$47,4,FALSE)="","",VLOOKUP($B16,grondstoffen!$B$8:$AL$47,4,FALSE))) -> Slakken | H16: =IF($B16="","",IF(VLOOKUP($B16,grondstoffen!$B$8:$AL$47,7,FALSE)="","",VLOOKUP($B16,grondstoffen!$B$8:$AL$47,7,FALSE))) -> 6/10 | I16: =IF($B16="","",IF(VLOOKUP($B16,grondstoffen!$B$8:$AL$47,8,FALSE)="","",VLOOKUP($B16,grondstoffen!$B$8:$AL$47,8,FALSE))) -> Dd4 IV f4 | K16: =IF($B16="","",IF(VLOOKUP($B16,grondstoffen!$B$8:$AL$47,10,FALSE)="","",VLOOKUP($B16,grondstoffen!$B$8:$AL$47,10,FALSE))) -> SDF | N16: =IF($B16="","",IF(VLOOKUP($B16,grondstoffen!$B$8:$AL$47,13,FALSE)="","",VLOOKUP($B16,grondstoffen!$B$8:$AL$47,13,FALSE))) -> Genk | Q16: =IF($B16="","",IF(VLOOKUP($B16,grondstoffen!$B$8:$AL$47,16,FALSE)="","",VLOOKUP($B16,grondstoffen!$B$8:$AL$47,16,FALSE))) -> intern | S16: =IF($B16="","",IF(VLOOKUP($B16,grondstoffen!$B$8:$AL$47,18,FALSE)="","",VLOOKUP($B16,grondstoffen!$B$8:$AL$47,18,FALSE))) -> 3.2 | U16: =IF($B16="","",IF(VLOOKUP($B16,grondstoffen!$B$8:$AL$47,20,FALSE)="","",VLOOKUP($B16,grondstoffen!$B$8:$AL$47,20,FALSE))) -> B | W16: =IF($B16="","",IF(VLOOKUP($B16,grondstoffen!$B$8:$AL$47,22,FALSE)="","",VLOOKUP($B16,grondstoffen!$B$8:$AL$47,22,FALSE))) | X16: =IF($B16="","",IF(VLOOKUP($B16,grondstoffen!$B$8:$AL$47,23,FALSE)="","",VLOOKUP($B16,grondstoffen!$B$8:$AL$47,23,FALSE))) | Y16: =IF($B16="","",IF(VLOOKUP($B16,grondstoffen!$B$8:$AL$47,24,FALSE)="","",VLOOKUP($B16,grondstoffen!$B$8:$AL$47,24,FALSE))) | Z16: =IF($B16="","",IF(VLOOKUP($B16,grondstoffen!$B$8:$AL$47,25,FALSE)="","",VLOOKUP($B16,grondstoffen!$B$8:$AL$47,25,FALSE))) | AA16: =IF($B16="","",IF(VLOOKUP($B16,grondstoffen!$B$8:$AL$47,26,FALSE)="","",VLOOKUP($B16,grondstoffen!$B$8:$AL$47,26,FALSE))) -> 100 | AB16: =IF($B16="","",IF(VLOOKUP($B16,grondstoffen!$B$8:$AL$47,27,FALSE)="","",VLOOKUP($B16,grondstoffen!$B$8:$AL$47,27,FALSE))) -> 100 | AC16: =IF($B16="","",IF(VLOOKUP($B16,grondstoffen!$B$8:$AL$47,28,FALSE)="","",VLOOKUP($B16,grondstoffen!$B$8:$AL$47,28,FALSE))) -> 95 | AD16: =IF($B16="","",IF(VLOOKUP($B16,grondstoffen!$B$8:$AL$47,29,FALSE)="","",VLOOKUP($B16,grondstoffen!$B$8:$AL$47,29,FALSE))) -> 50 | AE16: =IF($B16="","",IF(VLOOKUP($B16,grondstoffen!$B$8:$AL$47,30,FALSE)="","",VLOOKUP($B16,grondstoffen!$B$8:$AL$47,30,FALSE))) -> 12 | AF16: =IF($B16="","",IF(VLOOKUP($B16,grondstoffen!$B$8:$AL$47,31,FALSE)="","",VLOOKUP($B16,grondstoffen!$B$8:$AL$47,31,FALSE))) -> 7 | AG16: =IF($B16="","",IF(VLOOKUP($B16,grondstoffen!$B$8:$AL$47,32,FALSE)="","",VLOOKUP($B16,grondstoffen!$B$8:$AL$47,32,FALSE))) -> 6 | AH16: =IF($B16="","",IF(VLOOKUP($B16,grondstoffen!$B$8:$AL$47,33,FALSE)="","",VLOOKUP($B16,grondstoffen!$B$8:$AL$47,33,FALSE))) -> 5 | AI16: =IF($B16="","",IF(VLOOKUP($B16,grondstoffen!$B$8:$AL$47,34,FALSE)="","",VLOOKUP($B16,grondstoffen!$B$8:$AL$47,34,FALSE))) -> 4 | AJ16: =IF($B16="","",IF(VLOOKUP($B16,grondstoffen!$B$8:$AL$47,35,FALSE)="","",VLOOKUP($B16,grondstoffen!$B$8:$AL$47,35,FALSE))) -> 3 | AK16: =IF($B16="","",IF(VLOOKUP($B16,grondstoffen!$B$8:$AL$47,36,FALSE)="","",VLOOKUP($B16,grondstoffen!$B$8:$AL$47,36,FALSE))) -> 2 | AL16: =IF($B16="","",IF(VLOOKUP($B16,grondstoffen!$B$8:$AL$47,37,FALSE)="","",VLOOKUP($B16,grondstoffen!$B$8:$AL$47,37,FALSE))) -> 1 | AM16: =IF($B16="","",IF(VLOOKUP($B16,grondstoffen!$B$8:$AQ$47,38,FALSE)="","",VLOOKUP($B16,grondstoffen!$B$8:$AQ$47,38,FALSE))) -> 30 | AN16: =IF($B16="","",IF(VLOOKUP($B16,grondstoffen!$B$8:$AQ$47,39,FALSE)="","",VLOOKUP($B16,grondstoffen!$B$8:$AQ$47,39,FALSE))) -> 100/0 | AO16: =IF($B16="","",IF(VLOOKUP($B16,grondstoffen!$B$8:$AQ$47,40,FALSE)="","",VLOOKUP($B16,grondstoffen!$B$8:$AQ$47,40,FALSE))) -> 38 | AP16: =IF($B16="","",IF(VLOOKUP($B16,grondstoffen!$B$8:$AQ$47,41,FALSE)="","",VLOOKUP($B16,grondstoffen!$B$8:$AQ$47,41,FALSE))) -> 25 | AQ16: =IF($B16="","",IF(VLOOKUP($B16,grondstoffen!$B$8:$AQ$47,42,FALSE)="","",VLOOKUP($B16,grondstoffen!$B$8:$AQ$47,42,FALSE))) -> 50 | AR16: =IF($B16="","",IF(VLOOKUP($B16,grondstoffen!$B$8:$AR$47,43,FALSE)="","",VLOOKUP($B16,grondstoffen!$B$8:$AR$47,43,FALSE))) -> 64
C17: =IF(B17="","",C97) | E17: =IF($B17="","",IF(VLOOKUP($B17,grondstoffen!$B$8:$AL$47,4,FALSE)="","",VLOOKUP($B17,grondstoffen!$B$8:$AL$47,4,FALSE))) | H17: =IF($B17="","",IF(VLOOKUP($B17,grondstoffen!$B$8:$AL$47,7,FALSE)="","",VLOOKUP($B17,grondstoffen!$B$8:$AL$47,7,FALSE))) | I17: =IF($B17="","",IF(VLOOKUP($B17,grondstoffen!$B$8:$AL$47,8,FALSE)="","",VLOOKUP($B17,grondstoffen!$B$8:$AL$47,8,FALSE))) | K17: =IF($B17="","",IF(VLOOKUP($B17,grondstoffen!$B$8:$AL$47,10,FALSE)="","",VLOOKUP($B17,grondstoffen!$B$8:$AL$47,10,FALSE))) | N17: =IF($B17="","",IF(VLOOKUP($B17,grondstoffen!$B$8:$AL$47,13,FALSE)="","",VLOOKUP($B17,grondstoffen!$B$8:$AL$47,13,FALSE))) | Q17: =IF($B17="","",IF(VLOOKUP($B17,grondstoffen!$B$8:$AL$47,16,FALSE)="","",VLOOKUP($B17,grondstoffen!$B$8:$AL$47,16,FALSE))) | S17: =IF($B17="","",IF(VLOOKUP($B17,grondstoffen!$B$8:$AL$47,18,FALSE)="","",VLOOKUP($B17,grondstoffen!$B$8:$AL$47,18,FALSE))) | U17: =IF($B17="","",IF(VLOOKUP($B17,grondstoffen!$B$8:$AL$47,20,FALSE)="","",VLOOKUP($B17,grondstoffen!$B$8:$AL$47,20,FALSE))) | W17: =IF($B17="","",IF(VLOOKUP($B17,grondstoffen!$B$8:$AL$47,22,FALSE)="","",VLOOKUP($B17,grondstoffen!$B$8:$AL$47,22,FALSE))) | X17: =IF($B17="","",IF(VLOOKUP($B17,grondstoffen!$B$8:$AL$47,23,FALSE)="","",VLOOKUP($B17,grondstoffen!$B$8:$AL$47,23,FALSE))) | Y17: =IF($B17="","",IF(VLOOKUP($B17,grondstoffen!$B$8:$AL$47,24,FALSE)="","",VLOOKUP($B17,grondstoffen!$B$8:$AL$47,24,FALSE))) | Z17: =IF($B17="","",IF(VLOOKUP($B17,grondstoffen!$B$8:$AL$47,25,FALSE)="","",VLOOKUP($B17,grondstoffen!$B$8:$AL$47,25,FALSE))) | AA17: =IF($B17="","",IF(VLOOKUP($B17,grondstoffen!$B$8:$AL$47,26,FALSE)="","",VLOOKUP($B17,grondstoffen!$B$8:$AL$47,26,FALSE))) | AB17: =IF($B17="","",IF(VLOOKUP($B17,grondstoffen!$B$8:$AL$47,27,FALSE)="","",VLOOKUP($B17,grondstoffen!$B$8:$AL$47,27,FALSE))) | AC17: =IF($B17="","",IF(VLOOKUP($B17,grondstoffen!$B$8:$AL$47,28,FALSE)="","",VLOOKUP($B17,grondstoffen!$B$8:$AL$47,28,FALSE))) | AD17: =IF($B17="","",IF(VLOOKUP($B17,grondstoffen!$B$8:$AL$47,29,FALSE)="","",VLOOKUP($B17,grondstoffen!$B$8:$AL$47,29,FALSE))) | AE17: =IF($B17="","",IF(VLOOKUP($B17,grondstoffen!$B$8:$AL$47,30,FALSE)="","",VLOOKUP($B17,grondstoffen!$B$8:$AL$47,30,FALSE))) | AF17: =IF($B17="","",IF(VLOOKUP($B17,grondstoffen!$B$8:$AL$47,31,FALSE)="","",VLOOKUP($B17,grondstoffen!$B$8:$AL$47,31,FALSE))) | AG17: =IF($B17="","",IF(VLOOKUP($B17,grondstoffen!$B$8:$AL$47,32,FALSE)="","",VLOOKUP($B17,grondstoffen!$B$8:$AL$47,32,FALSE))) | AH17: =IF($B17="","",IF(VLOOKUP($B17,grondstoffen!$B$8:$AL$47,33,FALSE)="","",VLOOKUP($B17,grondstoffen!$B$8:$AL$47,33,FALSE))) | AI17: =IF($B17="","",IF(VLOOKUP($B17,grondstoffen!$B$8:$AL$47,34,FALSE)="","",VLOOKUP($B17,grondstoffen!$B$8:$AL$47,34,FALSE))) | AJ17: =IF($B17="","",IF(VLOOKUP($B17,grondstoffen!$B$8:$AL$47,35,FALSE)="","",VLOOKUP($B17,grondstoffen!$B$8:$AL$47,35,FALSE))) | AK17: =IF($B17="","",IF(VLOOKUP($B17,grondstoffen!$B$8:$AL$47,36,FALSE)="","",VLOOKUP($B17,grondstoffen!$B$8:$AL$47,36,FALSE))) | AL17: =IF($B17="","",IF(VLOOKUP($B17,grondstoffen!$B$8:$AL$47,37,FALSE)="","",VLOOKUP($B17,grondstoffen!$B$8:$AL$47,37,FALSE))) | AM17: =IF($B17="","",IF(VLOOKUP($B17,grondstoffen!$B$8:$AQ$47,38,FALSE)="","",VLOOKUP($B17,grondstoffen!$B$8:$AQ$47,38,FALSE))) | AN17: =IF($B17="","",IF(VLOOKUP($B17,grondstoffen!$B$8:$AQ$47,39,FALSE)="","",VLOOKUP($B17,grondstoffen!$B$8:$AQ$47,39,FALSE))) | AO17: =IF($B17="","",IF(VLOOKUP($B17,grondstoffen!$B$8:$AQ$47,40,FALSE)="","",VLOOKUP($B17,grondstoffen!$B$8:$AQ$47,40,FALSE))) | AP17: =IF($B17="","",IF(VLOOKUP($B17,grondstoffen!$B$8:$AQ$47,41,FALSE)="","",VLOOKUP($B17,grondstoffen!$B$8:$AQ$47,41,FALSE))) | AQ17: =IF($B17="","",IF(VLOOKUP($B17,grondstoffen!$B$8:$AQ$47,42,FALSE)="","",VLOOKUP($B17,grondstoffen!$B$8:$AQ$47,42,FALSE))) | AR17: =IF($B17="","",IF(VLOOKUP($B17,grondstoffen!$B$8:$AR$47,43,FALSE)="","",VLOOKUP($B17,grondstoffen!$B$8:$AR$47,43,FALSE)))
C19: Hoeveelheid: Toegevoegd gehalte aggregaten in het aggregaatmengsel. In te vullen vanaf rij 88.
B20: Nr.: Kies de nummers van de grondstoffen die u wil selecteren uit het blad 'grondstoffen'.
B23: VULSTOFFEN
B24: Nr. | C24: Hoeveelheid | E24: Soort | H24: Type | K24: Commerciële | N24: Leverancier | Q24: Keuring | S24: Volumemassa | U24: Holle ruimte | W24: Korrelverdeling (in % doorval door de zeef van … mm) | AM24: Gehalte Ca(OH)2
B25: 41-45 | C25: (%) | K25: benaming | N25: en herkomst | S25: (Mg/m³) | U25: (%) | W25: =berekeningen!D9 -> 40 | X25: =berekeningen!E9 -> 31.5 | Y25: =berekeningen!F9 -> 20 | Z25: =berekeningen!G9 -> 16 | AA25: =berekeningen!H9 -> 14 | AB25: =berekeningen!I9 -> 12.5 | AC25: =berekeningen!J9 -> 10 | AD25: =berekeningen!K9 -> 8 | ... AL25: =berekeningen!S9 -> 0.063 | AM25: (%)
